Workbook

Sheet Diagrama de clases

Sheet Clases
A1: Clase | B1: Estereotipo | C1: Desripción
A2: Barberia | B2: class | C2: Representa la cadena o marca comercial de barbería, dueña de una o varias sedes.
A3: DiaSemana | B3: class | C3: Representa cada uno de los días de la semana, incluyendo festivo, que se usa como catálogo para definir los horarios de la barbería y de cada barbero.
A4: Departamento | B4: class | C4: Representa cada uno de los departamentos del país en los que se encuentran las ciudades donde la barbería puede tener sedes.
A5: Estado | B5: class | C5: Representa en qué situación puntual se encuentra una cita: agendada, finalizada, cancelada por alguna de las partes, con tardanza del cliente o del barbero, o con inasistencia del cliente.
A6: PrefijoCelular | B6: class | C6: Representa el catálogo de prefijos telefónicos de país que el administrador habilita, y que son los únicos que barberos y clientes pueden usar en su número de celular.
A7: TipoMulta | B7: class | C7: Representa los tipos de multa que puede recibir un cliente: por tardanza o por inasistencia.
A8: TipoRegistroHora | B8: class | C8: Representa el catálogo de los distintos momentos en que se puede registrar una hora real durante una cita: llegada del cliente, barbero preparado, inicio y fin de la atención.
A9: Cliente | B9: class | C9: Representa a la persona que solicita citas en la barbería.
A10: Ciudad | B10: class | C10: Representa cada una de las ciudades, pertenecientes a un departamento, en las que puede estar ubicada una sede de la barbería.
A11: Sede | B11: class | C11: Representa cada una de las sucursales físicas de una barbería, ubicada en una ciudad puntual, donde se ofrecen los servicios y trabajan los barberos.
A12: Barbero | B12: class | C12: Representa a un trabajador de la barbería que atiende clientes según los servicios que sabe realizar, organiza su propio horario y tiene su agenda personal para atender todas las citas que valla teniendo.
... A22: RegistroHoraCita | B22: class | C22: Representa cada hora real registrada durante una cita puntual, según el tipo de momento al que corresponde (llegada del cliente, barbero preparado, inicio o fin de la atención).

Sheet Barberia
A1: <-Volver al inicio
A2: =Clases!$A$1 -> Clase | B2: =Clases!A2 -> Barberia
A3: =Clases!$B$1 -> Estereotipo | B3: =Clases!B2 -> class
A4: =Clases!$C$1 -> Desripción | B4: =Clases!C2 -> Representa la cadena o marca comercial de barbería, dueña de una o varias sedes.
A5: Modificador acceso: | B5: public
A6: Tipo clase: | B6: no final
A7: Relaciones
A8: Relación | B8: Tipo relación | E8: Estructura
A9: Es usada por | B9: Composición | E9: =Sede!B2 -> Sede
A10: Atributos
A11: Modificador de aceso | B11: Nombre | C11: Tipo de dato | E11: Tipo modificación atributo | F11: Tipo acceso atributo | G11: Valor por defecto | J11: Descripción atributo
C12: Tipo de dato | D12: ¿Cuál?
A13: private | B13: id | C13: Otro | D13: UUID | E13: no final | F13: no static | G13: new UUID(0L, 0L) | J13: Representa un identificador que hará unico cada objeto de dominio de este tipo, no se puede repetir
A14: private | B14: nombre | C14: String | E14: no final | F14: no static | G14: "" | J14: Representa el nombre comercial de la cadena de barbería, dueña de una o varias sedes
A15: private | B15: nit | C15: String | E15: no final | F15: no static | G15: "" | J15: Representa el número de identificación tributaria (NIT) que identifica legalmente a la barbería como empresa
A16: Constructores
A17: Modificador de aceso | B17: Nombre | C17: Tipo constructor | D17: Descripción | E17: Parámetros | M17: Excepciones
E18: Nombre | F18: Tipo de dato | G18: ¿Cuál? | H18: Tipo parámetro | I18: Tipo modificación atributo | J18: Descripción
A19: public | B19: =B2 -> Barberia | C19: Defecto | D19: Constructor por defecto que crea un objeto Barberia con todos sus atributos en su valor por defecto
A20: public | B20: =B2 -> Barberia | C20: Parametrizado | D20: Constructor parametrizado que crea un objeto Barberia asignando el valor recibido a cada uno de sus atributos | E20: valorId | F20: Otro | G20: UUID | H20: Por referencia | I20: no final | J20: Valor que se asigna al atributo id
E21: valorNombre | F21: String | H21: Por valor | I21: no final | J21: Valor que se asigna al atributo nombre
E22: valorNit | F22: String | H22: Por valor | I22: no final | J22: Valor que se asigna al atributo nit
A23: Métodos accesores
A24: Modificador de aceso | B24: Nombre | C24: Tipo método accesor | D24: Tipo modificación método | E24: Descripción | F24: Parámetros | L24: Tipo dato de retorno | N24: Excepciones
F25: Nombre | G25: Tipo de dato | H25: ¿Cuál? | I25: Tipo parámetro | J25: Tipo modificación atributo | K25: Descripción | L25: Tipo de dato | M25: ¿Cuál?
A26: public | B26: getId | C26: getter | D26: no final | E26: Método encargado de obtener el valor del atributo id | L26: Otro | M26: UUID
A27: public | B27: setId | C27: setter | D27: no final | E27: Método encargado de colocar el valor al atributo id | F27: valorId | G27: Otro | H27: UUID | I27: Por referencia | J27: no final | K27: Nuevo valor del atributo id | L27: void
A28: public | B28: getNombre | C28: getter | D28: no final | E28: Método encargado de obtener el valor del atributo nombre | L28: String
A29: public | B29: setNombre | C29: setter | D29: no final | E29: Método encargado de colocar el valor al atributo nombre | F29: valorNombre | G29: String | I29: Por valor | J29: no final | K29: Nuevo valor del atributo nombre | L29: void
A30: public | B30: getNit | C30: getter | D30: no final | E30: Método encargado de obtener el valor del atributo nit | L30: String
A31: public | B31: setNit | C31: setter | D31: no final | E31: Método encargado de colocar el valor al atributo nit | F31: valorNit | G31: String | I31: Por valor | J31: no final | K31: Nuevo valor del atributo nit | L31: void
A32: Métodos
A33: Modificador de aceso | B33: Nombre | C33: Tipo acceso método | D33: Tipo modificación método | E33: Descripción | F33: Parámetros | L33: Tipo dato de retorno | N33: Excepciones
F34: Nombre | G34: Tipo de dato | H34: ¿Cuál? | I34: Tipo parámetro | J34: Tipo modificación atributo | K34: Descripción | L34: Tipo de dato | M34: ¿Cuál?
A35: public | B35: registrarBarberia | C35: no static | D35: no final | E35: Comando que permite registrar una nueva barbería con su nombre y nit | F35: nombre | G35: String | I35: Por valor | J35: no final | K35: Representa el nombre comercial de la cadena de barbería, dueña de una o varias sedes | L35: Otro | M35: Barberia | N35: Generar una excepción indicándole al administrador que los datos no cumplen; Generar una excepción indicándole al administrador que ya existe una barbería con ese nit
F36: nit | G36: String | I36: Por valor | J36: no final | K36: Representa el número de identificación tributaria (NIT) que identifica legalmente a la barbería como empresa
A37: public | B37: consultarDatosBarberia | C37: no static | D37: no final | E37: Permite al administrador consultar el nombre y el nit de la barbería | F37: id | G37: Otro | H37: UUID | I37: Por referencia | J37: no final | K37: Corresponde al identificador de la barbería que se va a consultar | L37: Otro | M37: Barberia | N37: Informar con un mensaje que no existe una barbería con el identificador enviado y por lo tanto no se puede realizar la operación
A38: public | B38: consultarNombreBarberia | C38: no static | D38: no final | E38: Permite al barbero y al cliente consultar el nombre de la barbería | F38: id | G38: Otro | H38: UUID | I38: Por referencia | J38: no final | K38: Corresponde al identificador de la barbería que se va a consultar | L38: String | N38: Informar con un mensaje que no existe una barbería con el identificador enviado y por lo tanto no se puede realizar la operación
A39: public | B39: cambiarNombreBarberia | C39: no static | D39: no final | E39: Permite al administrador cambiar el nombre comercial de la barbería | F39: id | G39: Otro | H39: UUID | I39: Por referencia | J39: no final | K39: Corresponde al identificador de la barbería | L39: Otro | M39: Barberia | N39: Informar con un mensaje que no existe una barbería con el identificador enviado y por lo tanto no se puede realizar la operación; Generar una excepción indicándole al administrador cuáles datos de la barbería no cumplen con las reglas definidas
F40: nombre | G40: String | I40: Por valor | J40: no final | K40: Representa el nombre comercial de la cadena de barbería, dueña de una o varias sedes
...

Sheet DiaSemana
A1: <-Volver al inicio
A2: =Clases!$A$1 -> Clase | B2: =Clases!A3 -> DiaSemana
A3: =Clases!$B$1 -> Estereotipo | B3: =Clases!B3 -> class
A4: =Clases!$C$1 -> Desripción | B4: =Clases!C3 -> Representa cada uno de los días de la semana, incluyendo festivo, que se usa como catálogo para definir los horarios de la barbería y de cada barbero.
A5: Modificador acceso: | B5: public
A6: Tipo clase: | B6: no final
A7: Relaciones
A8: Relación | B8: Tipo relación | E8: Estructura
A9: Es usada por | B9: Asociación | E9: =HorarioBarberia!B2 -> HorarioBarberia
A10: Atributos
A11: Modificador de aceso | B11: Nombre | C11: Tipo de dato | E11: Tipo modificación atributo | F11: Tipo acceso atributo | G11: Valor por defecto | J11: Descripción atributo
C12: Tipo de dato | D12: ¿Cuál?
A13: private | B13: id | C13: Otro | D13: UUID | E13: no final | F13: no static | G13: new UUID(0L, 0L) | J13: Representa un identificador que hará unico cada objeto de dominio de este tipo, no se puede repetir
A14: private | B14: nombre | C14: String | E14: no final | F14: no static | G14: "" | J14: Representa como se llama el dia de la semana, para los horarios
A15: Constructores
A16: Modificador de aceso | B16: Nombre | C16: Tipo constructor | D16: Descripción | E16: Parámetros | M16: Excepciones
E17: Nombre | F17: Tipo de dato | G17: ¿Cuál? | H17: Tipo parámetro | I17: Tipo modificación atributo | J17: Descripción
A18: public | B18: =B2 -> DiaSemana | C18: Defecto | D18: Constructor por defecto que crea un objeto DiaSemana con todos sus atributos en su valor por defecto
A19: public | B19: =B2 -> DiaSemana | C19: Parametrizado | D19: Constructor parametrizado que crea un objeto DiaSemana asignando el valor recibido a cada uno de sus atributos | E19: valorId | F19: Otro | G19: UUID | H19: Por referencia | I19: no final | J19: Valor que se asigna al atributo id
E20: valorNombre | F20: String | H20: Por valor | I20: no final | J20: Valor que se asigna al atributo nombre
A21: Métodos accesores
A22: Modificador de aceso | B22: Nombre | C22: Tipo método accesor | D22: Tipo modificación método | E22: Descripción | F22: Parámetros | L22: Tipo dato de retorno | N22: Excepciones
F23: Nombre | G23: Tipo de dato | H23: ¿Cuál? | I23: Tipo parámetro | J23: Tipo modificación atributo | K23: Descripción | L23: Tipo de dato | M23: ¿Cuál?
A24: public | B24: getId | C24: getter | D24: no final | E24: Método encargado de obtener el valor del atributo id | L24: Otro | M24: UUID
A25: public | B25: setId | C25: setter | D25: no final | E25: Método encargado de colocar el valor al atributo id | F25: valorId | G25: Otro | H25: UUID | I25: Por referencia | J25: no final | K25: Nuevo valor del atributo id | L25: void
A26: public | B26: getNombre | C26: getter | D26: no final | E26: Método encargado de obtener el valor del atributo nombre | L26: String
A27: public | B27: setNombre | C27: setter | D27: no final | E27: Método encargado de colocar el valor al atributo nombre | F27: valorNombre | G27: String | I27: Por valor | J27: no final | K27: Nuevo valor del atributo nombre | L27: void
A28: Métodos
A29: Modificador de aceso | B29: Nombre | C29: Tipo acceso método | D29: Tipo modificación método | E29: Descripción | F29: Parámetros | L29: Tipo dato de retorno | N29: Excepciones
F30: Nombre | G30: Tipo de dato | H30: ¿Cuál? | I30: Tipo parámetro | J30: Tipo modificación atributo | K30: Descripción | L30: Tipo de dato | M30: ¿Cuál?
A31: public | B31: verDiasDeLaSemana | C31: no static | D31: no final | E31: Permite consultar el catálogo de días de la semana, incluyendo festivo, para definir los horarios | L31: Otro | M31: List<DiaSemana> | N31: No aplica

Sheet Departamento
A1: <-Volver al inicio
A2: =Clases!$A$1 -> Clase | B2: =Clases!A4 -> Departamento
A3: =Clases!$B$1 -> Estereotipo | B3: =Clases!B4 -> class
A4: =Clases!$C$1 -> Desripción | B4: =Clases!C4 -> Representa cada uno de los departamentos del país en los que se encuentran las ciudades donde la barbería puede tener sedes.
A5: Modificador acceso: | B5: public
A6: Tipo clase: | B6: no final
A7: Relaciones
A8: Relación | B8: Tipo relación | E8: Estructura
A9: Es usada por | B9: Composición | E9: =Ciudad!B2 -> Ciudad
A10: Atributos
A11: Modificador de aceso | B11: Nombre | C11: Tipo de dato | E11: Tipo modificación atributo | F11: Tipo acceso atributo | G11: Valor por defecto | J11: Descripción atributo
C12: Tipo de dato | D12: ¿Cuál?
A13: private | B13: id | C13: Otro | D13: UUID | E13: no final | F13: no static | G13: new UUID(0L, 0L) | J13: Representa un identificador que hará unico cada objeto de dominio de este tipo, no se puede repetir
A14: private | B14: nombre | C14: String | E14: no final | F14: no static | G14: "" | J14: Representa el nombre del departamento en el que están ubicadas las ciudades donde la barbería puede tener sedes
A15: Constructores
A16: Modificador de aceso | B16: Nombre | C16: Tipo constructor | D16: Descripción | E16: Parámetros | M16: Excepciones
E17: Nombre | F17: Tipo de dato | G17: ¿Cuál? | H17: Tipo parámetro | I17: Tipo modificación atributo | J17: Descripción
A18: public | B18: =B2 -> Departamento | C18: Defecto | D18: Constructor por defecto que crea un objeto Departamento con todos sus atributos en su valor por defecto
A19: public | B19: =B2 -> Departamento | C19: Parametrizado | D19: Constructor parametrizado que crea un objeto Departamento asignando el valor recibido a cada uno de sus atributos | E19: valorId | F19: Otro | G19: UUID | H19: Por referencia | I19: no final | J19: Valor que se asigna al atributo id
E20: valorNombre | F20: String | H20: Por valor | I20: no final | J20: Valor que se asigna al atributo nombre
A21: Métodos accesores
A22: Modificador de aceso | B22: Nombre | C22: Tipo método accesor | D22: Tipo modificación método | E22: Descripción | F22: Parámetros | L22: Tipo dato de retorno | N22: Excepciones
F23: Nombre | G23: Tipo de dato | H23: ¿Cuál? | I23: Tipo parámetro | J23: Tipo modificación atributo | K23: Descripción | L23: Tipo de dato | M23: ¿Cuál?
A24: public | B24: getId | C24: getter | D24: no final | E24: Método encargado de obtener el valor del atributo id | L24: Otro | M24: UUID
A25: public | B25: setId | C25: setter | D25: no final | E25: Método encargado de colocar el valor al atributo id | F25: valorId | G25: Otro | H25: UUID | I25: Por referencia | J25: no final | K25: Nuevo valor del atributo id | L25: void
A26: public | B26: getNombre | C26: getter | D26: no final | E26: Método encargado de obtener el valor del atributo nombre | L26: String
A27: public | B27: setNombre | C27: setter | D27: no final | E27: Método encargado de colocar el valor al atributo nombre | F27: valorNombre | G27: String | I27: Por valor | J27: no final | K27: Nuevo valor del atributo nombre | L27: void
A28: Métodos
A29: Modificador de aceso | B29: Nombre | C29: Tipo acceso método | D29: Tipo modificación método | E29: Descripción | F29: Parámetros | L29: Tipo dato de retorno | N29: Excepciones
F30: Nombre | G30: Tipo de dato | H30: ¿Cuál? | I30: Tipo parámetro | J30: Tipo modificación atributo | K30: Descripción | L30: Tipo de dato | M30: ¿Cuál?
A31: public | B31: consultarDepartamentos | C31: no static | D31: no final | E31: Permite consultar el catálogo de departamentos disponibles | L31: Otro | M31: List<Departamento> | N31: No aplica

Sheet Estado
A1: <-Volver al inicio
A2: =Clases!$A$1 -> Clase | B2: =Clases!A5 -> Estado
A3: =Clases!$B$1 -> Estereotipo | B3: =Clases!B5 -> class
A4: =Clases!$C$1 -> Desripción | B4: =Clases!C5 -> Representa en qué situación puntual se encuentra una cita: agendada, finalizada, cancelada por alguna de las partes, con tardanza del cliente o del barbero, o con inasistencia del cliente.
A5: Modificador acceso: | B5: public
A6: Tipo clase: | B6: no final
A7: Relaciones
A8: Relación | B8: Tipo relación | E8: Estructura
A9: Es usada por | B9: Asociación | E9: =Cita!B2 -> Cita
A10: Atributos
A11: Modificador de aceso | B11: Nombre | C11: Tipo de dato | E11: Tipo modificación atributo | F11: Tipo acceso atributo | G11: Valor por defecto | J11: Descripción atributo
C12: Tipo de dato | D12: ¿Cuál?
A13: private | B13: id | C13: Otro | D13: UUID | E13: no final | F13: no static | G13: new UUID(0L, 0L) | J13: Representa un identificador que hará unico cada objeto de dominio de este tipo, no se puede repetir
A14: private | B14: nombre | C14: String | E14: no final | F14: no static | G14: "" | J14: Representa como se llama el estado en el que se encuentra una cita puntual
A15: private | B15: descripcion | C15: String | E15: no final | F15: no static | G15: "" | J15: Representa el significado de que representa cada estado para la cita
A16: Constructores
A17: Modificador de aceso | B17: Nombre | C17: Tipo constructor | D17: Descripción | E17: Parámetros | M17: Excepciones
E18: Nombre | F18: Tipo de dato | G18: ¿Cuál? | H18: Tipo parámetro | I18: Tipo modificación atributo | J18: Descripción
A19: public | B19: =B2 -> Estado | C19: Defecto | D19: Constructor por defecto que crea un objeto Estado con todos sus atributos en su valor por defecto
A20: public | B20: =B2 -> Estado | C20: Parametrizado | D20: Constructor parametrizado que crea un objeto Estado asignando el valor recibido a cada uno de sus atributos | E20: valorId | F20: Otro | G20: UUID | H20: Por referencia | I20: no final | J20: Valor que se asigna al atributo id
E21: valorNombre | F21: String | H21: Por valor | I21: no final | J21: Valor que se asigna al atributo nombre
E22: valorDescripcion | F22: String | H22: Por valor | I22: no final | J22: Valor que se asigna al atributo descripcion
A23: Métodos accesores
A24: Modificador de aceso | B24: Nombre | C24: Tipo método accesor | D24: Tipo modificación método | E24: Descripción | F24: Parámetros | L24: Tipo dato de retorno | N24: Excepciones
F25: Nombre | G25: Tipo de dato | H25: ¿Cuál? | I25: Tipo parámetro | J25: Tipo modificación atributo | K25: Descripción | L25: Tipo de dato | M25: ¿Cuál?
A26: public | B26: getId | C26: getter | D26: no final | E26: Método encargado de obtener el valor del atributo id | L26: Otro | M26: UUID
A27: public | B27: setId | C27: setter | D27: no final | E27: Método encargado de colocar el valor al atributo id | F27: valorId | G27: Otro | H27: UUID | I27: Por referencia | J27: no final | K27: Nuevo valor del atributo id | L27: void
A28: public | B28: getNombre | C28: getter | D28: no final | E28: Método encargado de obtener el valor del atributo nombre | L28: String
A29: public | B29: setNombre | C29: setter | D29: no final | E29: Método encargado de colocar el valor al atributo nombre | F29: valorNombre | G29: String | I29: Por valor | J29: no final | K29: Nuevo valor del atributo nombre | L29: void
A30: public | B30: getDescripcion | C30: getter | D30: no final | E30: Método encargado de obtener el valor del atributo descripcion | L30: String
A31: public | B31: setDescripcion | C31: setter | D31: no final | E31: Método encargado de colocar el valor al atributo descripcion | F31: valorDescripcion | G31: String | I31: Por valor | J31: no final | K31: Nuevo valor del atributo descripcion | L31: void
A32: Métodos
A33: Modificador de aceso | B33: Nombre | C33: Tipo acceso método | D33: Tipo modificación método | E33: Descripción | F33: Parámetros | L33: Tipo dato de retorno | N33: Excepciones
F34: Nombre | G34: Tipo de dato | H34: ¿Cuál? | I34: Tipo parámetro | J34: Tipo modificación atributo | K34: Descripción | L34: Tipo de dato | M34: ¿Cuál?
A35: public | B35: consultarTodosLosEstados | C35: no static | D35: no final | E35: Permite consultar los estados posibles que puede tener una cita | L35: Otro | M35: List<Estado> | N35: No aplica
A36: public | B36: editarDescripcion | C36: no static | D36: no final | E36: Permite ajustar el texto descriptivo de un estado ya creado, sin cambiar su significado en el flujo de la cita | F36: id | G36: Otro | H36: UUID | I36: Por referencia | J36: no final | K36: Corresponde al identificador del estado que se va a editar | L36: void | N36: Informar con un mensaje que no existe un estado con el identificador enviado y por lo tanto no es posible modificar la descripción; Generar una excepción indicándole al usuario cuáles datos de la descripción del estado no cumplen con las reglas definidas
F37: descripcion | G37: String | I37: Por valor | J37: no final | K37: Representa el significado de que representa cada estado para la cita
A38: public | B38: consultarDescripcion | C38: no static | D38: no final | E38: Permite consultar la descripcion de un estado en especifico | F38: nombre | G38: String | I38: Por valor | J38: no final | K38: Representa como se llama el estado en el que se encuentra una cita puntual | L38: String | N38: Informar con un mensaje que no existe un Estado con el identificador enviado y por lo tanto no es posible modificar la descripción

Sheet PrefijoCelular
A1: <-Volver al inicio
A2: =Clases!$A$1 -> Clase | B2: =Clases!A6 -> PrefijoCelular
A3: =Clases!$B$1 -> Estereotipo | B3: =Clases!B6 -> class
A4: =Clases!$C$1 -> Desripción | B4: =Clases!C6 -> Representa el catálogo de prefijos telefónicos de país que el administrador habilita, y que son los únicos que barberos y clientes pueden usar en su número de celular.
A5: Modificador acceso: | B5: public
A6: Tipo clase: | B6: no final
A7: Relaciones
A8: Relación | B8: Tipo relación | E8: Estructura
A9: Es usada por | B9: Asociación | E9: =Cliente!B2 -> Cliente
A10: Es usada por | B10: Asociación | E10: =Barbero!B2 -> Barbero
A11: Atributos
A12: Modificador de aceso | B12: Nombre | C12: Tipo de dato | E12: Tipo modificación atributo | F12: Tipo acceso atributo | G12: Valor por defecto | J12: Descripción atributo
C13: Tipo de dato | D13: ¿Cuál?
A14: private | B14: id | C14: Otro | D14: UUID | E14: no final | F14: no static | G14: new UUID(0L, 0L) | J14: Representa un identificador que hará unico cada objeto de dominio de este tipo, no se puede repetir
A15: private | B15: prefijo | C15: String | E15: no final | F15: no static | G15: "+0" | J15: Representa el prefijo telefónico del país que el administrador habilita para que la barbería pueda atender números de ese país
A16: Constructores
A17: Modificador de aceso | B17: Nombre | C17: Tipo constructor | D17: Descripción | E17: Parámetros | M17: Excepciones
E18: Nombre | F18: Tipo de dato | G18: ¿Cuál? | H18: Tipo parámetro | I18: Tipo modificación atributo | J18: Descripción
A19: public | B19: =B2 -> PrefijoCelular | C19: Defecto | D19: Constructor por defecto que crea un objeto PrefijoCelular con todos sus atributos en su valor por defecto
A20: public | B20: =B2 -> PrefijoCelular | C20: Parametrizado | D20: Constructor parametrizado que crea un objeto PrefijoCelular asignando el valor recibido a cada uno de sus atributos | E20: valorId | F20: Otro | G20: UUID | H20: Por referencia | I20: no final | J20: Valor que se asigna al atributo id
E21: valorPrefijo | F21: String | H21: Por valor | I21: no final | J21: Valor que se asigna al atributo prefijo
A22: Métodos accesores
A23: Modificador de aceso | B23: Nombre | C23: Tipo método accesor | D23: Tipo modificación método | E23: Descripción | F23: Parámetros | L23: Tipo dato de retorno | N23: Excepciones
F24: Nombre | G24: Tipo de dato | H24: ¿Cuál? | I24: Tipo parámetro | J24: Tipo modificación atributo | K24: Descripción | L24: Tipo de dato | M24: ¿Cuál?
A25: public | B25: getId | C25: getter | D25: no final | E25: Método encargado de obtener el valor del atributo id | L25: Otro | M25: UUID
A26: public | B26: setId | C26: setter | D26: no final | E26: Método encargado de colocar el valor al atributo id | F26: valorId | G26: Otro | H26: UUID | I26: Por referencia | J26: no final | K26: Nuevo valor del atributo id | L26: void
A27: public | B27: getPrefijo | C27: getter | D27: no final | E27: Método encargado de obtener el valor del atributo prefijo | L27: String
A28: public | B28: setPrefijo | C28: setter | D28: no final | E28: Método encargado de colocar el valor al atributo prefijo | F28: valorPrefijo | G28: String | I28: Por valor | J28: no final | K28: Nuevo valor del atributo prefijo | L28: void
A29: Métodos
A30: Modificador de aceso | B30: Nombre | C30: Tipo acceso método | D30: Tipo modificación método | E30: Descripción | F30: Parámetros | L30: Tipo dato de retorno | N30: Excepciones
F31: Nombre | G31: Tipo de dato | H31: ¿Cuál? | I31: Tipo parámetro | J31: Tipo modificación atributo | K31: Descripción | L31: Tipo de dato | M31: ¿Cuál?
A32: public | B32: consultarPrefijosCelular | C32: no static | D32: no final | E32: Permite al administrador consultar el catálogo de prefijos telefónicos de país que tiene habilitados | L32: Otro | M32: List<PrefijoCelular> | N32: No aplica

Sheet TipoMulta
A1: <-Volver al inicio
A2: =Clases!$A$1 -> Clase | B2: =Clases!A7 -> TipoMulta
A3: =Clases!$B$1 -> Estereotipo | B3: =Clases!B7 -> class
A4: =Clases!$C$1 -> Desripción | B4: =Clases!C7 -> Representa los tipos de multa que puede recibir un cliente: por tardanza o por inasistencia.
A5: Modificador acceso: | B5: public
A6: Tipo clase: | B6: no final
A7: Relaciones
A8: Relación | B8: Tipo relación | E8: Estructura
A9: Es usada por | B9: Asociación | E9: =Multa!B2 -> Multa
A10: Atributos
A11: Modificador de aceso | B11: Nombre | C11: Tipo de dato | E11: Tipo modificación atributo | F11: Tipo acceso atributo | G11: Valor por defecto | J11: Descripción atributo
C12: Tipo de dato | D12: ¿Cuál?
A13: private | B13: id | C13: Otro | D13: UUID | E13: no final | F13: no static | G13: new UUID(0L, 0L) | J13: Representa un identificador que hará unico cada objeto de dominio de este tipo, no se puede repetir
A14: private | B14: nombre | C14: String | E14: no final | F14: no static | G14: "" | J14: Representa el nombre del tipo de multa
A15: private | B15: descripcion | C15: String | E15: no final | F15: no static | G15: "" | J15: Representa que hace cada tipo de multa
A16: Constructores
A17: Modificador de aceso | B17: Nombre | C17: Tipo constructor | D17: Descripción | E17: Parámetros | M17: Excepciones
E18: Nombre | F18: Tipo de dato | G18: ¿Cuál? | H18: Tipo parámetro | I18: Tipo modificación atributo | J18: Descripción
A19: public | B19: =B2 -> TipoMulta | C19: Defecto | D19: Constructor por defecto que crea un objeto TipoMulta con todos sus atributos en su valor por defecto
A20: public | B20: =B2 -> TipoMulta | C20: Parametrizado | D20: Constructor parametrizado que crea un objeto TipoMulta asignando el valor recibido a cada uno de sus atributos | E20: valorId | F20: Otro | G20: UUID | H20: Por referencia | I20: no final | J20: Valor que se asigna al atributo id
E21: valorNombre | F21: String | H21: Por valor | I21: no final | J21: Valor que se asigna al atributo nombre
E22: valorDescripcion | F22: String | H22: Por valor | I22: no final | J22: Valor que se asigna al atributo descripcion
A23: Métodos accesores
A24: Modificador de aceso | B24: Nombre | C24: Tipo método accesor | D24: Tipo modificación método | E24: Descripción | F24: Parámetros | L24: Tipo dato de retorno | N24: Excepciones
F25: Nombre | G25: Tipo de dato | H25: ¿Cuál? | I25: Tipo parámetro | J25: Tipo modificación atributo | K25: Descripción | L25: Tipo de dato | M25: ¿Cuál?
A26: public | B26: getId | C26: getter | D26: no final | E26: Método encargado de obtener el valor del atributo id | L26: Otro | M26: UUID
A27: public | B27: setId | C27: setter | D27: no final | E27: Método encargado de colocar el valor al atributo id | F27: valorId | G27: Otro | H27: UUID | I27: Por referencia | J27: no final | K27: Nuevo valor del atributo id | L27: void
A28: public | B28: getNombre | C28: getter | D28: no final | E28: Método encargado de obtener el valor del atributo nombre | L28: String
A29: public | B29: setNombre | C29: setter | D29: no final | E29: Método encargado de colocar el valor al atributo nombre | F29: valorNombre | G29: String | I29: Por valor | J29: no final | K29: Nuevo valor del atributo nombre | L29: void
A30: public | B30: getDescripcion | C30: getter | D30: no final | E30: Método encargado de obtener el valor del atributo descripcion | L30: String
A31: public | B31: setDescripcion | C31: setter | D31: no final | E31: Método encargado de colocar el valor al atributo descripcion | F31: valorDescripcion | G31: String | I31: Por valor | J31: no final | K31: Nuevo valor del atributo descripcion | L31: void
A32: Métodos
A33: Modificador de aceso | B33: Nombre | C33: Tipo acceso método | D33: Tipo modificación método | E33: Descripción | F33: Parámetros | L33: Tipo dato de retorno | N33: Excepciones
F34: Nombre | G34: Tipo de dato | H34: ¿Cuál? | I34: Tipo parámetro | J34: Tipo modificación atributo | K34: Descripción | L34: Tipo de dato | M34: ¿Cuál?
A35: public | B35: consultarTodosLosTiposMulta | C35: no static | D35: no final | E35: Permite consultar los tipos de multa que puede recibir un cliente | L35: Otro | M35: List<TipoMulta> | N35: No aplica

Sheet TipoRegistroHora
A1: <-Volver al inicio
A2: =Clases!$A$1 -> Clase | B2: =Clases!A8 -> TipoRegistroHora
A3: =Clases!$B$1 -> Estereotipo | B3: =Clases!B8 -> class
A4: =Clases!$C$1 -> Desripción | B4: =Clases!C8 -> Representa el catálogo de los distintos momentos en que se puede registrar una hora real durante una cita: llegada del cliente, barbero preparado, inicio y fin de la atención.
A5: Modificador acceso: | B5: public
A6: Tipo clase: | B6: no final
A7: Relaciones
A8: Relación | B8: Tipo relación | E8: Estructura
A9: Es usada por | B9: Asociación | E9: =RegistroHoraCita!B2 -> RegistroHoraCita
A10: Atributos
A11: Modificador de aceso | B11: Nombre | C11: Tipo de dato | E11: Tipo modificación atributo | F11: Tipo acceso atributo | G11: Valor por defecto | J11: Descripción atributo
C12: Tipo de dato | D12: ¿Cuál?
A13: private | B13: id | C13: Otro | D13: UUID | E13: no final | F13: no static | G13: new UUID(0L, 0L) | J13: Representa un identificador que hará unico cada objeto de dominio de este tipo, no se puede repetir
A14: private | B14: nombre | C14: String | E14: no final | F14: no static | G14: "" | J14: Representa el nombre del tipo de hora real que se puede registrar durante una cita
A15: Constructores
A16: Modificador de aceso | B16: Nombre | C16: Tipo constructor | D16: Descripción | E16: Parámetros | M16: Excepciones
E17: Nombre | F17: Tipo de dato | G17: ¿Cuál? | H17: Tipo parámetro | I17: Tipo modificación atributo | J17: Descripción
A18: public | B18: =B2 -> TipoRegistroHora | C18: Defecto | D18: Constructor por defecto que crea un objeto TipoRegistroHora con todos sus atributos en su valor por defecto
A19: public | B19: =B2 -> TipoRegistroHora | C19: Parametrizado | D19: Constructor parametrizado que crea un objeto TipoRegistroHora asignando el valor recibido a cada uno de sus atributos | E19: valorId | F19: Otro | G19: UUID | H19: Por referencia | I19: no final | J19: Valor que se asigna al atributo id
E20: valorNombre | F20: String | H20: Por valor | I20: no final | J20: Valor que se asigna al atributo nombre
A21: Métodos accesores
A22: Modificador de aceso | B22: Nombre | C22: Tipo método accesor | D22: Tipo modificación método | E22: Descripción | F22: Parámetros | L22: Tipo dato de retorno | N22: Excepciones
F23: Nombre | G23: Tipo de dato | H23: ¿Cuál? | I23: Tipo parámetro | J23: Tipo modificación atributo | K23: Descripción | L23: Tipo de dato | M23: ¿Cuál?
A24: public | B24: getId | C24: getter | D24: no final | E24: Método encargado de obtener el valor del atributo id | L24: Otro | M24: UUID
A25: public | B25: setId | C25: setter | D25: no final | E25: Método encargado de colocar el valor al atributo id | F25: valorId | G25: Otro | H25: UUID | I25: Por referencia | J25: no final | K25: Nuevo valor del atributo id | L25: void
A26: public | B26: getNombre | C26: getter | D26: no final | E26: Método encargado de obtener el valor del atributo nombre | L26: String
A27: public | B27: setNombre | C27: setter | D27: no final | E27: Método encargado de colocar el valor al atributo nombre | F27: valorNombre | G27: String | I27: Por valor | J27: no final | K27: Nuevo valor del atributo nombre | L27: void
A28: Métodos
A29: Modificador de aceso | B29: Nombre | C29: Tipo acceso método | D29: Tipo modificación método | E29: Descripción | F29: Parámetros | L29: Tipo dato de retorno | N29: Excepciones
F30: Nombre | G30: Tipo de dato | H30: ¿Cuál? | I30: Tipo parámetro | J30: Tipo modificación atributo | K30: Descripción | L30: Tipo de dato | M30: ¿Cuál?
A31: public | B31: consultarTiposRegistroHora | C31: no static | D31: no final | E31: Permite consultar el catálogo de tipos de registro de hora de una cita | L31: Otro | M31: List<TipoRegistroHora> | N31: No aplica

Sheet Cliente
A1: <-Volver al inicio
A2: =Clases!$A$1 -> Clase | B2: =Clases!A9 -> Cliente
A3: =Clases!$B$1 -> Estereotipo | B3: =Clases!B9 -> class
A4: =Clases!$C$1 -> Desripción | B4: =Clases!C9 -> Representa a la persona que solicita citas en la barbería.
A5: Modificador acceso: | B5: public
A6: Tipo clase: | B6: no final
A7: Relaciones
A8: Relación | B8: Tipo relación | E8: Estructura
A9: Necesita de | B9: Asociación | E9: =PrefijoCelular!B2 -> PrefijoCelular
A10: Es usada por | B10: Composición | E10: =Cita!B2 -> Cita
A11: Atributos
A12: Modificador de aceso | B12: Nombre | C12: Tipo de dato | E12: Tipo modificación atributo | F12: Tipo acceso atributo | G12: Valor por defecto | J12: Descripción atributo
C13: Tipo de dato | D13: ¿Cuál?
A14: private | B14: id | C14: Otro | D14: UUID | E14: no final | F14: no static | G14: new UUID(0L, 0L) | J14: Representa un identificador que hará unico cada objeto de dominio de este tipo, no se puede repetir
A15: private | B15: primerNombre | C15: String | E15: no final | F15: no static | G15: "" | J15: Representa el primer nombre de la persona, que va a estar llendo a la barberia para las citas
A16: private | B16: segundoNombre | C16: String | E16: no final | F16: no static | G16: "" | J16: Representa el segundo nombre de la persona, que va a estar llendo a la barberia para las citas
A17: private | B17: primerApellido | C17: String | E17: no final | F17: no static | G17: "" | J17: Representa el primer apellido de la persona, que va a estar llendo a la barberia para las citas
A18: private | B18: segundoApellido | C18: String | E18: no final | F18: no static | G18: "" | J18: Representa el segundo apellido de la persona, que va a estar llendo a la barberia para las citas
A19: private | B19: prefijoCelular | C19: Otro | D19: PrefijoCelular | E19: no final | F19: no static | G19: new PrefijoCelular() | J19: Representa cual es el prefijo del numero de celular del cliente
A20: private | B20: celular | C20: String | E20: no final | F20: no static | G20: "0" | J20: Representa el numero de celular del cliente, es el dato que el barbero necesita en caso de que tenga que contactarse con el
A21: private | B21: elNumeroCelularEsCorrecto | C21: boolean/Boolean | E21: no final | F21: no static | G21: false | J21: Representa si el numero que ingreso el cliente es correcto o no
A22: private | B22: estaVetado | C22: boolean/Boolean | E22: no final | F22: no static | G22: false | J22: Representa si el cliente esta en estado de veto o no, cuando el cliente esta vetado el sistema no va a permitir agendar citas con este cliente con ningun barbero
A23: Constructores
A24: Modificador de aceso | B24: Nombre | C24: Tipo constructor | D24: Descripción | E24: Parámetros | M24: Excepciones
E25: Nombre | F25: Tipo de dato | G25: ¿Cuál? | H25: Tipo parámetro | I25: Tipo modificación atributo | J25: Descripción
A26: public | B26: =B2 -> Cliente | C26: Defecto | D26: Constructor por defecto que crea un objeto Cliente con todos sus atributos en su valor por defecto
A27: public | B27: =B2 -> Cliente | C27: Parametrizado | D27: Constructor parametrizado que crea un objeto Cliente asignando el valor recibido a cada uno de sus atributos | E27: valorId | F27: Otro | G27: UUID | H27: Por referencia | I27: no final | J27: Valor que se asigna al atributo id
E28: valorPrimerNombre | F28: String | H28: Por valor | I28: no final | J28: Valor que se asigna al atributo primerNombre
E29: valorSegundoNombre | F29: String | H29: Por valor | I29: no final | J29: Valor que se asigna al atributo segundoNombre
E30: valorPrimerApellido | F30: String | H30: Por valor | I30: no final | J30: Valor que se asigna al atributo primerApellido
E31: valorSegundoApellido | F31: String | H31: Por valor | I31: no final | J31: Valor que se asigna al atributo segundoApellido
E32: valorPrefijoCelular | F32: Otro | G32: PrefijoCelular | H32: Por referencia | I32: no final | J32: Valor que se asigna al atributo prefijoCelular
E33: valorCelular | F33: String | H33: Por valor | I33: no final | J33: Valor que se asigna al atributo celular
E34: valorElNumeroCelularEsCorrecto | F34: boolean/Boolean | H34: Por valor | I34: no final | J34: Valor que se asigna al atributo elNumeroCelularEsCorrecto
E35: valorEstaVetado | F35: boolean/Boolean | H35: Por valor | I35: no final | J35: Valor que se asigna al atributo estaVetado
A36: Métodos accesores
A37: Modificador de aceso | B37: Nombre | C37: Tipo método accesor | D37: Tipo modificación método | E37: Descripción | F37: Parámetros | L37: Tipo dato de retorno | N37: Excepciones
F38: Nombre | G38: Tipo de dato | H38: ¿Cuál? | I38: Tipo parámetro | J38: Tipo modificación atributo | K38: Descripción | L38: Tipo de dato | M38: ¿Cuál?
A39: public | B39: getId | C39: getter | D39: no final | E39: Método encargado de obtener el valor del atributo id | L39: Otro | M39: UUID
A40: public | B40: setId | C40: setter | D40: no final | E40: Método encargado de colocar el valor al atributo id | F40: valorId | G40: Otro | H40: UUID | I40: Por referencia | J40: no final | K40: Nuevo valor del atributo id | L40: void
...

Sheet Ciudad
A1: <-Volver al inicio
A2: =Clases!$A$1 -> Clase | B2: =Clases!A10 -> Ciudad
A3: =Clases!$B$1 -> Estereotipo | B3: =Clases!B10 -> class
A4: =Clases!$C$1 -> Desripción | B4: =Clases!C10 -> Representa cada una de las ciudades, pertenecientes a un departamento, en las que puede estar ubicada una sede de la barbería.
A5: Modificador acceso: | B5: public
A6: Tipo clase: | B6: no final
A7: Relaciones
A8: Relación | B8: Tipo relación | E8: Estructura
A9: Necesita de | B9: Composición | E9: =Departamento!B2 -> Departamento
A10: Es usada por | B10: Agregación | E10: =Sede!B2 -> Sede
A11: Atributos
A12: Modificador de aceso | B12: Nombre | C12: Tipo de dato | E12: Tipo modificación atributo | F12: Tipo acceso atributo | G12: Valor por defecto | J12: Descripción atributo
C13: Tipo de dato | D13: ¿Cuál?
A14: private | B14: id | C14: Otro | D14: UUID | E14: no final | F14: no static | G14: new UUID(0L, 0L) | J14: Representa un identificador que hará unico cada objeto de dominio de este tipo, no se puede repetir
A15: private | B15: nombre | C15: String | E15: no final | F15: no static | G15: "" | J15: Representa el nombre de la ciudad en la que puede estar ubicada una sede de la barbería
A16: private | B16: departamento | C16: Otro | D16: Departamento | E16: no final | F16: no static | G16: new Departamento() | J16: Representa a qué departamento pertenece esta ciudad
A17: Constructores
A18: Modificador de aceso | B18: Nombre | C18: Tipo constructor | D18: Descripción | E18: Parámetros | M18: Excepciones
E19: Nombre | F19: Tipo de dato | G19: ¿Cuál? | H19: Tipo parámetro | I19: Tipo modificación atributo | J19: Descripción
A20: public | B20: =B2 -> Ciudad | C20: Defecto | D20: Constructor por defecto que crea un objeto Ciudad con todos sus atributos en su valor por defecto
A21: public | B21: =B2 -> Ciudad | C21: Parametrizado | D21: Constructor parametrizado que crea un objeto Ciudad asignando el valor recibido a cada uno de sus atributos | E21: valorId | F21: Otro | G21: UUID | H21: Por referencia | I21: no final | J21: Valor que se asigna al atributo id
E22: valorNombre | F22: String | H22: Por valor | I22: no final | J22: Valor que se asigna al atributo nombre
E23: valorDepartamento | F23: Otro | G23: Departamento | H23: Por referencia | I23: no final | J23: Valor que se asigna al atributo departamento
A24: Métodos accesores
A25: Modificador de aceso | B25: Nombre | C25: Tipo método accesor | D25: Tipo modificación método | E25: Descripción | F25: Parámetros | L25: Tipo dato de retorno | N25: Excepciones
F26: Nombre | G26: Tipo de dato | H26: ¿Cuál? | I26: Tipo parámetro | J26: Tipo modificación atributo | K26: Descripción | L26: Tipo de dato | M26: ¿Cuál?
A27: public | B27: getId | C27: getter | D27: no final | E27: Método encargado de obtener el valor del atributo id | L27: Otro | M27: UUID
A28: public | B28: setId | C28: setter | D28: no final | E28: Método encargado de colocar el valor al atributo id | F28: valorId | G28: Otro | H28: UUID | I28: Por referencia | J28: no final | K28: Nuevo valor del atributo id | L28: void
A29: public | B29: getNombre | C29: getter | D29: no final | E29: Método encargado de obtener el valor del atributo nombre | L29: String
A30: public | B30: setNombre | C30: setter | D30: no final | E30: Método encargado de colocar el valor al atributo nombre | F30: valorNombre | G30: String | I30: Por valor | J30: no final | K30: Nuevo valor del atributo nombre | L30: void
A31: public | B31: getDepartamento | C31: getter | D31: no final | E31: Método encargado de obtener el valor del atributo departamento | L31: Otro | M31: Departamento
A32: public | B32: setDepartamento | C32: setter | D32: no final | E32: Método encargado de colocar el valor al atributo departamento | F32: valorDepartamento | G32: Otro | H32: Departamento | I32: Por referencia | J32: no final | K32: Nuevo valor del atributo departamento | L32: void
A33: Métodos
A34: Modificador de aceso | B34: Nombre | C34: Tipo acceso método | D34: Tipo modificación método | E34: Descripción | F34: Parámetros | L34: Tipo dato de retorno | N34: Excepciones
F35: Nombre | G35: Tipo de dato | H35: ¿Cuál? | I35: Tipo parámetro | J35: Tipo modificación atributo | K35: Descripción | L35: Tipo de dato | M35: ¿Cuál?
A36: public | B36: consultarCiudades | C36: no static | D36: no final | E36: Permite consultar el catálogo de ciudades con su departamento | L36: Otro | M36: List<Ciudad> | N36: No aplica

Sheet Sede
A1: <-Volver al inicio
A2: =Clases!$A$1 -> Clase | B2: =Clases!A11 -> Sede
A3: =Clases!$B$1 -> Estereotipo | B3: =Clases!B11 -> class
A4: =Clases!$C$1 -> Desripción | B4: =Clases!C11 -> Representa cada una de las sucursales físicas de una barbería, ubicada en una ciudad puntual, donde se ofrecen los servicios y trabajan los barberos.
A5: Modificador acceso: | B5: public
A6: Tipo clase: | B6: no final
A7: Relaciones
A8: Relación | B8: Tipo relación | E8: Estructura
A9: Necesita de | B9: Agregación | E9: =Ciudad!B2 -> Ciudad
A10: Necesita de | B10: Composición | E10: =Barberia!B2 -> Barberia
A11: Es usada por | B11: Agregación | E11: =Barbero!B2 -> Barbero
A12: Es usada por | B12: Composición | E12: =HorarioBarberia!B2 -> HorarioBarberia
A13: Es usada por | B13: Asociación | E13: =Servicio!B2 -> Servicio
A14: Atributos
A15: Modificador de aceso | B15: Nombre | C15: Tipo de dato | E15: Tipo modificación atributo | F15: Tipo acceso atributo | G15: Valor por defecto | J15: Descripción atributo
C16: Tipo de dato | D16: ¿Cuál?
A17: private | B17: id | C17: Otro | D17: UUID | E17: no final | F17: no static | G17: new UUID(0L, 0L) | J17: Representa un identificador que hará unico cada objeto de dominio de este tipo, no se puede repetir
A18: private | B18: ciudad | C18: Otro | D18: Ciudad | E18: no final | F18: no static | G18: new Ciudad() | J18: Representa a qué ciudad pertenece esta sede
A19: private | B19: barberia | C19: Otro | D19: Barberia | E19: no final | F19: no static | G19: new Barberia() | J19: Representa a qué barbería pertenece esta sede
A20: private | B20: nombre | C20: String | E20: no final | F20: no static | G20: "" | J20: Representa el nombre con el que se identifica esta sede dentro de la barbería a la que pertenece
A21: private | B21: direccion | C21: String | E21: no final | F21: no static | G21: "" | J21: Representa la dirección física en la que está ubicada esta sede
A22: Constructores
A23: Modificador de aceso | B23: Nombre | C23: Tipo constructor | D23: Descripción | E23: Parámetros | M23: Excepciones
E24: Nombre | F24: Tipo de dato | G24: ¿Cuál? | H24: Tipo parámetro | I24: Tipo modificación atributo | J24: Descripción
A25: public | B25: =B2 -> Sede | C25: Defecto | D25: Constructor por defecto que crea un objeto Sede con todos sus atributos en su valor por defecto
A26: public | B26: =B2 -> Sede | C26: Parametrizado | D26: Constructor parametrizado que crea un objeto Sede asignando el valor recibido a cada uno de sus atributos | E26: valorId | F26: Otro | G26: UUID | H26: Por referencia | I26: no final | J26: Valor que se asigna al atributo id
E27: valorCiudad | F27: Otro | G27: Ciudad | H27: Por referencia | I27: no final | J27: Valor que se asigna al atributo ciudad
E28: valorBarberia | F28: Otro | G28: Barberia | H28: Por referencia | I28: no final | J28: Valor que se asigna al atributo barberia
E29: valorNombre | F29: String | H29: Por valor | I29: no final | J29: Valor que se asigna al atributo nombre
E30: valorDireccion | F30: String | H30: Por valor | I30: no final | J30: Valor que se asigna al atributo direccion
A31: Métodos accesores
A32: Modificador de aceso | B32: Nombre | C32: Tipo método accesor | D32: Tipo modificación método | E32: Descripción | F32: Parámetros | L32: Tipo dato de retorno | N32: Excepciones
F33: Nombre | G33: Tipo de dato | H33: ¿Cuál? | I33: Tipo parámetro | J33: Tipo modificación atributo | K33: Descripción | L33: Tipo de dato | M33: ¿Cuál?
A34: public | B34: getId | C34: getter | D34: no final | E34: Método encargado de obtener el valor del atributo id | L34: Otro | M34: UUID
A35: public | B35: setId | C35: setter | D35: no final | E35: Método encargado de colocar el valor al atributo id | F35: valorId | G35: Otro | H35: UUID | I35: Por referencia | J35: no final | K35: Nuevo valor del atributo id | L35: void
A36: public | B36: getCiudad | C36: getter | D36: no final | E36: Método encargado de obtener el valor del atributo ciudad | L36: Otro | M36: Ciudad
A37: public | B37: setCiudad | C37: setter | D37: no final | E37: Método encargado de colocar el valor al atributo ciudad | F37: valorCiudad | G37: Otro | H37: Ciudad | I37: Por referencia | J37: no final | K37: Nuevo valor del atributo ciudad | L37: void
A38: public | B38: getBarberia | C38: getter | D38: no final | E38: Método encargado de obtener el valor del atributo barberia | L38: Otro | M38: Barberia
A39: public | B39: setBarberia | C39: setter | D39: no final | E39: Método encargado de colocar el valor al atributo barberia | F39: valorBarberia | G39: Otro | H39: Barberia | I39: Por referencia | J39: no final | K39: Nuevo valor del atributo barberia | L39: void
A40: public | B40: getNombre | C40: getter | D40: no final | E40: Método encargado de obtener el valor del atributo nombre | L40: String
...

Sheet Barbero
A1: <-Volver al inicio
A2: =Clases!$A$1 -> Clase | B2: =Clases!A12 -> Barbero
A3: =Clases!$B$1 -> Estereotipo | B3: =Clases!B12 -> class
A4: =Clases!$C$1 -> Desripción | B4: =Clases!C12 -> Representa a un trabajador de la barbería que atiende clientes según los servicios que sabe realizar, organiza su propio horario y tiene su agenda personal para atender todas las citas que valla teniendo.
A5: Modificador acceso: | B5: public
A6: Tipo clase: | B6: no final
A7: Relaciones
A8: Relación | B8: Tipo relación | E8: Estructura
A9: Necesita de | B9: Asociación | E9: =PrefijoCelular!B2 -> PrefijoCelular
A10: Necesita de | B10: Agregación | E10: =Sede!B2 -> Sede
A11: Es usada por | B11: Composición | E11: =BarberoServicio!B2 -> BarberoServicio
A12: Es usada por | B12: Composición | E12: =Bloqueo!B2 -> Bloqueo
A13: Es usada por | B13: Composición | E13: =HorarioBarbero!B2 -> HorarioBarbero
A14: Atributos
A15: Modificador de aceso | B15: Nombre | C15: Tipo de dato | E15: Tipo modificación atributo | F15: Tipo acceso atributo | G15: Valor por defecto | J15: Descripción atributo
C16: Tipo de dato | D16: ¿Cuál?
A17: private | B17: id | C17: Otro | D17: UUID | E17: no final | F17: no static | G17: new UUID(0L, 0L) | J17: Representa un identificador que hará unico cada objeto de dominio de este tipo, no se puede repetir
A18: private | B18: primerNombre | C18: String | E18: no final | F18: no static | G18: "" | J18: Representa el primer nombre del barbero que trabaja en barbería
A19: private | B19: segundoNombre | C19: String | E19: no final | F19: no static | G19: "" | J19: Representa el segundo nombre del barbero que trabaja en barbería
A20: private | B20: primerApellido | C20: String | E20: no final | F20: no static | G20: "" | J20: Representa el primer apellido del barbero que trabaja en la barbería
A21: private | B21: segundoApellido | C21: String | E21: no final | F21: no static | G21: "" | J21: Representa el segundo apellido del barbero que trabaja en la barbería
A22: private | B22: prefijo | C22: Otro | D22: PrefijoCelular | E22: no final | F22: no static | G22: new PrefijoCelular() | J22: Representa cual es el prefijo del numero de celular del barbero
A23: private | B23: celular | C23: String | E23: no final | F23: no static | G23: "0" | J23: Representa el número de celular del barbero, es el dato que el cliente necesita en caso de que tenga que contactarse con el
A24: private | B24: elNumeroCelularEsCorrecto | C24: boolean/Boolean | E24: no final | F24: no static | G24: false | J24: Representa si el numero que ingreso el cliente es correcto o no
A25: private | B25: vigente | C25: boolean/Boolean | E25: no final | F25: no static | G25: true | J25: Representa si el barbero sigue o no trabajando en la barberia
A26: private | B26: sedeDeTrabajo | C26: Otro | D26: Sede | E26: no final | F26: no static | G26: new Sede() | J26: Representa cual es la sede y la barberia donde trabaja el barbero
A27: Constructores
A28: Modificador de aceso | B28: Nombre | C28: Tipo constructor | D28: Descripción | E28: Parámetros | M28: Excepciones
E29: Nombre | F29: Tipo de dato | G29: ¿Cuál? | H29: Tipo parámetro | I29: Tipo modificación atributo | J29: Descripción
A30: public | B30: =B2 -> Barbero | C30: Defecto | D30: Constructor por defecto que crea un objeto Barbero con todos sus atributos en su valor por defecto
A31: public | B31: =B2 -> Barbero | C31: Parametrizado | D31: Constructor parametrizado que crea un objeto Barbero asignando el valor recibido a cada uno de sus atributos | E31: valorId | F31: Otro | G31: UUID | H31: Por referencia | I31: no final | J31: Valor que se asigna al atributo id
E32: valorPrimerNombre | F32: String | H32: Por valor | I32: no final | J32: Valor que se asigna al atributo primerNombre
E33: valorSegundoNombre | F33: String | H33: Por valor | I33: no final | J33: Valor que se asigna al atributo segundoNombre
E34: valorPrimerApellido | F34: String | H34: Por valor | I34: no final | J34: Valor que se asigna al atributo primerApellido
E35: valorSegundoApellido | F35: String | H35: Por valor | I35: no final | J35: Valor que se asigna al atributo segundoApellido
E36: valorPrefijo | F36: Otro | G36: PrefijoCelular | H36: Por referencia | I36: no final | J36: Valor que se asigna al atributo prefijo
E37: valorCelular | F37: String | H37: Por valor | I37: no final | J37: Valor que se asigna al atributo celular
E38: valorElNumeroCelularEsCorrecto | F38: boolean/Boolean | H38: Por valor | I38: no final | J38: Valor que se asigna al atributo elNumeroCelularEsCorrecto
E39: valorVigente | F39: boolean/Boolean | H39: Por valor | I39: no final | J39: Valor que se asigna al atributo vigente
E40: valorSedeDeTrabajo | F40: Otro | G40: Sede | H40: Por referencia | I40: no final | J40: Valor que se asigna al atributo sedeDeTrabajo
...

Sheet HorarioBarberia
A1: <-Volver al inicio
A2: =Clases!$A$1 -> Clase | B2: =Clases!A13 -> HorarioBarberia
A3: =Clases!$B$1 -> Estereotipo | B3: =Clases!B13 -> class
A4: =Clases!$C$1 -> Desripción | B4: =Clases!C13 -> Representa, día por día, a qué hora abre y cierra el negocio; es el límite dentro del cual debe caber el horario de cualquier barbero.
A5: Modificador acceso: | B5: public
A6: Tipo clase: | B6: no final
A7: Relaciones
A8: Relación | B8: Tipo relación | E8: Estructura
A9: Necesita de | B9: Composición | E9: =Sede!B2 -> Sede
A10: Necesita de | B10: Asociación | E10: =DiaSemana!B2 -> DiaSemana
A11: Es usada por | B11: Composición | E11: =HorarioBarbero!B2 -> HorarioBarbero
A12: Atributos
A13: Modificador de aceso | B13: Nombre | C13: Tipo de dato | E13: Tipo modificación atributo | F13: Tipo acceso atributo | G13: Valor por defecto | J13: Descripción atributo
C14: Tipo de dato | D14: ¿Cuál?
A15: private | B15: id | C15: Otro | D15: UUID | E15: no final | F15: no static | G15: new UUID(0L, 0L) | J15: Representa un identificador que hará unico cada objeto de dominio de este tipo, no se puede repetir
A16: private | B16: sedeDeLaBarberia | C16: Otro | D16: Sede | E16: no final | F16: no static | G16: new Sede() | J16: Representa a cual barberia y sede pertenece el horario de apertura y cierre
A17: private | B17: diaDeLaSemana | C17: Otro | D17: DiaSemana | E17: no final | F17: no static | G17: new DiaSemana() | J17: Representa el día de la semana en el que la barberia abre
A18: private | B18: horaApertura | C18: Otro | D18: LocalTime | E18: no final | F18: no static | G18: LocalTime.of(0, 0) | J18: Representa la hora a la que abre la barbería
A19: private | B19: horaCierre | C19: Otro | D19: LocalTime | E19: no final | F19: no static | G19: LocalTime.of(0, 0) | J19: Representa la hora a la que cierra la barbería
A20: private | B20: fechaCreacion | C20: Otro | D20: LocalDate | E20: no final | F20: no static | G20: LocalDate.of(1000, 1, 1) | J20: Representa la fecha en el que el administrador definio el horario de la barberia. Es un dato calculado que toma la fecha del sistema en ese momento
A21: private | B21: fechaDesactivacion | C21: Otro | D21: LocalDate | E21: no final | F21: no static | G21: LocalDate.of(1000, 1, 1) | J21: Representa la fecha en la que este horario dejó de estar vigente. Es un dato calculado que toma la fecha del sistema en ese momento
A22: private | B22: vigente | C22: boolean/Boolean | E22: no final | F22: no static | G22: true | J22: Representa si este horario lo sigue o no vigente en la barberia. Una vez que el administrador desactive el horario de la barberia, no se puede volver a cambiar
A23: Constructores
A24: Modificador de aceso | B24: Nombre | C24: Tipo constructor | D24: Descripción | E24: Parámetros | M24: Excepciones
E25: Nombre | F25: Tipo de dato | G25: ¿Cuál? | H25: Tipo parámetro | I25: Tipo modificación atributo | J25: Descripción
A26: public | B26: =B2 -> HorarioBarberia | C26: Defecto | D26: Constructor por defecto que crea un objeto HorarioBarberia con todos sus atributos en su valor por defecto
A27: public | B27: =B2 -> HorarioBarberia | C27: Parametrizado | D27: Constructor parametrizado que crea un objeto HorarioBarberia asignando el valor recibido a cada uno de sus atributos | E27: valorId | F27: Otro | G27: UUID | H27: Por referencia | I27: no final | J27: Valor que se asigna al atributo id
E28: valorSedeDeLaBarberia | F28: Otro | G28: Sede | H28: Por referencia | I28: no final | J28: Valor que se asigna al atributo sedeDeLaBarberia
E29: valorDiaDeLaSemana | F29: Otro | G29: DiaSemana | H29: Por referencia | I29: no final | J29: Valor que se asigna al atributo diaDeLaSemana
E30: valorHoraApertura | F30: Otro | G30: LocalTime | H30: Por referencia | I30: no final | J30: Valor que se asigna al atributo horaApertura
E31: valorHoraCierre | F31: Otro | G31: LocalTime | H31: Por referencia | I31: no final | J31: Valor que se asigna al atributo horaCierre
E32: valorFechaCreacion | F32: Otro | G32: LocalDate | H32: Por referencia | I32: no final | J32: Valor que se asigna al atributo fechaCreacion
E33: valorFechaDesactivacion | F33: Otro | G33: LocalDate | H33: Por referencia | I33: no final | J33: Valor que se asigna al atributo fechaDesactivacion
E34: valorVigente | F34: boolean/Boolean | H34: Por valor | I34: no final | J34: Valor que se asigna al atributo vigente
A35: Métodos accesores
A36: Modificador de aceso | B36: Nombre | C36: Tipo método accesor | D36: Tipo modificación método | E36: Descripción | F36: Parámetros | L36: Tipo dato de retorno | N36: Excepciones
F37: Nombre | G37: Tipo de dato | H37: ¿Cuál? | I37: Tipo parámetro | J37: Tipo modificación atributo | K37: Descripción | L37: Tipo de dato | M37: ¿Cuál?
A38: public | B38: getId | C38: getter | D38: no final | E38: Método encargado de obtener el valor del atributo id | L38: Otro | M38: UUID
A39: public | B39: setId | C39: setter | D39: no final | E39: Método encargado de colocar el valor al atributo id | F39: valorId | G39: Otro | H39: UUID | I39: Por referencia | J39: no final | K39: Nuevo valor del atributo id | L39: void
A40: public | B40: getSedeDeLaBarberia | C40: getter | D40: no final | E40: Método encargado de obtener el valor del atributo sedeDeLaBarberia | L40: Otro | M40: Sede
...

Sheet Servicio
A1: <-Volver al inicio
A2: =Clases!$A$1 -> Clase | B2: =Clases!A14 -> Servicio
A3: =Clases!$B$1 -> Estereotipo | B3: =Clases!B14 -> class
A4: =Clases!$C$1 -> Desripción | B4: =Clases!C14 -> Representa cada tipo de corte o arreglo que ofrece la barbería, definido por el administrador, para que luego cada barbero decida cuáles sabe hacer.
A5: Modificador acceso: | B5: public
A6: Tipo clase: | B6: no final
A7: Relaciones
A8: Relación | B8: Tipo relación | E8: Estructura
A9: Necesita de | B9: Asociación | E9: =Sede!B2 -> Sede
A10: Es usada por | B10: Composición | E10: =BarberoServicio!B2 -> BarberoServicio
A11: Atributos
A12: Modificador de aceso | B12: Nombre | C12: Tipo de dato | E12: Tipo modificación atributo | F12: Tipo acceso atributo | G12: Valor por defecto | J12: Descripción atributo
C13: Tipo de dato | D13: ¿Cuál?
A14: private | B14: id | C14: Otro | D14: UUID | E14: no final | F14: no static | G14: new UUID(0L, 0L) | J14: Representa un identificador que hará unico cada objeto de dominio de este tipo, no se puede repetir
A15: private | B15: sedeDeLaBarberia | C15: Otro | D15: Sede | E15: no final | F15: no static | G15: new Sede() | J15: Representa a cual barberia y sede va a pertenecer el servicio
A16: private | B16: nombre | C16: String | E16: no final | F16: no static | G16: "" | J16: Representa el nombre del servicio que va estar en la barberia, para que el barbero elija los servicios que el sabe hacer
A17: private | B17: descripcion | C17: String | E17: no final | F17: no static | G17: "" | J17: Representa una descripcion de que va a hacer cada servicio en la barberia, para que el barbero sepa que hace el servicio
A18: private | B18: precio | C18: int/Integer | E18: no final | F18: no static | G18: 0 | J18: Representa cuanto va a valer el servicio en pesos colombianos
A19: private | B19: disponible | C19: boolean/Boolean | E19: no final | F19: no static | G19: true | J19: Representa si el servicio sigue o no disponible en la barberia
A20: Constructores
A21: Modificador de aceso | B21: Nombre | C21: Tipo constructor | D21: Descripción | E21: Parámetros | M21: Excepciones
E22: Nombre | F22: Tipo de dato | G22: ¿Cuál? | H22: Tipo parámetro | I22: Tipo modificación atributo | J22: Descripción
