Workbook

Sheet Modelo de Dominio
A1: Ir a objetos de dominio >>>>

Sheet Objetos de Dominio
A1: <<<< Ir al modulo de dominio
A2: Nombre | B2: Descripcion | C2: Linea de vida | D2: Muestreo | E2: Caracterización
A3: DiaSemana | B3: Representa cada uno de los días de la semana, incluyendo festivo, que se usa como catálogo para definir los horarios de la barbería y de cada barbero | C3: 1 | D3: Ir al muestreo | E3: Ir a la caracterización
A4: Estado | B4: Representa en qué situación puntual se encuentra una cita: agendada, finalizada, cancelada por alguna de las partes, con tardanza del cliente o del barbero, o con inasistencia del cliente | C4: 1 | D4: Ir al muestreo | E4: Ir a la caracterización
A5: Servicio | B5: Representa cada tipo de corte o arreglo que ofrece la barbería, definido por el dueño, para que luego cada barbero decida cuáles sabe hacer | C5: 1 | D5: Ir al muestreo | E5: Ir a la caracterización
A6: Regla | B6: Representa las políticas de la barbería frente al incumplimiento de clientes y barberos: tolerancias de tardanza, monto de la multa fija, número máximo de multas sin pagar antes del veto, y el descuento que se da cuando el barbero se demora | C6: 1 | D6: Ir al muestreo | E6: Ir a la caracterización
A7: PrefijoCelular | B7: Representa el catálogo de prefijos telefónicos de país disponibles para el número de celular de barberos y clientes | C7: 1 | D7: Ir al muestreo | E7: Ir a la caracterización
A8: TipoMulta | B8: Representa los tipos de multa que puede recibir un cliente: por tardanza o por inasistencia | C8: 1 | D8: Ir al muestreo | E8: Ir a la caracterización
A9: Barbero | B9: Representa a un trabajador de la barbería que atiende clientes según los servicios que sabe realizar, organiza su propio horario y tiene su agenda personal | C9: 2 | D9: Ir al muestreo | E9: Ir a la caracterización
A10: Cliente | B10: Representa a la persona que solicita citas en la barbería con un barbero. Guarda su historial de multas sin pagar para saber si está o no vetado | C10: 2 | D10: Ir al muestreo | E10: Ir a la caracterización
A11: HorarioBarberia | B11: Representa, día por día, a qué hora abre y cierra el negocio; es el límite dentro del cual debe caber el horario de cualquier barbero | C11: 2 | D11: Ir al muestreo | E11: Ir a la caracterización
A12: BarberoServicio | B12: Representa qué servicios sabe hacer cada barbero, cuánto se demora en realizarlos y cuánto tiempo extra usa de colchón, ya que no todos los barberos ofrecen los mismos servicios | C12: 3 | D12: Ir al muestreo | E12: Ir a la caracterización
A13: HorarioBarbero | B13: Representa el día de la semana en que trabaja un barbero, junto con la hora en la que empieza y termina su jornada | C13: 3 | D13: Ir al muestreo | E13: Ir a la caracterización
A14: Agenda | B14: Representa un día puntual del calendario en el que un barbero, según su horario de trabajo, va a recibir citas. Es donde se agrupan todas las citas de ese barbero para ese día | C14: 4 | D14: Ir al muestreo | E14: Ir a la caracterización
A15: Descanso | C15: 4 | D15: Ir al muestreo | E15: Ir a la caracterización
A16: Bloqueo | B16: Representa una parte de la agenda, en donde el barbero no puede trabajar en un momento dado, debido algún compromiso o inveniente que se le presento | C16: 5 | D16: Ir al muestreo | E16: Ir a la caracterización
A17: Cita | B17: Representa la reserva de un cliente con un barbero para un día y hora puntual, con los servicios pedidos, su estado, y lo que realmente ocurrió (llegada, atención, tardanzas) | C17: 5 | D17: Ir al muestreo | E17: Ir a la caracterización
A18: CitaServicio | B18: Representa cada servicio incluido dentro de una cita puntual, guardando el precio y la duración que tenía ese servicio para ese barbero en el momento exacto en que se agendó, para que cambios futuros en el catálogo no alteren citas ya registradas | C18: 6 | D18: Ir al muestreo | E18: Ir a la caracterización
A19: Multa | B19: Representa la sanción económica que se le impone a un cliente por incumplir una cita, ya sea por llegar tarde fuera de tolerancia o por no presentarse, calculada a partir de la cita específica que la originó | C19: 6 | D19: Ir al muestreo | E19: Ir a la caracterización

Sheet C-DiaSemana
A1: <<<< Ir al modulo de dominio | B1: <<<< Ir a objetos de dominio
A2: Nombre atributo | B2: Descripción atributo | C2: Identificador del objeto de dominio | D2: Tipo de dato | E2: Obligatorio | F2: Longitud mínima (si aplica) | G2: Longitud máxima (si aplica) | H2: Precisión (si aplica) | I2: Rendondeo (si aplica) | J2: Rango inicial (si aplica) | K2: Rango final (si aplica) | L2: Formato (si aplica) | M2: Reglas especiales (si aplica) | N2: Dato calculado | O2: Aplica ajuste del dato (si aplica) | P2: Carácter de ajuste (si aplica) | Q2: Quitar espacios en blanco al inicio (si aplica) | R2: Quitar espacios en blanco al fin (si aplica) | S2: Dato sensible (si aplica) | T2: Valor por defecto (si aplica) | U2: Auto generado
A3: ='M-DiaSemana'!A3 -> id | B3: ='M-DiaSemana'!A2 -> Representa un identificador que hará unico cada objeto de dominio de este tipo, no se puede repetir | C3: Si | D3: Identificador único universal | E3: Si | F3: No aplica | G3: No aplica | H3: No aplica | I3: No aplica | J3: No aplica | K3: No aplica | L3: No aplica | M3: No aplica | N3: No | O3: No aplica | P3: No aplica | Q3: No aplica | R3: No aplica | S3: No | T3: UUID vacio | U3: Si
A4: ='M-DiaSemana'!B3 -> nombre | B4: ='M-DiaSemana'!B2 -> Representa como se llama el dia de la semana, para los horarios | C4: No | D4: Alfanumérico | E4: Si | F4: 5 | G4: 9 | H4: No aplica | I4: No aplica | J4: No aplica | K4: No aplica | L4: No aplica | M4: Solo pueden ser los dias de la semana como Lunes, Martes, Miércoles, Jueves, Viernes, Sábado, Domingo y Festivo | N4: No | O4: No aplica | P4: No aplica | Q4: Si | R4: Si | S4: No | T4: Vacio | U4: No
A6: Nombre combinación única | B6: Descripción | C6: Atributos involucrados
A7: ='M-DiaSemana'!C3 -> Combinación única | B7: ='M-DiaSemana'!C2 -> Combinacion única que indica que no puede existir más un dia de la semana con el mismo nombre | C7: nombre

Sheet M-DiaSemana
A1: <<<< Ir al modulo de dominio | B1: <<<< Ir a objetos de dominio
A2: Representa un identificador que hará unico cada objeto de dominio de este tipo, no se puede repetir | B2: Representa como se llama el dia de la semana, para los horarios | C2: Combinacion única que indica que no puede existir más un dia de la semana con el mismo nombre
A3: id | B3: nombre | C3: Combinación única
A4: 1 | B4: Lunes | C4: =B4 -> Lunes
A5: 2 | B5: Martes | C5: =B5 -> Martes
A6: 3 | B6: Miércoles | C6: =B6 -> Miércoles
A7: 4 | B7: Jueves | C7: =B7 -> Jueves
A8: 5 | B8: Viernes | C8: =B8 -> Viernes
A9: 6 | B9: Sábado | C9: =B9 -> Sábado
A10: 7 | B10: Domingo | C10: =B10 -> Domingo
A11: 8 | B11: Festivo | C11: =B11 -> Festivo
B17: Corresponde a la descripcion de los atributos
B18: Corresponde al identificador unico del objeto de dominio
B19: Corresponde a los datos de tipo alfanumerico
B20: Corresponde a la combinacion única

Sheet C-Estado
A1: <<<< Ir al modulo de dominio | B1: <<<< Ir a objetos de dominio
A2: Nombre atributo | B2: Descripción atributo | C2: Identificador del objeto de dominio | D2: Tipo de dato | E2: Obligatorio | F2: Longitud mínima (si aplica) | G2: Longitud máxima (si aplica) | H2: Precisión (si aplica) | I2: Rendondeo (si aplica) | J2: Rango inicial (si aplica) | K2: Rango final (si aplica) | L2: Formato (si aplica) | M2: Reglas especiales (si aplica) | N2: Dato calculado | O2: Aplica ajuste del dato (si aplica) | P2: Carácter de ajuste (si aplica) | Q2: Quitar espacios en blanco al inicio (si aplica) | R2: Quitar espacios en blanco al fin (si aplica) | S2: Dato sensible (si aplica) | T2: Valor por defecto (si aplica) | U2: Auto generado
A3: ='M-Estado'!A3 -> id | B3: ='M-Estado'!A2 -> Representa un identificador que hará unico cada objeto de dominio de este tipo, no se puede repetir | C3: Si | D3: Identificador único universal | E3: Si | F3: No aplica | G3: No aplica | H3: No aplica | I3: No aplica | J3: No aplica | K3: No aplica | L3: No aplica | M3: No aplica | N3: No | O3: No aplica | P3: No aplica | Q3: No aplica | R3: No aplica | S3: No aplica | T3: UUID vacio | U3: Si
A4: ='M-Estado'!B3 -> nombre | B4: ='M-Estado'!B2 -> Representa como se llama el estado en el que se encuentra una cita puntual | C4: No | D4: Alfanumérico | E4: Si | F4: 4 | G4: 50 | H4: No aplica | I4: No aplica | J4: No aplica | K4: No aplica | L4: No aplica | M4: Solo se aceptan caracteres de letras de la 'a' a la 'z' y caracteres con tilde | N4: No | O4: No aplica | P4: No aplica | Q4: Si | R4: Si | S4: No | T4: Vacio | U4: No
A5: ='M-Estado'!C3 -> descripcion | B5: ='M-Estado'!C2 -> Representa el significado de que representa cada estado para la cita | C5: No | D5: Alfanumérico | E5: Si | F5: 10 | G5: 300 | H5: No aplica | I5: No aplica | J5: No aplica | K5: No aplica | L5: No aplica | M5: Solo se aceptan caracteres de letras de la 'a' a la 'z', caracteres con tilde y espacios en blanco | N5: No | O5: No aplica | P5: No aplica | Q5: Si | R5: Si | S5: No | T5: Vacio | U5: No
A7: Nombre combinación única | B7: Descripción | C7: Atributos involucrados
A8: ='M-Estado'!D3 -> Combinación única | B8: ='M-Estado'!D2 -> Combinacion única que indica que no puede existir más un dia de la semana con el mismo nombre | C8: nombre

Sheet M-Estado
A1: <<<< Ir al modulo de dominio | B1: <<<< Ir a objetos de dominio
A2: Representa un identificador que hará unico cada objeto de dominio de este tipo, no se puede repetir | B2: Representa como se llama el estado en el que se encuentra una cita puntual | C2: Representa el significado de que representa cada estado para la cita | D2: Combinacion única que indica que no puede existir más un dia de la semana con el mismo nombre
A3: id | B3: nombre | C3: descripcion | D3: Combinación única
A4: 1 | B4: Agendada | C4: La cita quedó registrada en la agenda del barbero y está a la espera de la fecha y hora acordadas. | D4: =B4 -> Agendada
A5: 2 | B5: Finalizada | C5: El barbero atendió al cliente y el servicio contratado se prestó por completo. | D5: =B5 -> Finalizada
A6: 3 | B6: Cancelada por el cliente | C6: El cliente decidió no asistir y anuló la cita antes de la fecha y hora programada. | D6: =B6 -> Cancelada por el cliente
A7: 4 | B7: Cancelada por el barbero | C7: El barbero anuló la cita antes de la fecha y hora programada, por ejemplo por una eventualidad. | D7: =B7 -> Cancelada por el barbero
A8: 5 | B8: El cliente se demoro | C8: El cliente llegó después de la hora acordada superando la toleranciaTardanzaCliente definida en Regla, lo que genera una multa. | D8: =B8 -> El cliente se demoro
A9: 6 | B9: El barbero se demoro | C9: El barbero se demoró más de lo previsto en una cita anterior y no pudo atender al cliente a la hora acordada, dándole un descuento en compensación según Regla. | D9: =B9 -> El barbero se demoro
A10: 7 | B10: Inasistencia del cliente | C10: El cliente nunca llegó a la cita: se alcanzó la hora estimada de finalización sin registrar su llegada, lo que genera una multa por el valor total de los servicios pedidos. | D10: =B10 -> Inasistencia del cliente
A11: 8 | B11: Inasistencia del barbero | C11: El barbero nunca inició la atención de la cita: se alcanzó la hora estimada de finalización sin que el barbero hubiera atendido al cliente, lo que da lugar a un descuento en la próxima cita del cliente como compensación. | D11: =B11 -> Inasistencia del barbero
B17: Corresponde a la descripcion de los atributos
B18: Corresponde al identificador unico del objeto de dominio
B19: Corresponde a los datos de tipo alfanumerico
B20: Corresponde a la combinacion única

Sheet C-Servicio
A1: <<<< Ir al modulo de dominio | B1: <<<< Ir a objetos de dominio
A2: Nombre atributo | B2: Descripción atributo | C2: Identificador del objeto de dominio | D2: Tipo de dato | E2: Obligatorio | F2: Longitud mínima (si aplica) | G2: Longitud máxima (si aplica) | H2: Precisión (si aplica) | I2: Rendondeo (si aplica) | J2: Rango inicial (si aplica) | K2: Rango final (si aplica) | L2: Formato (si aplica) | M2: Reglas especiales (si aplica) | N2: Dato calculado | O2: Aplica ajuste del dato (si aplica) | P2: Carácter de ajuste (si aplica) | Q2: Quitar espacios en blanco al inicio (si aplica) | R2: Quitar espacios en blanco al fin (si aplica) | S2: Dato sensible (si aplica) | T2: Valor por defecto (si aplica) | U2: Auto generado
A3: ='M-Servicio'!A3 -> id | B3: ='M-Servicio'!A2 -> Representa un identificador que hará unico cada objeto de dominio de este tipo, no se puede repetir | C3: Si | D3: Identificador único universal | E3: Si | F3: No aplica | G3: No aplica | H3: No aplica | I3: No aplica | J3: No aplica | K3: No aplica | L3: No aplica | M3: No aplica | N3: No | O3: No aplica | P3: No aplica | Q3: No aplica | R3: No aplica | S3: No | T3: UUID vacio | U3: Si
A4: ='M-Servicio'!B3 -> nombre | B4: ='M-Servicio'!B2 -> Representa el nombre del servicio que va estar en la barberia, para que el barbero elija los servicios que el sabe hacer | C4: No | D4: Alfanumérico | E4: Si | F4: 3 | G4: 50 | H4: No aplica | I4: No aplica | J4: No aplica | K4: No aplica | L4: No aplica | M4: Solo se aceptan caracteres de letras de la 'a' a la 'z' y caracteres con tilde | N4: No | O4: No aplica | P4: No aplica | Q4: Si | R4: Si | S4: No | T4: Vacio | U4: No
A5: ='M-Servicio'!C3 -> descripcion | B5: ='M-Servicio'!C2 -> Representa una descripcion de que va a hacer cada servicio en la barberia, para que el barbero sepa que hace el servicio | C5: No | D5: Alfanumérico | E5: Si | F5: 10 | G5: 200 | H5: No aplica | I5: No aplica | J5: No aplica | K5: No aplica | L5: No aplica | M5: Solo se aceptan caracteres de letras de la 'a' a la 'z', caracteres con tilde y espacios en blanco | N5: No | O5: No aplica | P5: No aplica | Q5: Si | R5: Si | S5: No | T5: Vacio | U5: No
A6: ='M-Servicio'!D3 -> precio | B6: ='M-Servicio'!D2 -> Representa cuanto va a valer el servicio en pesos colombianos | C6: No | D6: Entero | E6: Si | F6: No aplica | G6: No aplica | H6: No aplica | I6: No aplica | J6: 0 | K6: 2000000 | L6: No aplica | M6: No aplica | N6: No | O6: No aplica | P6: No aplica | Q6: No aplica | R6: No aplica | S6: No | T6: 0 | U6: No
A7: ='M-Servicio'!E3 -> disponible | B7: ='M-Servicio'!E2 -> Representa si el servicio sigue o no disponible en la barberia | C7: No | D7: Lógico | E7: No | F7: No aplica | G7: No aplica | H7: No aplica | I7: No aplica | J7: No aplica | K7: No aplica | L7: No aplica | M7: No aplica | N7: No | O7: No aplica | P7: No aplica | Q7: No aplica | R7: No aplica | S7: No | T7: Si | U7: No
A9: Nombre combinación única | B9: Descripción | C9: Atributos involucrados
A10: ='M-Servicio'!F3 -> Combinacion única | B10: ='M-Servicio'!F2 -> Combinacion única que indica que no puede existir más de un servicio con el mismo nombre | C10: =A4 -> nombre

Sheet M-Servicio
A1: <<<< Ir al modulo de dominio | B1: <<<< Ir a objetos de dominio
A2: Representa un identificador que hará unico cada objeto de dominio de este tipo, no se puede repetir | B2: Representa el nombre del servicio que va estar en la barberia, para que el barbero elija los servicios que el sabe hacer | C2: Representa una descripcion de que va a hacer cada servicio en la barberia, para que el barbero sepa que hace el servicio | D2: Representa cuanto va a valer el servicio en pesos colombianos | E2: Representa si el servicio sigue o no disponible en la barberia | F2: Combinacion única que indica que no puede existir más de un servicio con el mismo nombre
A3: id | B3: nombre | C3: descripcion | D3: precio | E3: disponible | F3: Combinacion única
A4: 1 | B4: Motilada | C4: Corte de cabello completo con máquina y tijera, incluye lavado y secado | D4: 22000 | E4: si | F4: =B4 -> Motilada
A5: 2 | B5: Corte de barba | C5: Recorte de la barba con máquina para dejarla pareja y a la medida que pide el cliente | D5: 12000 | E5: si | F5: =B5 -> Corte de barba
A6: 3 | B6: Perfilada de barba | C6: Delineado de los bordes de la barba y el bigote con navaja, sin recortar el largo | D6: 15000 | E6: si | F6: =B6 -> Perfilada de barba
A7: 4 | B7: Arreglo completo de barba con toalla caliente | C7: Recorte, perfilado con navaja, toalla caliente, exfoliación y aceite para la barba | D7: 35000 | E7: si | F7: =B7 -> Arreglo completo de barba con toalla caliente
B13: Corresponde a la descripcion de los atributos
B14: Corresponde al identificador unico del objeto de dominio
B15: Corresponde a los datos de referencia de otros objetos de dominio
B16: Corresponde a los datos de tipo alfanumerico
B17: Corresponde a los datos de tipo entero
B18: Corresponde a los datos de tipo logico
B19: Corresponde a la combinacion única

Sheet C-Regla
A1: <<<< Ir al modulo de dominio | B1: <<<< Ir a objetos de dominio
A2: Nombre atributo | B2: Descripción atributo | C2: Identificador del objeto de dominio | D2: Tipo de dato | E2: Obligatorio | F2: Longitud mínima (si aplica) | G2: Longitud máxima (si aplica) | H2: Precisión (si aplica) | I2: Rendondeo (si aplica) | J2: Rango inicial (si aplica) | K2: Rango final (si aplica) | L2: Formato (si aplica) | M2: Reglas especiales (si aplica) | N2: Dato calculado | O2: Aplica ajuste del dato (si aplica) | P2: Carácter de ajuste (si aplica) | Q2: Quitar espacios en blanco al inicio (si aplica) | R2: Quitar espacios en blanco al fin (si aplica) | S2: Dato sensible (si aplica) | T2: Valor por defecto (si aplica) | U2: Auto generado
A3: ='M-Regla'!A3 -> id | B3: ='M-Regla'!A2 -> Representa un identificador que hará unico cada objeto de dominio de este tipo, no se puede repetir | C3: Si | D3: Identificador único universal | E3: Si | F3: No aplica | G3: No aplica | H3: No aplica | I3: No aplica | J3: No aplica | K3: No aplica | L3: No aplica | M3: No aplica | N3: No | O3: No aplica | P3: No aplica | Q3: No | R3: No | S3: No | T3: UUID vacio | U3: Si
A4: ='M-Regla'!B3 -> toleranciaTardanzaCliente | B4: ='M-Regla'!B2 -> Representa la cantidad de minutos maxima que un cliente puede llegar tarde | C4: No | D4: Entero | E4: No | F4: No aplica | G4: No aplica | H4: No aplica | I4: No aplica | J4: 0 | K4: 59 | L4: No aplica | M4: No aplica | N4: No | O4: No aplica | P4: No aplica | Q4: No aplica | R4: No aplica | S4: No | T4: 0 | U4: No
A5: ='M-Regla'!C3 -> montoMultaTardanzaCliente | B5: ='M-Regla'!C2 -> Representa la cantidad de dinero que el cliente debe de pagar en pesos colombianos, por superar la toleranciaTardanza | C5: No | D5: Entero | E5: No | F5: No aplica | G5: No aplica | H5: No aplica | I5: No aplica | J5: 0 | K5: 1000000 | L5: No aplica | M5: No aplica | N5: No | O5: No aplica | P5: No aplica | Q5: No aplica | R5: No aplica | S5: No | T5: 0 | U5: No
A6: ='M-Regla'!D3 -> numeroMultasMaxima | B6: ='M-Regla'!D2 -> Representa la maxima de multas que pueda tener un cliente sin pagar, a partir de esta cantidad se le hace un veto al cliente | C6: No | D6: Entero | E6: No | F6: No aplica | G6: No aplica | H6: No aplica | I6: No aplica | J6: 0 | K6: 100 | L6: No aplica | M6: No aplica | N6: No | O6: No aplica | P6: No aplica | Q6: No aplica | R6: No aplica | S6: No | T6: 0 | U6: No
A7: ='M-Regla'!E3 -> toleranciaTardanzaBarbero | B7: ='M-Regla'!E2 -> Representa la cantidad de minutos que un barbero puede demorarse en atender a un cliente, en caso de que el barbero se demore mas de lo previsto en su cita anterior | C7: No | D7: Entero | E7: No | F7: No aplica | G7: No aplica | H7: No aplica | I7: No aplica | J7: 0 | K7: 59 | L7: No aplica | M7: No aplica | N7: No | O7: No aplica | P7: No aplica | Q7: No aplica | R7: No aplica | S7: No | T7: 0 | U7: No
A8: ='M-Regla'!F3 -> porcentajeDescuentoCita | B8: ='M-Regla'!F2 -> Representa la cantidad cuanto descuento va a tener un cliente en la cita con el barbero, como recompesa por esperar al barbero mas de la tolerancia permitida | C8: No | D8: Entero | E8: No | F8: No aplica | G8: No aplica | H8: No aplica | I8: No aplica | J8: 0 | K8: 100 | L8: No aplica | M8: No aplica | N8: No | O8: No aplica | P8: No aplica | Q8: No aplica | R8: No aplica | S8: No | T8: 0 | U8: No
A9: ='M-Regla'!G3 -> tiempoEnHorasAnticipacionDelBarberoParaCancelarUnaCita | B9: ='M-Regla'!G2 -> Representa la parte en horas del tiempo mínimo de anticipación con el que un barbero pueda cancelar una cita con el cliente. El barbero no podrá cancelar la cita cuando falte menos del tiempo indicado | C9: No | D9: Entero | E9: No | F9: No aplica | G9: No aplica | H9: No aplica | I9: No aplica | J9: 0 | K9: 720 | L9: No aplica | M9: No aplica | N9: No | O9: No aplica | P9: No aplica | Q9: No aplica | R9: No aplica | S9: No | T9: 0 | U9: No
A10: ='M-Regla'!H3 -> tiempoEnMinutosAnticipacionDelBarberoParaCancelarUnaCita | B10: ='M-Regla'!H2 -> Representa la parte en minutos del tiempo mínimo de anticipación con el que un barbero puede cancelar una cita con el cliente. El barbero no podrá cancelar la cita cuando falte menos del tiempo indicado | C10: No | D10: Entero | E10: No | F10: No aplica | G10: No aplica | H10: No aplica | I10: No aplica | J10: 0 | K10: 59 | L10: No aplica | M10: No aplica | N10: No | O10: No aplica | P10: No aplica | Q10: No aplica | R10: No aplica | S10: No | T10: 0 | U10: No
A11: ='M-Regla'!I3 -> tiempoEnHorasAnticipacionDelClienteParaCancelarUnaCita | B11: ='M-Regla'!I2 -> Representa la parte en horas del tiempo mínimo de anticipación con el que un cliente puede cancelar una cita con el barbero. El cliente no podrá cancelar la cita cuando falte menos del tiempo indicado | C11: No | D11: Entero | E11: No | F11: No aplica | G11: No aplica | H11: No aplica | I11: No aplica | J11: 0 | K11: 720 | L11: No aplica | M11: No aplica | N11: No | O11: No aplica | P11: No aplica | Q11: No aplica | R11: No aplica | S11: No | T11: 0 | U11: No
A12: ='M-Regla'!J3 -> tiempoEnMinutosAnticipacionDelClienteParaCancelarUnaCita | B12: ='M-Regla'!J2 -> Representa la parte en minutos del tiempo mínimo de anticipación con el que un cliente puede cancelar una cita con el barbero. El cliente no podrá cancelar la cita cuando falte menos del tiempo indicado | C12: No | D12: Entero | E12: No | F12: No aplica | G12: No aplica | H12: No aplica | I12: No aplica | J12: 0 | K12: 59 | L12: No aplica | M12: No aplica | N12: No | O12: No aplica | P12: No aplica | Q12: No aplica | R12: No aplica | S12: No | T12: 0 | U12: No

Sheet M-Regla
A1: <<<< Ir al modulo de dominio | B1: <<<< Ir a objetos de dominio
A2: Representa un identificador que hará unico cada objeto de dominio de este tipo, no se puede repetir | B2: Representa la cantidad de minutos maxima que un cliente puede llegar tarde | C2: Representa la cantidad de dinero que el cliente debe de pagar en pesos colombianos, por superar la toleranciaTardanza | D2: Representa la maxima de multas que pueda tener un cliente sin pagar, a partir de esta cantidad se le hace un veto al cliente | E2: Representa la cantidad de minutos que un barbero puede demorarse en atender a un cliente, en caso de que el barbero se demore mas de lo previsto en su cita anterior | F2: Representa la cantidad cuanto descuento va a tener un cliente en la cita con el barbero, como recompesa por esperar al barbero mas de la tolerancia permitida | G2: Representa la parte en horas del tiempo mínimo de anticipación con el que un barbero pueda cancelar una cita con el cliente. El barbero no podrá cancelar la cita cuando falte menos del tiempo indicado | H2: Representa la parte en minutos del tiempo mínimo de anticipación con el que un barbero puede cancelar una cita con el cliente. El barbero no podrá cancelar la cita cuando falte menos del tiempo indicado | I2: Representa la parte en horas del tiempo mínimo de anticipación con el que un cliente puede cancelar una cita con el barbero. El cliente no podrá cancelar la cita cuando falte menos del tiempo indicado | J2: Representa la parte en minutos del tiempo mínimo de anticipación con el que un cliente puede cancelar una cita con el barbero. El cliente no podrá cancelar la cita cuando falte menos del tiempo indicado
A3: id | B3: toleranciaTardanzaCliente | C3: montoMultaTardanzaCliente | D3: numeroMultasMaxima | E3: toleranciaTardanzaBarbero | F3: porcentajeDescuentoCita | G3: tiempoEnHorasAnticipacionDelBarberoParaCancelarUnaCita | H3: tiempoEnMinutosAnticipacionDelBarberoParaCancelarUnaCita | I3: tiempoEnHorasAnticipacionDelClienteParaCancelarUnaCita | J3: tiempoEnMinutosAnticipacionDelClienteParaCancelarUnaCita
A4: 1 | B4: 10 | C4: 10000 | D4: 3 | E4: 15 | F4: 10 | G4: 1 | H4: 0 | I4: 1 | J4: 0
B10: Corresponde a la descripcion de los atributos
B11: Corresponde al identificador unico del objeto de dominio
B12: Corresponde a los datos de tipo entero

Sheet C-PrefijoCelular
A1: <<<< Ir al modulo de dominio | B1: <<<< Ir a objetos de dominio
A2: Nombre atributo | B2: Descripción atributo | C2: Identificador del objeto de dominio | D2: Tipo de dato | E2: Obligatorio | F2: Longitud mínima (si aplica) | G2: Longitud máxima (si aplica) | H2: Precisión (si aplica) | I2: Rendondeo (si aplica) | J2: Rango inicial (si aplica) | K2: Rango final (si aplica) | L2: Formato (si aplica) | M2: Reglas especiales (si aplica) | N2: Dato calculado | O2: Aplica ajuste del dato (si aplica) | P2: Carácter de ajuste (si aplica) | Q2: Quitar espacios en blanco al inicio (si aplica) | R2: Quitar espacios en blanco al fin (si aplica) | S2: Dato sensible (si aplica) | T2: Valor por defecto (si aplica) | U2: Auto generado
A3: ='M-PrefijoCelular'!A3 -> id | B3: ='M-PrefijoCelular'!A2 -> Representa un identificador que hará unico cada objeto de dominio de este tipo, no se puede repetir | C3: Si | D3: Identificador único universal | E3: Si | F3: No aplica | G3: No aplica | H3: No aplica | I3: No aplica | J3: No aplica | K3: No aplica | L3: No aplica | M3: No aplica | N3: No | O3: No | P3: No aplica | Q3: No | R3: No | S3: No | T3: No aplica | U3: Si
A4: ='M-PrefijoCelular'!B3 -> prefijo | B4: ='M-PrefijoCelular'!B2 -> Representa el primer nombre del barbero que trabaja en barbería | C4: No | D4: Alfanumérico | E4: Si | F4: 2 | G4: 6 | H4: No aplica | I4: No aplica | J4: No aplica | K4: No aplica | L4: Simbolo + seguido de un número. Por ejemplo +57. Tambien el anterior puede ser seguido de un - y un numero. Por ejemplo +1-809 | M4: Solo se aceptan caracteres numericos del 0 al 9 y el carácter '+' y '-' | N4: No | O4: No | P4: No aplica | Q4: Si | R4: Si | S4: No | T4: +0 | U4: No
A6: Nombre combinación única | B6: Descripción | C6: Atributos involucrados
A7: ='M-PrefijoCelular'!C3 -> Combinación única | B7: ='M-PrefijoCelular'!C2 -> Combinacion única que indica que no puede existir más un mismo prefijo | C7: prefijo

Sheet M-PrefijoCelular
A1: <<<< Ir al modulo de dominio | B1: <<<< Ir a objetos de dominio
A2: Representa un identificador que hará unico cada objeto de dominio de este tipo, no se puede repetir | B2: Representa el primer nombre del barbero que trabaja en barbería | C2: Combinacion única que indica que no puede existir más un mismo prefijo
A3: id | B3: prefijo | C3: Combinación única
A4: 1 | B4: +57 | C4: =B4 -> +57
A5: 2 | B5: +91 | C5: =B5 -> +91
A6: 3 | B6: +593 | C6: =B6 -> +593
A7: 4 | B7: +58 | C7: =B7 -> +58
B13: Corresponde a la descripcion de los atributos
B14: Corresponde al identificador unico del objeto de dominio
B15: Corresponde a los datos de tipo alfanumerico
B16: Corresponde a la combinacion única

Sheet C-TipoMulta
A1: <<<< Ir al modulo de dominio | B1: <<<< Ir a objetos de dominio
A2: Nombre atributo | B2: Descripción atributo | C2: Identificador del objeto de dominio | D2: Tipo de dato | E2: Obligatorio | F2: Longitud mínima (si aplica) | G2: Longitud máxima (si aplica) | H2: Precisión (si aplica) | I2: Rendondeo (si aplica) | J2: Rango inicial (si aplica) | K2: Rango final (si aplica) | L2: Formato (si aplica) | M2: Reglas especiales (si aplica) | N2: Dato calculado | O2: Aplica ajuste del dato (si aplica) | P2: Carácter de ajuste (si aplica) | Q2: Quitar espacios en blanco al inicio (si aplica) | R2: Quitar espacios en blanco al fin (si aplica) | S2: Dato sensible (si aplica) | T2: Valor por defecto (si aplica) | U2: Auto generado
A3: ='M-TipoMulta'!A3 -> id | B3: ='M-TipoMulta'!A2 -> Representa un identificador que hará unico cada objeto de dominio de este tipo, no se puede repetir | C3: Si | D3: Identificador único universal | E3: Si | F3: No aplica | G3: No aplica | H3: No aplica | I3: No aplica | J3: No aplica | K3: No aplica | L3: No aplica | M3: No aplica | N3: No | O3: No | P3: No aplica | Q3: No | R3: No | S3: No | T3: UUID vacio | U3: Si
A4: ='M-TipoMulta'!B3 -> nombre | B4: ='M-TipoMulta'!B2 -> Representa el nombre del tipo de multa | C4: No | D4: Alfanumérico | E4: Si | F4: 4 | G4: 50 | H4: No aplica | I4: No aplica | J4: No aplica | K4: No aplica | L4: No aplica | M4: No aplica | N4: No | O4: No | P4: No aplica | Q4: Si | R4: Si | S4: No | T4: Vacio | U4: No
A5: ='M-TipoMulta'!C3 -> descripcion | B5: ='M-TipoMulta'!C2 -> Representa que hace cada tipo de multa | C5: No | D5: Alfanumérico | E5: Si | F5: 10 | G5: 300 | H5: No aplica | I5: No aplica | J5: No aplica | K5: No aplica | L5: No aplica | M5: No aplica | N5: No | O5: No | P5: No aplica | Q5: Si | R5: Si | S5: No | T5: Vacio | U5: No
A7: Nombre combinación única | B7: Descripción | C7: Atributos involucrados
A8: ='M-TipoMulta'!D3 -> Combinación única | B8: ='M-TipoMulta'!D2 -> Combinación única indica que no puede existir más de un tipo de multa con el mismo nombre | C8: nombre

Sheet M-TipoMulta
A1: <<<< Ir al modulo de dominio | B1: <<<< Ir a objetos de dominio
A2: Representa un identificador que hará unico cada objeto de dominio de este tipo, no se puede repetir | B2: Representa el nombre del tipo de multa | C2: Representa que hace cada tipo de multa | D2: Combinación única indica que no puede existir más de un tipo de multa con el mismo nombre
A3: id | B3: nombre | C3: descripcion | D3: Combinación única
A4: 1 | B4: Tardanza | C4: El cliente llegó a la cita después de la hora acordada, superando los minutos de toleranciaTardanzaCliente definidos en Regla. | D4: =B4 -> Tardanza
A5: 2 | B5: Inasistencia | C5: El cliente no se presentó a la cita agendada: se llegó a la hora estimada de finalización sin que hubiera registrado su llegada. | D5: =B5 -> Inasistencia
B11: Corresponde a la descripcion de los atributos
B12: Corresponde al identificador unico del objeto de dominio
B13: Corresponde a los datos de tipo texto
B14: Corresponde a los datos de tipo alfanumerico
B15: Corresponde a la combinacion única

Sheet C-Barbero
A1: <<<< Ir al modulo de dominio | B1: <<<< Ir a objetos de dominio
A2: Nombre atributo | B2: Descripción atributo | C2: Identificador del objeto de dominio | D2: Tipo de dato | E2: Obligatorio | F2: Longitud mínima (si aplica) | G2: Longitud máxima (si aplica) | H2: Precisión (si aplica) | I2: Rendondeo (si aplica) | J2: Rango inicial (si aplica) | K2: Rango final (si aplica) | L2: Formato (si aplica) | M2: Reglas especiales (si aplica) | N2: Dato calculado | O2: Aplica ajuste del dato (si aplica) | P2: Carácter de ajuste (si aplica) | Q2: Quitar espacios en blanco al inicio (si aplica) | R2: Quitar espacios en blanco al fin (si aplica) | S2: Dato sensible (si aplica) | T2: Valor por defecto (si aplica) | U2: Auto generado
A3: ='M-Barbero'!A3 -> id | B3: ='M-Barbero'!A2 -> Representa un identificador que hará unico cada objeto de dominio de este tipo, no se puede repetir | C3: Si | D3: Identificador único universal | E3: Si | F3: No aplica | G3: No aplica | H3: No aplica | I3: No aplica | J3: No aplica | K3: No aplica | L3: No aplica | M3: No aplica | N3: No | O3: No aplica | P3: No aplica | Q3: No | R3: No | S3: No | T3: UUID vacio | U3: Si
A4: ='M-Barbero'!B3 -> primerNombre | B4: ='M-Barbero'!B2 -> Representa el primer nombre del barbero que trabaja en barbería | C4: No | D4: Alfanumérico | E4: Si | F4: 3 | G4: 100 | H4: No aplica | I4: No aplica | J4: No aplica | K4: No aplica | L4: No aplica | M4: Solo se aceptan caracteres de letras de la 'a' a la 'z', caracteres con tilde y numeros del 0 al 9 | N4: No | O4: No | P4: No | Q4: Si | R4: Si | S4: No | T4: vacío | U4: No
A5: ='M-Barbero'!C3 -> segundoNombre | B5: ='M-Barbero'!C2 -> Representa el segundo nombre del barbero que trabaja en barbería | C5: No | D5: Alfanumérico | E5: No | F5: 3 | G5: 100 | H5: No aplica | I5: No aplica | J5: No aplica | K5: No aplica | L5: No aplica | M5: Solo se aceptan caracteres de letras de la 'a' a la 'z', caracteres con tilde y numeros del 0 al 9 | N5: No | O5: No | P5: No | Q5: Si | R5: Si | S5: No | T5: vacío | U5: No
A6: ='M-Barbero'!D3 -> primerApellido | B6: ='M-Barbero'!D2 -> Representa el primer apellido del barbero que trabaja en la barbería | C6: No | D6: Alfanumérico | E6: Si | F6: 3 | G6: 100 | H6: No aplica | I6: No aplica | J6: No aplica | K6: No aplica | L6: No aplica | M6: Solo se aceptan caracteres de letras de la 'a' a la 'z', caracteres con tilde y numeros del 0 al 9 | N6: No | O6: No | P6: No | Q6: Si | R6: Si | S6: No | T6: vacío | U6: No
A7: ='M-Barbero'!E3 -> segundoApellido | B7: ='M-Barbero'!E2 -> Representa el segundo apellido del barbero que trabaja en la barbería | C7: No | D7: Alfanumérico | E7: No | F7: 3 | G7: 100 | H7: No aplica | I7: No aplica | J7: No aplica | K7: No aplica | L7: No aplica | M7: Solo se aceptan caracteres de letras de la 'a' a la 'z', caracteres con tilde y numeros del 0 al 9 | N7: No | O7: No | P7: No | Q7: Si | R7: Si | S7: No | T7: vacío | U7: No
A8: ='M-Barbero'!F3 -> prefijo | B8: ='M-Barbero'!F2 -> Representa cual es el prefijo del numero de celular del barbero | C8: No | D8: PrefijoCelular | E8: Si | F8: No aplica | G8: No aplica | H8: No aplica | I8: No aplica | J8: No aplica | K8: No aplica | L8: No aplica | M8: No aplica | N8: No | O8: No aplica | P8: No aplica | Q8: No aplica | R8: No aplica | S8: No | T8: UUID vacio | U8: No
A9: ='M-Barbero'!G3 -> celular | B9: ='M-Barbero'!G2 -> Representa el número de celular del barbero, es el dato que el cliente necesita en caso de que tenga que contactarse con el | C9: No | D9: Entero | E9: Si | F9: No aplica | G9: No aplica | H9: No aplica | I9: No aplica | J9: 1000000 | K9: 9999999999 | L9: Número telefónico, sin el prefijo de país | M9: No aplica | N9: No | O9: No aplica | P9: No aplica | Q9: No aplica | R9: No aplica | S9: Si | T9: 0 | U9: No
A10: ='M-Barbero'!H3 -> vigente | B10: ='M-Barbero'!H2 -> Representa si el barbero sigue o no trabajando en la barberia | C10: No | D10: Lógico | E10: No | F10: No aplica | G10: No aplica | H10: No aplica | I10: No aplica | J10: No aplica | K10: No aplica | L10: No aplica | M10: No aplica | N10: Si | O10: No aplica | P10: No aplica | Q10: No aplica | R10: No aplica | S10: No | T10: Si | U10: No
A11: ='M-Barbero'!I3 -> anticipacionEnHorasParaAgendarCita | B11: ='M-Barbero'!I2 -> Representa la parte en horas del tiempo mínimo de anticipación con el que un cliente debe pedirle una cita a este barbero. Junto con anticipacionEnMinutosParaAgendarCita forma el tiempo total de anticipación que exige el barbero | C11: No | D11: Entero | E11: No | F11: No aplica | G11: No aplica | H11: No aplica | I11: No aplica | J11: 0 | K11: 720 | L11: Horas | M11: No aplica | N11: No | O11: No aplica | P11: No aplica | Q11: No aplica | R11: No aplica | S11: No | T11: 0 | U11: No
A12: ='M-Barbero'!J3 -> anticipacionEnMinutosParaAgendarCita | B12: ='M-Barbero'!J2 -> Representa la parte en minutos del tiempo mínimo de anticipación con el que un cliente debe pedirle una cita a este barbero. Junto con anticipacionEnHorasParaAgendarCita forma el tiempo total de anticipación que exige el barbero | C12: No | D12: Entero | E12: No | F12: No aplica | G12: No aplica | H12: No aplica | I12: No aplica | J12: 0 | K12: 59 | L12: Minutos | M12: No aplica | N12: No | O12: No aplica | P12: No aplica | Q12: No aplica | R12: No aplica | S12: No | T12: 0 | U12: No
A14: Nombre combinación única | B14: Descripción | C14: Atributos involucrados
A15: ='M-Barbero'!K3 -> Combinación única 1 | B15: ='M-Barbero'!K2 -> Combinacion única que indica que no puede existir más de un barbero con el mismo prefijo de celular y número de celular | C15: =A8 -> prefijo
C16: =A9 -> celular

Sheet M-Barbero
A1: <<<< Ir al modulo de dominio | B1: <<<< Ir a objetos de dominio
A2: Representa un identificador que hará unico cada objeto de dominio de este tipo, no se puede repetir | B2: Representa el primer nombre del barbero que trabaja en barbería | C2: Representa el segundo nombre del barbero que trabaja en barbería | D2: Representa el primer apellido del barbero que trabaja en la barbería | E2: Representa el segundo apellido del barbero que trabaja en la barbería | F2: Representa cual es el prefijo del numero de celular del barbero | G2: Representa el número de celular del barbero, es el dato que el cliente necesita en caso de que tenga que contactarse con el | H2: Representa si el barbero sigue o no trabajando en la barberia | I2: Representa la parte en horas del tiempo mínimo de anticipación con el que un cliente debe pedirle una cita a este barbero. Junto con anticipacionEnMinutosParaAgendarCita forma el tiempo total de anticipación que exige el barbero | J2: Representa la parte en minutos del tiempo mínimo de anticipación con el que un cliente debe pedirle una cita a este barbero. Junto con anticipacionEnHorasParaAgendarCita forma el tiempo total de anticipación que exige el barbero | K2: Combinacion única que indica que no puede existir más de un barbero con el mismo prefijo de celular y número de celular
A3: id | B3: primerNombre | C3: segundoNombre | D3: primerApellido | E3: segundoApellido | F3: prefijo | G3: celular | H3: vigente | I3: anticipacionEnHorasParaAgendarCita | J3: anticipacionEnMinutosParaAgendarCita | K3: Combinación única 1
A4: 1 | B4: Juan | C4: Fernando | D4: García | E4: Lopez | F4: ='M-PrefijoCelular'!C4 -> +57 | G4: 3245627890 | H4: si | I4: 24 | J4: 0 | K4: =_xlfn.CONCAT(F4,"-",G4) -> +57-3245627890
A5: 2 | B5: Juan | C5: David | D5: Ortiz | E5: Sanchez | F5: ='M-PrefijoCelular'!C4 -> +57 | G5: 3124518923 | H5: si | I5: 0 | J5: 30 | K5: =_xlfn.CONCAT(F5,"-",G5) -> +57-3124518923
A6: 3 | B6: Carlos | D6: Arbeladez | F6: ='M-PrefijoCelular'!C4 -> +57 | G6: 3214533321 | H6: si | I6: 1 | J6: 0 | K6: =_xlfn.CONCAT(F6,"-",G6) -> +57-3214533321
A7: 4 | B7: Andres | D7: Ramirez | E7: Patiño | F7: ='M-PrefijoCelular'!C5 -> +91 | G7: 9876543210 | H7: no | I7: 0 | J7: 0 | K7: =_xlfn.CONCAT(F7,"-",G7) -> +91-9876543210
A8: 5 | B8: Juan | C8: Carlos | D8: Zambrano | E8: Perez | F8: ='M-PrefijoCelular'!C6 -> +593 | G8: 998765432 | H8: no | I8: 2 | J8: 0 | K8: =_xlfn.CONCAT(F8,"-",G8) -> +593-998765432
B14: Corresponde a la descripcion de los atributos
B15: Corresponde al identificador unico del objeto de dominio
B16: Corresponde a los datos de tipo alfanumerico
B17: Corresponde a referencias de objetos de dominio
B18: Corresponde a los datos de tipo entero
B19: Corresponde a los datos de tipo lógico
B20: Corresponde a la combinacion única 1

Sheet C-Cliente
A1: <<<< Ir al modulo de dominio | B1: <<<< Ir a objetos de dominio
A2: Nombre atributo | B2: Descripción atributo | C2: Identificador del objeto de dominio | D2: Tipo de dato | E2: Obligatorio | F2: Longitud mínima (si aplica) | G2: Longitud máxima (si aplica) | H2: Precisión (si aplica) | I2: Rendondeo (si aplica) | J2: Rango inicial (si aplica) | K2: Rango final (si aplica) | L2: Formato (si aplica) | M2: Reglas especiales (si aplica) | N2: Dato calculado | O2: Aplica ajuste del dato (si aplica) | P2: Carácter de ajuste (si aplica) | Q2: Quitar espacios en blanco al inicio (si aplica) | R2: Quitar espacios en blanco al fin (si aplica) | S2: Dato sensible (si aplica) | T2: Valor por defecto (si aplica) | U2: Auto generado
A3: ='M-Cliente'!A3 -> id | B3: ='M-Cliente'!A2 -> Representa un identificador que hará unico cada objeto de dominio de este tipo, no se puede repetir | C3: Si | D3: Identificador único universal | E3: Si | F3: No aplica | G3: No aplica | H3: No aplica | I3: No aplica | J3: No aplica | K3: No aplica | L3: No aplica | M3: No aplica | N3: Si | O3: No | P3: No aplica | Q3: No aplica | R3: No aplica | S3: No | T3: UUID vacio | U3: Si
A4: ='M-Cliente'!B3 -> primerNombre | B4: ='M-Cliente'!B2 -> Representa el primer nombre de la persona, que va a estar llendo a la barberia para las citas | C4: No | D4: Alfanumérico | E4: Si | F4: 2 | G4: 50 | H4: No aplica | I4: No aplica | J4: No aplica | K4: No aplica | L4: No aplica | M4: Solo se aceptan caracteres de letras de la 'a' a la 'z', caracteres con tilde y numeros del 0 al 9 | N4: No | O4: No | P4: No | Q4: Si | R4: Si | S4: No | T4: Vacio | U4: No
A5: ='M-Cliente'!C3 -> segundoNombre | B5: ='M-Cliente'!C2 -> Representa el segundo nombre de la persona, que va a estar llendo a la barberia para las citas | C5: No | D5: Alfanumérico | E5: No | F5: 2 | G5: 50 | H5: No aplica | I5: No aplica | J5: No aplica | K5: No aplica | L5: No aplica | M5: Solo se aceptan caracteres de letras de la 'a' a la 'z', caracteres con tilde y numeros del 0 al 9 | N5: No | O5: No | P5: No | Q5: Si | R5: Si | S5: No | T5: Vacio | U5: No
A6: ='M-Cliente'!D3 -> primerApellido | B6: ='M-Cliente'!D2 -> Representa el primer apellido de la persona, que va a estar llendo a la barberia para las citas | C6: No | D6: Alfanumérico | E6: Si | F6: 2 | G6: 50 | H6: No aplica | I6: No aplica | J6: No aplica | K6: No aplica | L6: No aplica | M6: Solo se aceptan caracteres de letras de la 'a' a la 'z', caracteres con tilde y numeros del 0 al 9 | N6: No | O6: No | P6: No | Q6: Si | R6: Si | S6: No | T6: Vacio | U6: No
A7: ='M-Cliente'!E3 -> segundoApellido | B7: ='M-Cliente'!E2 -> Representa el segundo apellido de la persona, que va a estar llendo a la barberia para las citas | C7: No | D7: Alfanumérico | E7: No | F7: 2 | G7: 50 | H7: No aplica | I7: No aplica | J7: No aplica | K7: No aplica | L7: No aplica | M7: Solo se aceptan caracteres de letras de la 'a' a la 'z', caracteres con tilde y numeros del 0 al 9 | N7: No | O7: No | P7: No | Q7: Si | R7: Si | S7: No | T7: Vacio | U7: No
A8: ='M-Cliente'!F3 -> prefijoCelular | B8: ='M-Cliente'!F2 -> Representa cual es el prefijo del numero de celular del cliente | C8: No | D8: PrefijoCelular | E8: Si | F8: 2 | G8: 4 | H8: No aplica | I8: No aplica | J8: No aplica | K8: No aplica | L8: El mismo formato del objeto referenciado | M8: Aplican las reglas del objeto referenciado | N8: No | O8: No | P8: No aplica | Q8: No | R8: No | S8: Si | T8: UUID vacio | U8: No
A9: ='M-Cliente'!G3 -> celular | B9: ='M-Cliente'!G2 -> Representa el numero de celular del cliente, es el dato que el barbero necesita en caso de que tenga que contactarse con el | C9: No | D9: Alfanumérico | E9: Si | F9: 4 | G9: 15 | H9: No aplica | I9: No aplica | J9: No aplica | K9: No aplica | L9: Deben de ser solo números que cumplan un número de teléfono válido | M9: No aplica | N9: No | O9: No | P9: No | Q9: Si | R9: Si | S9: Si | T9: 0 | U9: No
A10: ='M-Cliente'!I3 -> multasSinPagar | B10: ='M-Cliente'!I2 -> Representa la cantidad de multas que tiene sin pagar en las citas que ha tenido, ya sea multa por tardanza o por no llegar | C10: No | D10: Entero | E10: Si | F10: No aplica | G10: No aplica | H10: No aplica | I10: No aplica | J10: 0 | K10: 3 | L10: No aplica | M10: Se calcula contando las Multa del cliente donde pagada='no' | N10: Si | O10: No | P10: No aplica | Q10: No aplica | R10: No aplica | S10: No | T10: 0 | U10: No
A11: ='M-Cliente'!J3 -> estaVetado | B11: ='M-Cliente'!J2 -> Representa si el cliente esta en estado de veto o no, cuando el cliente esta vetado el sistema no va a permitir agendar citas con este cliente con ningun barbero | C11: No | D11: Lógico | E11: Si | F11: No aplica | G11: No aplica | H11: No aplica | I11: No aplica | J11: No aplica | K11: No aplica | L11: No aplica | M11: Se calcula comparando multasSinPagar contra Regla.numeroMultasMaxima; si multasSinPagar alcanza ese máximo, el cliente queda vetado | N11: Si | O11: No | P11: No aplica | Q11: No aplica | R11: No aplica | S11: No | T11: No | U11: No
A12: ='M-Cliente'!K3 -> cantidadDeDescuentoCitas | B12: ='M-Cliente'!K2 -> Representa la cantidad de citas que un cliente va a tener con descuento, cada inasistencia que un barbero le haga al cliente se le suma un descuento a la proxima cita | C12: No | D12: Entero | E12: Si | F12: No aplica | G12: No aplica | H12: No aplica | I12: No aplica | J12: 0 | K12: 1000 | L12: No aplica | M12: Se calcula contando cuántas citas con inasistencia del barbero ha tenido el cliente | N12: Si | O12: No | P12: No aplica | Q12: No aplica | R12: No aplica | S12: No | T12: 0 | U12: No
A14: Nombre combinación única | B14: Descripción | C14: Atributos involucrados
A15: ='M-Cliente'!L3 -> Combinación única 1 | B15: ='M-Cliente'!L2 -> Combinacion única que indica que no puede existir más de un cliente con el mismo prefijo de celular y número de celular | C15: =A8 -> prefijoCelular
C18: =A9 -> celular

Sheet M-Cliente
A1: <<<< Ir al modulo de dominio | B1: <<<< Ir a objetos de dominio
A2: Representa un identificador que hará unico cada objeto de dominio de este tipo, no se puede repetir | B2: Representa el primer nombre de la persona, que va a estar llendo a la barberia para las citas | C2: Representa el segundo nombre de la persona, que va a estar llendo a la barberia para las citas | D2: Representa el primer apellido de la persona, que va a estar llendo a la barberia para las citas | E2: Representa el segundo apellido de la persona, que va a estar llendo a la barberia para las citas | F2: Representa cual es el prefijo del numero de celular del cliente | G2: Representa el numero de celular del cliente, es el dato que el barbero necesita en caso de que tenga que contactarse con el | H2: Representa si el numero que ingreso el cliente es correcto o no | I2: Representa la cantidad de multas que tiene sin pagar en las citas que ha tenido, ya sea multa por tardanza o por no llegar | J2: Representa si el cliente esta en estado de veto o no, cuando el cliente esta vetado el sistema no va a permitir agendar citas con este cliente con ningun barbero | K2: Representa la cantidad de citas que un cliente va a tener con descuento, cada inasistencia que un barbero le haga al cliente se le suma un descuento a la proxima cita | L2: Combinacion única que indica que no puede existir más de un cliente con el mismo prefijo de celular y número de celular
A3: id | B3: primerNombre | C3: segundoNombre | D3: primerApellido | E3: segundoApellido | F3: prefijoCelular | G3: celular | H3: elNumeroCelularEsCorrecto | I3: multasSinPagar | J3: estaVetado | K3: cantidadDeDescuentoCitas | L3: Combinación única 1
A4: 1 | B4: Juan | D4: Gómez | F4: ='M-PrefijoCelular'!C4 -> +57 | G4: 3234528921 | H4: Si | I4: 0 | J4: no | K4: 0 | L4: =_xlfn.CONCAT(F4,"-",G4) -> +57-3234528921
A5: 2 | B5: Jose | C5: Miguel | D5: Ramirez | E5: Perez | F5: ='M-PrefijoCelular'!C4 -> +57 | G5: 3161657782 | H5: Si | I5: 0 | J5: no | K5: 0 | L5: =_xlfn.CONCAT(F5,"-",G5) -> +57-3161657782
A6: 3 | B6: Simon | D6: Ochoa | E6: Ramirez | F6: ='M-PrefijoCelular'!C4 -> +57 | G6: 3119884321 | H6: Si | I6: 0 | J6: no | K6: 0 | L6: =_xlfn.CONCAT(F6,"-",G6) -> +57-3119884321
A7: 4 | B7: Alexis | D7: Gallego | F7: ='M-PrefijoCelular'!C7 -> +58 | G7: 4127359182 | H7: Si | I7: 1 | J7: no | K7: 1 | L7: =_xlfn.CONCAT(F7,"-",G7) -> +58-4127359182
A8: 5 | B8: Kevin | C8: Andrés | D8: Muñoz | E8: Salazar | F8: ='M-PrefijoCelular'!C4 -> +57 | G8: 3005544332 | H8: Si | I8: 3 | J8: si | K8: 0 | L8: =_xlfn.CONCAT(F8,"-",G8) -> +57-3005544332
B14: Corresponde a la descripcion de los atributos
B15: Corresponde al identificador unico del objeto de dominio
B16: Corresponde a los datos de tipo alfanumerico
B17: Corresponde a referencias de objetos de dominio
B18: Corresponde a los datos calculados por el sistema
B19: Corresponde a la combinacion única

Sheet C-HorarioBarberia
A1: <<<< Ir al modulo de dominio | B1: <<<< Ir a objetos de dominio
A2: Nombre atributo | B2: Descripción atributo | C2: Identificador del objeto de dominio | D2: Tipo de dato | E2: Obligatorio | F2: Longitud mínima (si aplica) | G2: Longitud máxima (si aplica) | H2: Precisión (si aplica) | I2: Rendondeo (si aplica) | J2: Rango inicial (si aplica) | K2: Rango final (si aplica) | L2: Formato (si aplica) | M2: Reglas especiales (si aplica) | N2: Dato calculado | O2: Aplica ajuste del dato (si aplica) | P2: Carácter de ajuste (si aplica) | Q2: Quitar espacios en blanco al inicio (si aplica) | R2: Quitar espacios en blanco al fin (si aplica) | S2: Dato sensible (si aplica) | T2: Valor por defecto (si aplica) | U2: Auto generado
A3: ='M-HorarioBarberia'!A3 -> id | B3: ='M-HorarioBarberia'!A2 -> Representa un identificador que hará unico cada objeto de dominio de este tipo, no se puede repetir | C3: Si | D3: Identificador único universal | E3: Si | F3: No aplica | G3: No aplica | H3: No aplica | I3: No aplica | J3: No aplica | K3: No aplica | L3: No aplica | M3: No aplica | N3: No | O3: No | P3: No aplica | Q3: No aplica | R3: No aplica | S3: No | T3: UUID vacio | U3: Si
A4: ='M-HorarioBarberia'!B3 -> diaDeLaSemana | B4: ='M-HorarioBarberia'!B2 -> Representa el día de la semana en el que la barberia abre | C4: No | D4: DiaSemana | E4: Si | F4: No aplica | G4: No aplica | H4: No aplica | I4: No aplica | J4: No aplica | K4: No aplica | L4: No aplica | M4: Aplican las reglas del objeto referenciado | N4: No | O4: No | P4: No aplica | Q4: No aplica | R4: No aplica | S4: No | T4: UUID vacio | U4: No
A5: ='M-HorarioBarberia'!C3 -> horaApertura | B5: ='M-HorarioBarberia'!C2 -> Representa la hora a la que abre la barbería | C5: No | D5: Hora | E5: No | F5: No aplica | G5: No aplica | H5: No aplica | I5: No aplica | J5: No aplica | K5: No aplica | L5: No aplica | M5: No aplica | N5: No | O5: No | P5: No aplica | Q5: No aplica | R5: No aplica | S5: No | T5: 00:00 | U5: No
A6: ='M-HorarioBarberia'!D3 -> horaCierre | B6: ='M-HorarioBarberia'!D2 -> Representa la hora a la que cierra la barbería | C6: No | D6: Hora | E6: Si | F6: No aplica | G6: No aplica | H6: No aplica | I6: No aplica | J6: No aplica | K6: No aplica | L6: No aplica | M6: Debe ser mayor a horaApertura | N6: No | O6: No | P6: No aplica | Q6: No aplica | R6: No aplica | S6: No | T6: 00:00 | U6: No
A7: ='M-HorarioBarberia'!E3 -> fechaCreacion | B7: ='M-HorarioBarberia'!E2 -> Representa la fecha en el que el dueño definio el horario de la barberia. Es un dato calculado que toma la fecha del sistema en ese momento | C7: No | D7: Fecha | E7: Si | F7: No aplica | G7: No aplica | H7: No aplica | I7: No aplica | J7: No aplica | K7: No aplica | L7: No aplica | M7: No aplica | N7: Si | O7: No | P7: No aplica | Q7: No aplica | R7: No aplica | S7: No | T7: 1/01/1000 | U7: No
A8: ='M-HorarioBarberia'!F3 -> fechaDesactivacion | B8: ='M-HorarioBarberia'!F2 -> Representa la fecha en la que este horario dejó de estar vigente, dueño. Es un dato calculado que toma la fecha del sistema en ese momento | C8: No | D8: Fecha | E8: No | F8: No aplica | G8: No aplica | H8: No aplica | I8: No aplica | J8: No aplica | K8: No aplica | L8: No aplica | M8: No aplica | N8: Si | O8: No | P8: No aplica | Q8: No aplica | R8: No aplica | S8: No | T8: 1/01/1000 | U8: No
A9: ='M-HorarioBarberia'!G3 -> vigente | B9: ='M-HorarioBarberia'!G2 -> Representa si este horario lo sigue o no vigente en la barberia. Una vez que el dueño desactive el horario de la barberia, no se puede volver a cambiar | C9: No | D9: Lógico | E9: No | F9: No aplica | G9: No aplica | H9: No aplica | I9: No aplica | J9: No aplica | K9: No aplica | L9: No aplica | M9: No aplica | N9: No | O9: No | P9: No aplica | Q9: No aplica | R9: No aplica | S9: No | T9: Si | U9: No
A11: Nombre combinación única | B11: Descripción | C11: Atributos involucrados
A12: ='M-HorarioBarberia'!H3 -> Combinación única | B12: ='M-HorarioBarberia'!H2 -> Combinacion única que indica que no puede existir más de un horario con la misma barberia, dia de la semana, hora de apertura y cierre | C12: =A4 -> diaDeLaSemana
C13: =A5 -> horaApertura
C14: =A6 -> horaCierre
C15: =A7 -> fechaCreacion
C16: =A8 -> fechaDesactivacion
C17: =A9 -> vigente

Sheet M-HorarioBarberia
A1: <<<< Ir al modulo de dominio | B1: <<<< Ir a objetos de dominio
A2: Representa un identificador que hará unico cada objeto de dominio de este tipo, no se puede repetir | B2: Representa el día de la semana en el que la barberia abre | C2: Representa la hora a la que abre la barbería | D2: Representa la hora a la que cierra la barbería | E2: Representa la fecha en el que el dueño definio el horario de la barberia. Es un dato calculado que toma la fecha del sistema en ese momento | F2: Representa la fecha en la que este horario dejó de estar vigente, dueño. Es un dato calculado que toma la fecha del sistema en ese momento | G2: Representa si este horario lo sigue o no vigente en la barberia. Una vez que el dueño desactive el horario de la barberia, no se puede volver a cambiar | H2: Combinacion única que indica que no puede existir más de un horario con la misma barberia, dia de la semana, hora de apertura y cierre
A3: id | B3: diaDeLaSemana | C3: horaApertura | D3: horaCierre | E3: fechaCreacion | F3: fechaDesactivacion | G3: vigente | H3: Combinación única
A4: 1 | B4: ='M-DiaSemana'!C4 -> Lunes | C4: 0.375 | D4: 0.79166667 | E4: 45242 | F4: 1/01/1000 | G4: Si | H4: =_xlfn.CONCAT(B4,"-",TEXT(C4,"hh:mm"),"-",TEXT(D4,"hh:mm"),"-",TEXT(E4,"dd/mm/yyyy"),"-",TEXT(F4,"dd/mm/yyyy")) -> Lunes-09:00-19:00-12/11/2023-1/01/1000
A5: 2 | B5: ='M-DiaSemana'!C5 -> Martes | C5: 0.375 | D5: 0.79166667 | E5: 45242 | F5: 1/01/1000 | G5: Si | H5: =_xlfn.CONCAT(B5,"-",TEXT(C5,"hh:mm"),"-",TEXT(D5,"hh:mm"),"-",TEXT(E5,"dd/mm/yyyy"),"-",TEXT(F5,"dd/mm/yyyy")) -> Martes-09:00-19:00-12/11/2023-1/01/1000
A6: 3 | B6: ='M-DiaSemana'!C6 -> Miércoles | C6: 0.375 | D6: 0.79166667 | E6: 45242 | F6: 1/01/1000 | G6: Si | H6: =_xlfn.CONCAT(B6,"-",TEXT(C6,"hh:mm"),"-",TEXT(D6,"hh:mm"),"-",TEXT(E6,"dd/mm/yyyy"),"-",TEXT(F6,"dd/mm/yyyy")) -> Miércoles-09:00-19:00-12/11/2023-1/01/1000
A7: 4 | B7: ='M-DiaSemana'!C7 -> Jueves | C7: 0.375 | D7: 0.79166667 | E7: 45242 | F7: 1/01/1000 | G7: Si | H7: =_xlfn.CONCAT(B7,"-",TEXT(C7,"hh:mm"),"-",TEXT(D7,"hh:mm"),"-",TEXT(E7,"dd/mm/yyyy"),"-",TEXT(F7,"dd/mm/yyyy")) -> Jueves-09:00-19:00-12/11/2023-1/01/1000
A8: 5 | B8: ='M-DiaSemana'!C8 -> Viernes | C8: 0.375 | D8: 0.79166667 | E8: 45242 | F8: 1/01/1000 | G8: Si | H8: =_xlfn.CONCAT(B8,"-",TEXT(C8,"hh:mm"),"-",TEXT(D8,"hh:mm"),"-",TEXT(E8,"dd/mm/yyyy"),"-",TEXT(F8,"dd/mm/yyyy")) -> Viernes-09:00-19:00-12/11/2023-1/01/1000
A9: 6 | B9: ='M-DiaSemana'!C9 -> Sábado | C9: 0.33333333 | D9: 0.875 | E9: 45638 | F9: 1/01/1000 | G9: Si | H9: =_xlfn.CONCAT(B9,"-",TEXT(C9,"hh:mm"),"-",TEXT(D9,"hh:mm"),"-",TEXT(E9,"dd/mm/yyyy"),"-",TEXT(F9,"dd/mm/yyyy")) -> Sábado-08:00-21:00-12/12/2024-1/01/1000
A10: 7 | B10: ='M-DiaSemana'!C11 -> Festivo | C10: 0.41666667 | D10: 0.625 | E10: 45638 | F10: 1/01/1000 | G10: Si | H10: =_xlfn.CONCAT(B10,"-",TEXT(C10,"hh:mm"),"-",TEXT(D10,"hh:mm"),"-",TEXT(E10,"dd/mm/yyyy"),"-",TEXT(F10,"dd/mm/yyyy")) -> Festivo-10:00-15:00-12/12/2024-1/01/1000
B16: Corresponde a la descripcion de los atributos
B17: Corresponde al identificador unico del objeto de dominio
B18: Corresponde a referencias de objetos de dominio
B19: Corresponde a los datos de tipo hora
B20: Corresponde a los datos calculados por el sistema
B21: Corresponde a los datos tipo logico
B22: Corresponde a la combinacion única

Sheet C-BarberoServicio
A1: <<<< Ir al modulo de dominio | B1: <<<< Ir a objetos de dominio
A2: Nombre atributo | B2: Descripción atributo | C2: Identificador del objeto de dominio | D2: Tipo de dato | E2: Obligatorio | F2: Longitud mínima (si aplica) | G2: Longitud máxima (si aplica) | H2: Precisión (si aplica) | I2: Rendondeo (si aplica) | J2: Rango inicial (si aplica) | K2: Rango final (si aplica) | L2: Formato (si aplica) | M2: Reglas especiales (si aplica) | N2: Dato calculado | O2: Aplica ajuste del dato (si aplica) | P2: Carácter de ajuste (si aplica) | Q2: Quitar espacios en blanco al inicio (si aplica) | R2: Quitar espacios en blanco al fin (si aplica) | S2: Dato sensible (si aplica) | T2: Valor por defecto (si aplica) | U2: Auto generado
A3: ='M-BarberoServicio'!A3 -> id | B3: ='M-BarberoServicio'!A2 -> Representa un identificador que hará unico cada objeto de dominio de este tipo, no se puede repetir | C3: Si | D3: Identificador único universal | E3: Si | F3: No aplica | G3: No aplica | H3: No aplica | I3: No aplica | J3: No aplica | K3: No aplica | L3: No aplica | M3: No aplica | N3: No | O3: No aplica | P3: No aplica | Q3: No aplica | R3: No aplica | S3: No | T3: UUID vacio | U3: Si
A4: ='M-BarberoServicio'!B3 -> barbero | B4: ='M-BarberoServicio'!B2 -> Representa el nombre y apellidos del barbero | C4: No | D4: Barbero | E4: Si | F4: No aplica | G4: No aplica | H4: No aplica | I4: No aplica | J4: No aplica | K4: No aplica | L4: No aplica | M4: Aplican las reglas del objeto referenciado | N4: No | O4: No aplica | P4: No aplica | Q4: No aplica | R4: No aplica | S4: No | T4: UUID vacio | U4: No
A5: ='M-BarberoServicio'!C3 -> servicio | B5: ='M-BarberoServicio'!C2 -> Representa el nombre del servicio de la barberia | C5: No | D5: Servicio | E5: Si | F5: No aplica | G5: No aplica | H5: No aplica | I5: No aplica | J5: No aplica | K5: No aplica | L5: No aplica | M5: Aplican las reglas del objeto referenciado | N5: No | O5: No aplica | P5: No aplica | Q5: No aplica | R5: No aplica | S5: No | T5: UUID vacio | U5: No
A6: ='M-BarberoServicio'!D3 -> duracionEnHoras | B6: ='M-BarberoServicio'!D2 -> Representa la cantidad de horas que un barbero tarda en realizar un servicio, esta duracion el barbero debe de ser consiente de cuanto se demora en realizarlo | C6: No | D6: Entero | E6: No | F6: No aplica | G6: No aplica | H6: No aplica | I6: No aplica | J6: 0 | K6: 3 | L6: No aplica | M6: No aplica | N6: No | O6: No aplica | P6: No aplica | Q6: No aplica | R6: No aplica | S6: No | T6: 0 | U6: No
A7: ='M-BarberoServicio'!E3 -> duracionEnMinutos | B7: ='M-BarberoServicio'!E2 -> Representa la cantidad de minutos que un barbero tarda en realizar un servicio, esta duracion el barbero debe de ser consiente de cuanto se demora en realizarlo | C7: No | D7: Entero | E7: No | F7: No aplica | G7: No aplica | H7: No aplica | I7: No aplica | J7: 0 | K7: 59 | L7: No aplica | M7: No aplica | N7: No | O7: No aplica | P7: No aplica | Q7: No aplica | R7: No aplica | S7: No | T7: 0 | U7: No
A8: ='M-BarberoServicio'!F3 -> tiempoExtra | B8: ='M-BarberoServicio'!F2 -> Representa la cantidad de minutos que un barbero pone de tiempo extra en las citas de su agenda, cada barbero usa este tiempo porque hay ocaciones que la cita se puede demorar más de lo previsto. Este tiempo les ayuda a evitar que se les retrase la agenda | C8: No | D8: Entero | E8: No | F8: No aplica | G8: No aplica | H8: No aplica | I8: No aplica | J8: 0 | K8: 59 | L8: No aplica | M8: No aplica | N8: No | O8: No aplica | P8: No aplica | Q8: No aplica | R8: No aplica | S8: No | T8: 0 | U8: No
A9: ='M-BarberoServicio'!G3 -> vigente | B9: ='M-BarberoServicio'!G2 -> Representa si el barbero sigue o no presentando el servicio en la barbería | C9: No | D9: Lógico | E9: No | F9: No aplica | G9: No aplica | H9: No aplica | I9: No aplica | J9: No aplica | K9: No aplica | L9: No aplica | M9: No aplica | N9: No | O9: No aplica | P9: No aplica | Q9: No aplica | R9: No aplica | S9: No | T9: Si | U9: No
A11: Nombre combinación única | B11: Descripción | C11: Atributos involucrados
A12: ='M-BarberoServicio'!H3 -> Combinación única | B12: ='M-BarberoServicio'!H2 -> Combinación única que indica que un mismo barbero no puede aparecer dos veces ofreciendo el mismo servicio | C12: barbero
C13: servicio

Sheet M-BarberoServicio
A1: <<<< Ir al modulo de dominio | B1: <<<< Ir a objetos de dominio
