Workbook

Sheet Modelo de Dominio
A1: Ir a objetos de dominio >>>>

Sheet Objetos de Dominio
A1: <<<< Ir al modulo de dominio
A2: Nombre | B2: Descripcion | C2: Linea de vida | D2: Datos
A3: Dueño | B3: Representa a quien va crear la regla de la barberia, los horarios de la barberia y los servicios de la barberia | C3: 1 | D3: aquí
A4: Barbero | B4: Representa a un trabajador de la barbería que atiende clientes según los servicios que sabe realizar y que organiza su tiempo a través de su propia agenda | C4: 1 | D4: aquí
A5: Cliente | B5: Representa a la persona que solicita citas en la barbería, el se las pide a un barbero por WhatsApp. Su valor esta en darle al sistema un historial por persona: que citas ha pedido, que multas tiene y si esta o no vetado, para que cualquier barbero sepa con quien esta tratando antes de agendarle | C5: 1 | D5: aquí
A6: Agenda | B6: Representa la agenda personal de un barbero, donde se junta todo lo que ocupa su tiempo: los horarios de trabajo que definió para cada día, los bloqueos puntuales y las citas que el agrego agendaron. Es el único lugar donde el barbero ve su tiempo organizado. | C6: 1 | D6: aquí
A7: HorarioBarberia | B7: Representa, día por día, a que hora abre y cierra el negocio. Es el límite dentro del cual tiene que caber el horario de cualquier barbero, nadie puede trabajar antes de que abra ni después de que cierre | C7: 2 | D7: aquí
A8: Regla | B8: Representa las políticas de la barbería frente al incumplimiento de los clientes o barberos: cuantos minutos de tolerancia se dan antes de considerar tardanza, cuanto vale la multa fija por llegar tarde, y cuantas multas sin pagar activan un veto | C8: 2 | D8: aquí
A9: Servicio | B9: Representa cada tipo de corte o arreglo que ha definido el dueño para la barberia y que cada barbero luego decida que servicio prestar | C9: 2 | D9: aquí
A10: Bloqueo | B10: Representa un momento puntual en una fecha y hora específica, en el que un barbero no puede trabajar por un compromiso personal, aunque ese día normalmente sí trabaje según su horario | C10: 2 | D10: aquí
A11: BarberoServicio | B11: Representa que servicios realiza cada barbero, ya que no todos los barberos de la barbería ofrecen los mismos servicios, mostrando lo que demora cada barbero en realizar ese servicio y un tiempo de desfase en caso de que se demore más en realizar el servicio | C11: 3 | D11: aquí
A12: HorarioBarbero | B12: Representa el día de la semana, con la hora en que empieza y termina trabajar un barbero, con su descanso si el lo quiere | C12: 3 | D12: aquí
A13: Cita | B13: Representa la reserva de un cliente con un barbero para una fecha y hora puntual. La cita puede tener seis estados (agendada, atendida, el cliente se demoro, me demore, incumplida, cancelada) | C13: 3 | D13: aquí
A14: CitaServicio | B14: Representa cada servicio incluido dentro de una cita puntual, guardando el precio y la duración que tenía ese servicio en el momento exacto en que se agendó, para que cambios futuros en el catálogo no alteren citas ya registradas | C14: 4 | D14: aquí
A15: Multa | B15: Representa la sanción económica que se le impone a un cliente por incumplir una cita (llegar tarde fuera de tolerancia o no presentarse), calculada a partir de la cita específica que la originó | C15: 4 | D15: aquí

Sheet C-Agenda
A1: <<<< Ir al modulo de dominio | B1: <<<< Ir a objetos de dominio
A2: Nombre atributo | B2: Descripción atributo | C2: Identificador del objeto de dominio | D2: Tipo de dato | E2: Obligatorio | F2: Longitud mínima (si aplica) | G2: Longitud máxima (si aplica) | H2: Precisión (si aplica) | I2: Rendondeo (si aplica) | J2: Rango inicial (si aplica) | K2: Rango final (si aplica) | L2: Formato (si aplica) | M2: Reglas especiales (si aplica) | N2: Dato calculado | O2: Aplica ajuste del dato (si aplica) | P2: Carácter de ajuste (si aplica) | Q2: Quitar espacios en blanco al inicio (si aplica) | R2: Quitar espacios en blanco al fin (si aplica) | S2: Dato sensible (si aplica) | T2: Valor por defecto (si aplica) | U2: Auto generado
A3: ='M-Agenda'!A3 -> id | B3: ='M-Agenda'!A2 -> Representa un identificador que hará unico cada objeto de dominio de este tipo, no se puede repetir | C3: Si | D3: Identificador único universal | E3: Si | N3: No | O3: No | Q3: No | R3: No | S3: No | U3: Si
A4: ='M-Agenda'!B3 -> nombre | B4: ='M-Agenda'!B2 -> Representa como el barbero llama a su propia agenda. Su valor por defecto es el vacio y no es permitido | C4: No | D4: Alfanumérico | E4: Si | F4: 3 | G4: 100 | N4: No | O4: No | Q4: Si | R4: Si | S4: No | U4: No
A6: Nombre combinación única | B6: Descripción | C6: Atributos involucrados
A7: ='M-Agenda'!C3 -> Combinación única | B7: ='M-Agenda'!C2 -> Combinación única que indica que no puede existir más de una agenda con el mismo nombre | C7: =A4 -> nombre

Sheet M-Agenda
A1: <<<< Ir al modulo de dominio | B1: <<<< Ir a objetos de dominio
A2: Representa un identificador que hará unico cada objeto de dominio de este tipo, no se puede repetir | B2: Representa como el barbero llama a su propia agenda. Su valor por defecto es el vacio y no es permitido | C2: Combinación única que indica que no puede existir más de una agenda con el mismo nombre
A3: id | B3: nombre | C3: Combinación única
A4: 1 | B4: Agenda de Juan García | C4: =B4 -> Agenda de Juan García
A5: 2 | B5: Agenda de Juan Ortiz | C5: =B5 -> Agenda de Juan Ortiz
A6: 3 | B6: Agenda de Carlos Arbeladez | C6: =B6 -> Agenda de Carlos Arbeladez
A7: 4 | B7: Agenda de Andres Ramirez | C7: =B7 -> Agenda de Andres Ramirez
A8: 5 | B8: Agenda de Juan Carlos Zambrano | C8: =B8 -> Agenda de Juan Carlos Zambrano
B13: Corresponde a la descripcion de los atributos
B14: Corresponde al identificador unico del objeto de dominio
B15: Corresponde a los datos de tipo alfanumerico
B16: Corresponde a la combinacion única

Sheet C-Dueño
A1: <<<< Ir al modulo de dominio | B1: <<<< Ir a objetos de dominio
A2: Nombre atributo | B2: Descripción atributo | C2: Identificador del objeto de dominio | D2: Tipo de dato | E2: Obligatorio | F2: Longitud mínima (si aplica) | G2: Longitud máxima (si aplica) | H2: Precisión (si aplica) | I2: Rendondeo (si aplica) | J2: Rango inicial (si aplica) | K2: Rango final (si aplica) | L2: Formato (si aplica) | M2: Reglas especiales (si aplica) | N2: Dato calculado | O2: Aplica ajuste del dato (si aplica) | P2: Carácter de ajuste (si aplica) | Q2: Quitar espacios en blanco al inicio (si aplica) | R2: Quitar espacios en blanco al fin (si aplica) | S2: Dato sensible (si aplica) | T2: Valor por defecto (si aplica) | U2: Auto generado
A3: ='M-Dueño'!A3 -> id | B3: ='M-Dueño'!A2 -> Representa un identificador que hará unico cada objeto de dominio de este tipo, no se puede repetir | C3: Si | D3: Identificador único universal | E3: Si | N3: No | O3: No | Q3: No | R3: No | S3: No | U3: Si
A4: ='M-Dueño'!B3 -> correo | B4: ='M-Dueño'!B2 -> Representa el correo electronico del dueño de la barberia, con el que se va a registrar o iniciar seción. Su valor por defecto es el vacio y no es permitido | C4: No | D4: Alfanumérico | E4: Si | F4: 3 | G4: 255 | L4: Debe de tener un @, tener un dominio de correo después del @, debe de terminar en el dominio web del correo, como .com, .co y no debe de tener espacios en blanco | N4: No | O4: No | Q4: Si | R4: Si | S4: No | U4: No
A5: ='M-Dueño'!C3 -> contraseña | B5: ='M-Dueño'!C2 -> Representa la contraseña encriptada del dueño de la barberia. Su tipo de dato es alfanumérico, su valor por defecto es el vacio y no esta permitido | C5: No | D5: Alfanumérico | E5: Si | F5: 8 | G5: 60 | M5: Se almacena cifrada con bcrypt | N5: No | O5: No | Q5: No | R5: No | S5: Si | U5: No
A6: ='M-Dueño'!D3 -> nombre | B6: ='M-Dueño'!D2 -> Representa el nombre de como el dueño, es quien decide el los cambios de la barberia | C6: No | D6: Alfanumérico | E6: Si | F6: 1 | G6: 30 | N6: No | O6: No | Q6: Si | R6: Si | S6: No | U6: No
A8: Nombre combinación única | B8: Descripción | C8: Atributos involucrados
A9: correoUnico | B9: Combinación única que indica que no puede existir más de un dueño con el mismo correo | C9: =A4 -> correo

Sheet M-Dueño
A1: <<<< Ir al modulo de dominio | B1: <<<< Ir a objetos de dominio
A2: Representa un identificador que hará unico cada objeto de dominio de este tipo, no se puede repetir | B2: Representa el correo electronico del dueño de la barberia, con el que se va a registrar o iniciar seción. Su valor por defecto es el vacio y no es permitido | C2: Representa la contraseña encriptada del dueño de la barberia. Su tipo de dato es alfanumérico, su valor por defecto es el vacio y no esta permitido | D2: Representa el nombre de como el dueño, es quien decide el los cambios de la barberia
A3: id | B3: correo | C3: contraseña | D3: nombre
A4: 1 | B4: dueniodelabarberia12345@gmail.com | C4: $2b$12$ArgOhAQEFEYiMG55jPsz9uVYEx8lc35b7Y8CJbpqSk0nB079OkbO. | D4: Carlos
B10: Corresponde a la descripcion de los atributos
B11: Corresponde al identificador unico del objeto de dominio
B12: Corresponde a los datos de tipo alfanumerico

Sheet C-Barbero
A1: <<<< Ir al modulo de dominio | B1: <<<< Ir a objetos de dominio
A2: Nombre atributo | B2: Descripción atributo | C2: Identificador del objeto de dominio | D2: Tipo de dato | E2: Obligatorio | F2: Longitud mínima (si aplica) | G2: Longitud máxima (si aplica) | H2: Precisión (si aplica) | I2: Rendondeo (si aplica) | J2: Rango inicial (si aplica) | K2: Rango final (si aplica) | L2: Formato (si aplica) | M2: Reglas especiales (si aplica) | N2: Dato calculado | O2: Aplica ajuste del dato (si aplica) | P2: Carácter de ajuste (si aplica) | Q2: Quitar espacios en blanco al inicio (si aplica) | R2: Quitar espacios en blanco al fin (si aplica) | S2: Dato sensible (si aplica) | T2: Valor por defecto (si aplica) | U2: Auto generado
A3: ='M-Barbero'!A3 -> id | B3: ='M-Barbero'!A2 -> Representa un identificador que hará unico cada objeto de dominio de este tipo, no se puede repetir | C3: Si | D3: Identificador único universal | E3: Si | N3: No | O3: No | Q3: No | R3: No | S3: No | U3: Si
A4: ='M-Barbero'!B3 -> primerNombre | B4: ='M-Barbero'!B2 -> Representa el primer nombre del barbero que trabaja en barbería | C4: No | D4: Alfanumérico | E4: Si | F4: 2 | G4: 50 | N4: No | O4: No | Q4: Si | R4: Si | S4: No | U4: No
A5: ='M-Barbero'!C3 -> segundoNombre | B5: ='M-Barbero'!C2 -> Representa el segundo nombre del barbero que trabaja en barbería | C5: No | D5: Alfanumérico | E5: No | F5: 2 | G5: 50 | N5: No | O5: No | Q5: Si | R5: Si | S5: No | U5: No
A6: ='M-Barbero'!D3 -> primerApellido | B6: ='M-Barbero'!D2 -> Representa el primer apellido del barbero que trabaja en la barbería | C6: No | D6: Alfanumérico | E6: Si | F6: 2 | G6: 50 | N6: No | O6: No | Q6: Si | R6: Si | S6: No | U6: No
A7: ='M-Barbero'!E3 -> segundoApellido | B7: ='M-Barbero'!E2 -> Representa el segundo apellido del barbero que trabaja en la barbería | C7: No | D7: Alfanumérico | E7: No | F7: 2 | G7: 50 | N7: No | O7: No | Q7: Si | R7: Si | S7: No | U7: No
A8: ='M-Barbero'!F3 -> prefijo | B8: ='M-Barbero'!F2 -> Representa de que pais es el numero de celular del barbero | C8: No | D8: Alfanumérico | E8: Si | F8: 2 | G8: 4 | M8: Debe iniciar con el símbolo + seguido del indicativo telefónico del país | N8: No | O8: No | Q8: Si | R8: Si | S8: No | T8: +0 | U8: No
A9: ='M-Barbero'!G3 -> celular | B9: ='M-Barbero'!G2 -> Representa el número de celular del barbero | C9: No | D9: Alfanumérico | E9: Si | F9: 4 | G9: 15 | L9: Deben de ser solo números que cumplan un número de teléfono válido | N9: No | O9: No | Q9: Si | R9: Si | S9: No | T9: 0000 | U9: No
A10: ='M-Barbero'!H3 -> correo | B10: ='M-Barbero'!H2 -> Representa el correo electronico del barbero, con el que se va a registrar o iniciar seción | C10: No | D10: Alfanumérico | E10: Si | F10: 3 | G10: 255 | L10: Debe de tener un @, tener un dominio de correo después del @, debe de terminar en el dominio web del correo, como .com, .co y no debe de tener espacios en blanco | N10: No | O10: No | Q10: Si | R10: Si | S10: No | U10: No
A11: ='M-Barbero'!I3 -> contraseña | B11: ='M-Barbero'!I2 -> Representa la contraseña encriptada del barbero | C11: No | D11: Alfanumérico | E11: Si | F11: 8 | G11: 60 | M11: Se almacena cifrada con bcrypt | N11: No | O11: No | Q11: No | R11: No | S11: Si | U11: No
A12: ='M-Barbero'!J3 -> vigente | B12: ='M-Barbero'!J2 -> Representa si el barbero sigue o no trabajando. Es un dato calculado, si el barbero tiene en su agenda un horario de trabajo si es vigente y si no tiene horario de trabajo dice no es vigente | C12: No | D12: Lógico | E12: No | M12: Se calcula evaluando si el barbero tiene al menos un HorarioBarbero vigente; si no tiene ninguna, no es vigente | N12: Si | O12: No | Q12: No | R12: No | S12: No | U12: No
A14: Nombre combinación única | B14: Descripción | C14: Atributos involucrados
A15: ='M-Barbero'!K3 -> Combinación única | B15: ='M-Barbero'!K2 -> Combinacion única que indica que no puede existir más de un barbero con el mismo nombre, apellidos, prefijo de celular y número de celular | C15: =A4 -> primerNombre
C16: =A5 -> segundoNombre
C17: =A6 -> primerApellido
C18: =A7 -> segundoApellido
C19: =A8 -> prefijo
C20: =A9 -> celular

Sheet M-Barbero
A1: <<<< Ir al modulo de dominio | B1: <<<< Ir a objetos de dominio
A2: Representa un identificador que hará unico cada objeto de dominio de este tipo, no se puede repetir | B2: Representa el primer nombre del barbero que trabaja en barbería | C2: Representa el segundo nombre del barbero que trabaja en barbería | D2: Representa el primer apellido del barbero que trabaja en la barbería | E2: Representa el segundo apellido del barbero que trabaja en la barbería | F2: Representa de que pais es el numero de celular del barbero | G2: Representa el número de celular del barbero | H2: Representa el correo electronico del barbero, con el que se va a registrar o iniciar seción | I2: Representa la contraseña encriptada del barbero | J2: Representa si el barbero sigue o no trabajando. Es un dato calculado, si el barbero tiene en su agenda un horario de trabajo si es vigente y si no tiene horario de trabajo dice no es vigente | K2: Combinacion única que indica que no puede existir más de un barbero con el mismo nombre, apellidos, prefijo de celular y número de celular
A3: id | B3: primerNombre | C3: segundoNombre | D3: primerApellido | E3: segundoApellido | F3: prefijo | G3: celular | H3: correo | I3: contraseña | J3: vigente | K3: Combinación única
A4: 1 | B4: Juan | C4: Fernando | D4: García | E4: Lopez | F4: +57 | G4: 3245627890 | H4: juanfer234535@gmail.com | I4: $2b$12$Ce2ZsSJaOpx4iq5W.LNrCuvonh1fxNgpYYqBddeR50IjtYsh9n97C | J4: si | K4: =_xlfn.CONCAT(B4,"-",C4,"-",D4,"-",E4,"-",F4,"-",G4) -> Juan-Fernando-García-Lopez-+57-3245627890
A5: 2 | B5: Juan | C5: David | D5: Ortiz | E5: Sanchez | F5: +57 | G5: 3124518923 | H5: juandaviddd2525@gmail.com | I5: $2b$12$4dn1n10vtv3SpDX5ryR2FOluaaros/pqDXz8liKcEp/7JG7TBvqAK | J5: si | K5: =_xlfn.CONCAT(B5,"-",C5,"-",D5,"-",E5,"-",F5,"-",G5) -> Juan-David-Ortiz-Sanchez-+57-3124518923
A6: 3 | B6: Carlos | D6: Arbeladez | F6: +57 | G6: 3214533321 | H6: carlosbeladez@gmail.com | I6: $2b$12$htWWNCh.2QPjVycBmNb5ROHBO21L9p7hlWyFtctUtP4SbV3yBNqei | J6: si | K6: =_xlfn.CONCAT(B6,"-",C6,"-",D6,"-",E6,"-",F6,"-",G6) -> Carlos--Arbeladez--+57-3214533321
A7: 4 | B7: Andres | D7: Ramirez | E7: Patiño | F7: +91 | G7: 9876543210 | H7: andresramirezpatino123@gmail.com | I7: $2b$12$IzNJVnlQl1UX5Py84yi5jOE1yuEdUrA.0Okt.BidVKs8biBdotH7W | J7: no | K7: =_xlfn.CONCAT(B7,"-",C7,"-",D7,"-",E7,"-",F7,"-",G7) -> Andres--Ramirez-Patiño-+91-9876543210
A8: 5 | B8: Juan | C8: Carlos | D8: Zambrano | E8: Perez | F8: +593 | G8: 998765432 | H8: juancarloszambrano4394@gmail.com | I8: $2b$12$mlxS0WUooP1stXSQdVR8EeBoYrgBrP5czZRqSvIgvelxUIGcwFgh. | J8: no | K8: =_xlfn.CONCAT(B8,"-",C8,"-",D8,"-",E8,"-",F8,"-",G8) -> Juan-Carlos-Zambrano-Perez-+593-998765432
B14: Corresponde a la descripcion de los atributos
B15: Corresponde al identificador unico del objeto de dominio
B16: Corresponde a los datos de tipo alfanumerico
B17: Corresponde a los datos calculados por el sistema
B18: Corresponde a la combinacion única

Sheet C-Cliente
A1: <<<< Ir al modulo de dominio | B1: <<<< Ir a objetos de dominio
A2: Nombre atributo | B2: Descripción atributo | C2: Identificador del objeto de dominio | D2: Tipo de dato | E2: Obligatorio | F2: Longitud mínima (si aplica) | G2: Longitud máxima (si aplica) | H2: Precisión (si aplica) | I2: Rendondeo (si aplica) | J2: Rango inicial (si aplica) | K2: Rango final (si aplica) | L2: Formato (si aplica) | M2: Reglas especiales (si aplica) | N2: Dato calculado | O2: Aplica ajuste del dato (si aplica) | P2: Carácter de ajuste (si aplica) | Q2: Quitar espacios en blanco al inicio (si aplica) | R2: Quitar espacios en blanco al fin (si aplica) | S2: Dato sensible (si aplica) | T2: Valor por defecto (si aplica) | U2: Auto generado
A3: ='M-Cliente'!A3 -> id | B3: ='M-Cliente'!A2 -> Representa un identificador que hará unico cada objeto de dominio de este tipo, no se puede repetir | C3: Si | D3: Identificador único universal | E3: Si | N3: Si | O3: No | Q3: No | R3: No | S3: No | U3: Si
A4: ='M-Cliente'!B3 -> primerNombre | B4: ='M-Cliente'!B2 -> Representa el primer nombre de la persona, que va a estar llendo a la barberia para las citas | C4: No | D4: Alfanumérico | E4: Si | F4: 2 | G4: 50 | N4: No | O4: No | Q4: Si | R4: Si | S4: No | U4: No
A5: ='M-Cliente'!C3 -> segundoNombre | B5: ='M-Cliente'!C2 -> Representa el segundo nombre de la persona, que va a estar llendo a la barberia para las citas | C5: No | D5: Alfanumérico | E5: No | F5: 2 | G5: 50 | N5: No | O5: No | Q5: Si | R5: Si | S5: No | U5: No
A6: ='M-Cliente'!D3 -> primerApellido | B6: ='M-Cliente'!D2 -> Representa el primer apellido de la persona, que va a estar llendo a la barberia para las citas | C6: No | D6: Alfanumérico | E6: Si | F6: 2 | G6: 50 | N6: No | O6: No | Q6: Si | R6: Si | S6: No | U6: No
A7: ='M-Cliente'!E3 -> segundoApellido | B7: ='M-Cliente'!E2 -> Representa el segundo apellido de la persona, que va a estar llendo a la barberia para las citas | C7: No | D7: Alfanumérico | E7: No | F7: 2 | G7: 50 | N7: No | O7: No | Q7: Si | R7: Si | S7: No | U7: No
A8: ='M-Cliente'!F3 -> prefijoCelular | B8: ='M-Cliente'!F2 -> Representa de que pais es el numero de celular del cliente | C8: No | D8: Alfanumérico | E8: Si | F8: 2 | G8: 4 | M8: Debe iniciar con el símbolo + seguido del indicativo telefónico del país | N8: No | O8: No | Q8: No | R8: No | S8: No | T8: +0 | U8: No
A9: ='M-Cliente'!G3 -> celular | B9: ='M-Cliente'!G2 -> Representa el numero de celular de la persona que le va a escribir al barbero por WhatsApp para pedirle una cita | C9: No | D9: Alfanumérico | E9: Si | F9: 4 | G9: 15 | L9: Deben de ser solo números que cumplan un número de teléfono válido | N9: No | O9: No | Q9: Si | R9: Si | S9: No | U9: No
A10: ='M-Cliente'!H3 -> multasSinPagar | B10: ='M-Cliente'!H2 -> Representa la cantidad de multas que tiene sin pagar en las citas que ha tenido, ya sea multa por tardanza o por no llegar | C10: No | D10: Entero | E10: Si | M10: Se calcula contando las Multa del cliente donde pagada='no' | N10: Si | O10: No | T10: 0 | U10: No
A11: ='M-Cliente'!I3 -> estaVetado | B11: ='M-Cliente'!I2 -> Representa si el cliente esta en estado de veto o no, cuando el cliente esta vetado el sistema no va a permitir agendar citas con este cliente con ningun barbero | C11: No | D11: Lógico | E11: Si | M11: Se calcula comparando multasSinPagar contra Regla.numeroMultasMaxima; si multasSinPagar alcanza ese máximo, el cliente queda vetado | N11: Si | O11: No | T11: No | U11: No
A13: Nombre combinación única | B13: Descripción | C13: Atributos involucrados
A14: ='M-Cliente'!J3 -> Combinación única | B14: ='M-Cliente'!J2 -> Combinacion única que indica que no puede existir más de un cliente con un mismo nombre, apellidos, prefijo de celular y número de celular | C14: =A4 -> primerNombre
C15: =A5 -> segundoNombre
C16: =A6 -> primerApellido
C17: =A7 -> segundoApellido
C18: =A8 -> prefijoCelular
C19: =A9 -> celular

Sheet M-Cliente
A1: <<<< Ir al modulo de dominio | B1: <<<< Ir a objetos de dominio
A2: Representa un identificador que hará unico cada objeto de dominio de este tipo, no se puede repetir | B2: Representa el primer nombre de la persona, que va a estar llendo a la barberia para las citas | C2: Representa el segundo nombre de la persona, que va a estar llendo a la barberia para las citas | D2: Representa el primer apellido de la persona, que va a estar llendo a la barberia para las citas | E2: Representa el segundo apellido de la persona, que va a estar llendo a la barberia para las citas | F2: Representa de que pais es el numero de celular del cliente | G2: Representa el numero de celular de la persona que le va a escribir al barbero por WhatsApp para pedirle una cita | H2: Representa la cantidad de multas que tiene sin pagar en las citas que ha tenido, ya sea multa por tardanza o por no llegar | I2: Representa si el cliente esta en estado de veto o no, cuando el cliente esta vetado el sistema no va a permitir agendar citas con este cliente con ningun barbero | J2: Combinacion única que indica que no puede existir más de un cliente con un mismo nombre, apellidos, prefijo de celular y número de celular
A3: id | B3: primerNombre | C3: segundoNombre | D3: primerApellido | E3: segundoApellido | F3: prefijoCelular | G3: celular | H3: multasSinPagar | I3: estaVetado | J3: Combinación única
A4: 1 | B4: Juan | D4: Gómez | F4: +57 | G4: 3234528921 | H4: 0 | I4: no | J4: =_xlfn.CONCAT(B4,"-",C4,"-",D4,"-",E4,"-",F4,"-",G4) -> Juan--Gómez--+57-3234528921
A5: 2 | B5: Jose | C5: Miguel | D5: Ramirez | E5: Perez | F5: +57 | G5: 3161657782 | H5: 0 | I5: no | J5: =_xlfn.CONCAT(B5,"-",C5,"-",D5,"-",E5,"-",F5,"-",G5) -> Jose-Miguel-Ramirez-Perez-+57-3161657782
A6: 3 | B6: Simon | D6: Ochoa | E6: Ramirez | F6: +57 | G6: 3119884321 | H6: 0 | I6: no | J6: =_xlfn.CONCAT(B6,"-",C6,"-",D6,"-",E6,"-",F6,"-",G6) -> Simon--Ochoa-Ramirez-+57-3119884321
A7: 4 | B7: Alexis | D7: Gallego | F7: +58 | G7: 4127359182 | H7: 1 | I7: no | J7: =_xlfn.CONCAT(B7,"-",C7,"-",D7,"-",E7,"-",F7,"-",G7) -> Alexis--Gallego--+58-4127359182
A8: 5 | B8: Kevin | C8: Andrés | D8: Muñoz | E8: Salazar | F8: +57 | G8: 3005544332 | H8: 3 | I8: si | J8: =_xlfn.CONCAT(B8,"-",C8,"-",D8,"-",E8,"-",F8,"-",G8) -> Kevin-Andrés-Muñoz-Salazar-+57-3005544332
B14: Corresponde a la descripcion de los atributos
B15: Corresponde al identificador unico del objeto de dominio
B16: Corresponde a los datos de tipo alfanumerico
B17: Corresponde a los datos calculados por el sistema
B18: Corresponde a la combinacion única

Sheet C-HorarioBarberia
A1: <<<< Ir al modulo de dominio | B1: <<<< Ir a objetos de dominio
A2: Nombre atributo | B2: Descripción atributo | C2: Identificador del objeto de dominio | D2: Tipo de dato | E2: Obligatorio | F2: Longitud mínima (si aplica) | G2: Longitud máxima (si aplica) | H2: Precisión (si aplica) | I2: Rendondeo (si aplica) | J2: Rango inicial (si aplica) | K2: Rango final (si aplica) | L2: Formato (si aplica) | M2: Reglas especiales (si aplica) | N2: Dato calculado | O2: Aplica ajuste del dato (si aplica) | P2: Carácter de ajuste (si aplica) | Q2: Quitar espacios en blanco al inicio (si aplica) | R2: Quitar espacios en blanco al fin (si aplica) | S2: Dato sensible (si aplica) | T2: Valor por defecto (si aplica) | U2: Auto generado
A3: ='M-HorarioBarberia'!A3 -> id | B3: ='M-HorarioBarberia'!A2 -> Representa un identificador que hará unico cada objeto de dominio de este tipo, no se puede repetir | C3: Si | D3: Identificador único universal | E3: Si | N3: No | O3: No | Q3: No | R3: No | S3: No | U3: Si
A4: ='M-HorarioBarberia'!B3 -> dueño | B4: ='M-HorarioBarberia'!B2 -> Representa que el dueño tomo la decisión de agregar un horario para la barberia | C4: No | D4: Dueño | E4: Si | M4: Aplican las reglas del objeto referenciado | N4: No | O4: No | Q4: No | R4: No | S4: No | U4: No
A5: ='M-HorarioBarberia'!C3 -> diaDeLaSemana | B5: ='M-HorarioBarberia'!C2 -> Representa el día de la semana en que aplica este horario, el dueño solo podrá seleccionar los días de la semana y el dia festivo | C5: No | D5: Alfanumérico | E5: Si | F5: 5 | G5: 9 | M5: Solo puede tomar uno de los valores: Lunes, Martes, Miércoles, Jueves, Viernes, Sábado, Domingo o Festivo | N5: No | O5: No | Q5: No | R5: No | S5: No | U5: No
A6: ='M-HorarioBarberia'!D3 -> horaApertura | B6: ='M-HorarioBarberia'!D2 -> Representa la hora a la que abre la barbería | C6: No | D6: Hora | E6: No | L6: hh:mm | N6: No | O6: No | Q6: No | R6: No | S6: No | T6: 00:00 | U6: No
A7: ='M-HorarioBarberia'!E3 -> horaCierre | B7: ='M-HorarioBarberia'!E2 -> Representa la hora a la que cierra la barbería | C7: No | D7: Hora | E7: Si | L7: hh:mm | M7: Debe ser mayor a horaApertura | N7: No | O7: No | Q7: No | R7: No | S7: No | T7: 00:00 | U7: No
A9: Nombre combinación única | B9: Descripción | C9: Atributos involucrados
A10: ='M-HorarioBarberia'!F3 -> Combinación única | B10: ='M-HorarioBarberia'!F2 -> Combinacion única que indica que no puede existir más de un horario con la misma barberia, dia de la semana, hora de apertura y cierre | C10: =A5 -> diaDeLaSemana
C11: =A6 -> horaApertura
C12: =A7 -> horaCierre

Sheet M-HorarioBarberia
A1: <<<< Ir al modulo de dominio | B1: <<<< Ir a objetos de dominio
A2: Representa un identificador que hará unico cada objeto de dominio de este tipo, no se puede repetir | B2: Representa que el dueño tomo la decisión de agregar un horario para la barberia | C2: Representa el día de la semana en que aplica este horario, el dueño solo podrá seleccionar los días de la semana y el dia festivo | D2: Representa la hora a la que abre la barbería | E2: Representa la hora a la que cierra la barbería | F2: Combinacion única que indica que no puede existir más de un horario con la misma barberia, dia de la semana, hora de apertura y cierre
A3: id | B3: dueño | C3: diaDeLaSemana | D3: horaApertura | E3: horaCierre | F3: Combinación única
A4: 1 | B4: ='M-Dueño'!D4 -> Carlos | C4: Lunes | D4: 0.375 | E4: 0.79166667 | F4: =_xlfn.CONCAT(C4,"-",TEXT(D4,"hh:mm"),"-",TEXT(E4,"hh:mm")) -> Lunes-09:00-19:00
A5: 2 | B5: ='M-Dueño'!D4 -> Carlos | C5: Martes | D5: 0.375 | E5: 0.79166667 | F5: =_xlfn.CONCAT(C5,"-",TEXT(D5,"hh:mm"),"-",TEXT(E5,"hh:mm")) -> Martes-09:00-19:00
A6: 3 | B6: ='M-Dueño'!D4 -> Carlos | C6: Miércoles | D6: 0.375 | E6: 0.79166667 | F6: =_xlfn.CONCAT(C6,"-",TEXT(D6,"hh:mm"),"-",TEXT(E6,"hh:mm")) -> Miércoles-09:00-19:00
A7: 4 | B7: ='M-Dueño'!D4 -> Carlos | C7: Jueves | D7: 0.375 | E7: 0.79166667 | F7: =_xlfn.CONCAT(C7,"-",TEXT(D7,"hh:mm"),"-",TEXT(E7,"hh:mm")) -> Jueves-09:00-19:00
A8: 5 | B8: ='M-Dueño'!D4 -> Carlos | C8: Viernes | D8: 0.375 | E8: 0.79166667 | F8: =_xlfn.CONCAT(C8,"-",TEXT(D8,"hh:mm"),"-",TEXT(E8,"hh:mm")) -> Viernes-09:00-19:00
A9: 6 | B9: ='M-Dueño'!D4 -> Carlos | C9: Sábado | D9: 0.33333333 | E9: 0.875 | F9: =_xlfn.CONCAT(C9,"-",TEXT(D9,"hh:mm"),"-",TEXT(E9,"hh:mm")) -> Sábado-08:00-21:00
A10: 7 | B10: ='M-Dueño'!D4 -> Carlos | C10: Festivo | D10: 0.41666667 | E10: 0.625 | F10: =_xlfn.CONCAT(C10,"-",TEXT(D10,"hh:mm"),"-",TEXT(E10,"hh:mm")) -> Festivo-10:00-15:00
B16: Corresponde a la descripcion de los atributos
B17: Corresponde al identificador unico del objeto de dominio
B18: Corresponde a referencias de objetos de dominio
B19: Corresponde a los datos de tipo alfanumerico
B20: Corresponde a los datos de tipo hora
B21: Corresponde a la combinacion única

Sheet C-Regla
A1: <<<< Ir al modulo de dominio | B1: <<<< Ir a objetos de dominio
A2: Nombre atributo | B2: Descripción atributo | C2: Identificador del objeto de dominio | D2: Tipo de dato | E2: Obligatorio | F2: Longitud mínima (si aplica) | G2: Longitud máxima (si aplica) | H2: Precisión (si aplica) | I2: Rendondeo (si aplica) | J2: Rango inicial (si aplica) | K2: Rango final (si aplica) | L2: Formato (si aplica) | M2: Reglas especiales (si aplica) | N2: Dato calculado | O2: Aplica ajuste del dato (si aplica) | P2: Carácter de ajuste (si aplica) | Q2: Quitar espacios en blanco al inicio (si aplica) | R2: Quitar espacios en blanco al fin (si aplica) | S2: Dato sensible (si aplica) | T2: Valor por defecto (si aplica) | U2: Auto generado
A3: ='M-Regla'!A3 -> id | B3: ='M-Regla'!A2 -> Representa un identificador que hará unico cada objeto de dominio de este tipo, no se puede repetir | C3: Si | D3: Identificador único universal | E3: Si | N3: No | O3: No | Q3: No | R3: No | S3: No | U3: Si
A4: ='M-Regla'!B3 -> dueño | B4: ='M-Regla'!B2 -> Representa el objeto de dominio del dueño de la barberia, quien es el que crea regla | C4: No | D4: Dueño | E4: Si | M4: Aplican las reglas del objeto referenciado. | N4: No | O4: No | Q4: No | R4: No | S4: No | U4: No
A5: ='M-Regla'!C3 -> toleranciaTardanzaCliente | B5: ='M-Regla'!C2 -> Representa la cantidad de minutos que el cliente puede llegarle tarde un cliente a la cita establecida con el barbero, despues de eso el barbero lo podrá multar | C5: No | D5: Entero | E5: No | J5: 0 | N5: No | O5: No | Q5: No | R5: No | T5: 0 | U5: No
A6: ='M-Regla'!D3 -> montoMultaTardanzaCliente | B6: ='M-Regla'!D2 -> Representa la cantidad de dinero que el cliente debe de pagar en pesos colombianos, por superar la toleranciaTardanza. Debe de ser mayor a cero, su valor por defecto es 0 y no es permitido | C6: No | D6: Entero | E6: No | J6: 0 | L6: Se usa el formato de moneda Europea | N6: No | O6: No | Q6: No | R6: No | T6: 0 | U6: No
A7: ='M-Regla'!E3 -> numeroMultasMaxima | B7: ='M-Regla'!E2 -> Representa la maxima de multas que pueda tener un cliente sin pagar, a partir de esta cantidad se le hace un veto al cliente. Debe de ser mayor o igual a cero, su valor por defecto es 0 y es no es permitido | C7: No | D7: Entero | E7: No | J7: 0 | N7: No | O7: No | Q7: No | R7: No | T7: 0 | U7: No
A8: ='M-Regla'!F3 -> toleranciaTardanzaBarbero | B8: ='M-Regla'!F2 -> Representa la cantidad de minutos que un barbero puede demorarse en atender a un cliente, en caso de que el barbero se demore mas de lo previsto en su cita anterior | C8: No | D8: Entero | E8: No | J8: 0 | N8: No | O8: No | Q8: No | R8: No | T8: 0 | U8: No
A9: ='M-Regla'!G3 -> porcentajeDescuentoCita | B9: ='M-Regla'!G2 -> Representa la cantidad cuanto descuento va a tener un cliente en la cita con el barbero, como recompesa por esperar al barbero mas de la tolerancia permitida | C9: No | D9: Entero | E9: No | J9: 0 | K9: 100 | L9: Porcentaje entero de 0 a 100 | N9: No | O9: No | Q9: No | R9: No | T9: 0 | U9: No

Sheet M-Regla
A1: <<<< Ir al modulo de dominio | B1: <<<< Ir a objetos de dominio
A2: Representa un identificador que hará unico cada objeto de dominio de este tipo, no se puede repetir | B2: Representa el objeto de dominio del dueño de la barberia, quien es el que crea regla | C2: Representa la cantidad de minutos que el cliente puede llegarle tarde un cliente a la cita establecida con el barbero, despues de eso el barbero lo podrá multar | D2: Representa la cantidad de dinero que el cliente debe de pagar en pesos colombianos, por superar la toleranciaTardanza. Debe de ser mayor a cero, su valor por defecto es 0 y no es permitido | E2: Representa la maxima de multas que pueda tener un cliente sin pagar, a partir de esta cantidad se le hace un veto al cliente. Debe de ser mayor o igual a cero, su valor por defecto es 0 y es no es permitido | F2: Representa la cantidad de minutos que un barbero puede demorarse en atender a un cliente, en caso de que el barbero se demore mas de lo previsto en su cita anterior | G2: Representa la cantidad cuanto descuento va a tener un cliente en la cita con el barbero, como recompesa por esperar al barbero mas de la tolerancia permitida
A3: id | B3: dueño | C3: toleranciaTardanzaCliente | D3: montoMultaTardanzaCliente | E3: numeroMultasMaxima | F3: toleranciaTardanzaBarbero | G3: porcentajeDescuentoCita
A4: 1 | B4: ='M-Dueño'!D4 -> Carlos | C4: 10 | D4: 10000 | E4: 3 | F4: 15 | G4: 10
B9: Corresponde a la descripcion de los atributos
B10: Corresponde al identificador unico del objeto de dominio
B11: Corresponde a referencias de objetos de dominio
B12: Corresponde a los datos de tipo entero

Sheet C-Servicio
A1: <<<< Ir al modulo de dominio | B1: <<<< Ir a objetos de dominio
A2: Nombre atributo | B2: Descripción atributo | C2: Identificador del objeto de dominio | D2: Tipo de dato | E2: Obligatorio | F2: Longitud mínima (si aplica) | G2: Longitud máxima (si aplica) | H2: Precisión (si aplica) | I2: Rendondeo (si aplica) | J2: Rango inicial (si aplica) | K2: Rango final (si aplica) | L2: Formato (si aplica) | M2: Reglas especiales (si aplica) | N2: Dato calculado | O2: Aplica ajuste del dato (si aplica) | P2: Carácter de ajuste (si aplica) | Q2: Quitar espacios en blanco al inicio (si aplica) | R2: Quitar espacios en blanco al fin (si aplica) | S2: Dato sensible (si aplica) | T2: Valor por defecto (si aplica) | U2: Auto generado
A3: ='M-Servicio'!A3 -> id | B3: ='M-Servicio'!A2 -> Representa un identificador que hará unico cada objeto de dominio de este tipo, no se puede repetir | C3: Si | D3: Identificador único universal | E3: Si | N3: No | O3: No | Q3: No | R3: No | S3: No | U3: Si
A4: ='M-Servicio'!B3 -> dueño | B4: ='M-Servicio'!B2 -> Representa que el dueño tomo la decisión de agregar un servicio para la barberia | C4: No | D4: Dueño | E4: Si | M4: Aplican las reglas del objeto referenciado. | N4: No | O4: No | Q4: No | R4: No | S4: No | U4: No
A5: ='M-Servicio'!C3 -> nombre | B5: ='M-Servicio'!C2 -> Representa el nombre del servicio que va estar en la barberia, que el barbero ofrece y en las citas que esta. Su valor por defecto es el vacio y no es permitido | C5: No | D5: Alfanumérico | E5: Si | F5: 3 | G5: 50 | N5: No | O5: No | Q5: Si | R5: Si | S5: No | U5: No
A6: ='M-Servicio'!D3 -> descripcion | B6: ='M-Servicio'!D2 -> Representa como el dueño describe que va a hacer cada servicio, para que el barbero sepa que hace el servicio | C6: No | D6: Alfanumérico | E6: No | F6: 10 | G6: 100 | N6: No | O6: No | Q6: Si | R6: Si | S6: No | U6: No
A7: ='M-Servicio'!E3 -> precio | B7: ='M-Servicio'!E2 -> Representa cuanto va a valer el servicio en pesos colombianos. Debe de ser mayor a cero, su valor por defecto es 0 y no esta permitido | C7: No | D7: Entero | E7: Si | J7: 0 | L7: Formato de modena Europea | N7: No | S7: No | U7: No
A8: ='M-Servicio'!F3 -> disponible | B8: ='M-Servicio'!F2 -> Representa si el servicio sigue o no disponible en la barberia | C8: No | D8: Lógico | E8: No | N8: No | S8: No | T8: Si | U8: No
A10: Nombre combinación única | B10: Descripción | C10: Atributos involucrados
A11: ='M-Servicio'!G3 -> Combinacion única | B11: ='M-Servicio'!G2 -> Combinacion única que indica que no puede existir más de un servicio con el mismo nombre | C11: =A5 -> nombre

Sheet M-Servicio
A1: <<<< Ir al modulo de dominio | B1: <<<< Ir a objetos de dominio
A2: Representa un identificador que hará unico cada objeto de dominio de este tipo, no se puede repetir | B2: Representa que el dueño tomo la decisión de agregar un servicio para la barberia | C2: Representa el nombre del servicio que va estar en la barberia, que el barbero ofrece y en las citas que esta. Su valor por defecto es el vacio y no es permitido | D2: Representa como el dueño describe que va a hacer cada servicio, para que el barbero sepa que hace el servicio | E2: Representa cuanto va a valer el servicio en pesos colombianos. Debe de ser mayor a cero, su valor por defecto es 0 y no esta permitido | F2: Representa si el servicio sigue o no disponible en la barberia | G2: Combinacion única que indica que no puede existir más de un servicio con el mismo nombre
A3: id | B3: dueño | C3: nombre | D3: descripcion | E3: precio | F3: disponible | G3: Combinacion única
A4: 1 | B4: ='M-Dueño'!D4 -> Carlos | C4: Motilada | D4: Corte de cabello completo con máquina y tijera, incluye lavado y secado | E4: 22000 | F4: si | G4: =C4 -> Motilada
A5: 2 | B5: ='M-Dueño'!D4 -> Carlos | C5: Corte de barba | D5: Recorte de la barba con máquina para dejarla pareja y a la medida que pide el cliente | E5: 12000 | F5: si | G5: =C5 -> Corte de barba
A6: 3 | B6: ='M-Dueño'!D4 -> Carlos | C6: Perfilada de barba | D6: Delineado de los bordes de la barba y el bigote con navaja, sin recortar el largo | E6: 15000 | F6: si | G6: =C6 -> Perfilada de barba
A7: 4 | B7: ='M-Dueño'!D4 -> Carlos | C7: Arreglo completo de barba con toalla caliente | D7: Recorte, perfilado con navaja, toalla caliente, exfoliación y aceite para la barba | E7: 35000 | F7: si | G7: =C7 -> Arreglo completo de barba con toalla caliente
B13: Corresponde a la descripcion de los atributos
B14: Corresponde al identificador unico del objeto de dominio
B15: Corresponde a los datos de referencia de otros objetos de dominio
B16: Corresponde a los datos de tipo alfanumerico
B17: Corresponde a los datos de tipo entero
B18: Corresponde a los datos de tipo logico
B19: Corresponde a la combinacion única

Sheet C-BarberoServicio
A1: <<<< Ir al modulo de dominio | B1: <<<< Ir a objetos de dominio
A2: Nombre atributo | B2: Descripción atributo | C2: Identificador del objeto de dominio | D2: Tipo de dato | E2: Obligatorio | F2: Longitud mínima (si aplica) | G2: Longitud máxima (si aplica) | H2: Precisión (si aplica) | I2: Rendondeo (si aplica) | J2: Rango inicial (si aplica) | K2: Rango final (si aplica) | L2: Formato (si aplica) | M2: Reglas especiales (si aplica) | N2: Dato calculado | O2: Aplica ajuste del dato (si aplica) | P2: Carácter de ajuste (si aplica) | Q2: Quitar espacios en blanco al inicio (si aplica) | R2: Quitar espacios en blanco al fin (si aplica) | S2: Dato sensible (si aplica) | T2: Valor por defecto (si aplica) | U2: Auto generado
A3: ='M-BarberoServicio'!A3 -> id | B3: ='M-BarberoServicio'!A2 -> Representa un identificador que hará unico cada objeto de dominio de este tipo, no se puede repetir | C3: Si | D3: Identificador único universal | E3: Si | N3: No | O3: No | Q3: No | R3: No | S3: No | U3: Si
A4: ='M-BarberoServicio'!B3 -> barbero | B4: ='M-BarberoServicio'!B2 -> Representa el nombre y apellidos del barbero | C4: No | D4: Barbero | E4: Si | M4: Aplican las reglas del objeto referenciado. | N4: No | O4: No | Q4: No | R4: No | S4: No | U4: No
A5: ='M-BarberoServicio'!C3 -> servicio | B5: ='M-BarberoServicio'!C2 -> Representa el nombre del servicio de la barberia | C5: No | D5: Servicio | E5: Si | M5: Aplican las reglas del objeto referenciado. | N5: No | O5: No | Q5: No | R5: No | S5: No | U5: No
A6: ='M-BarberoServicio'!D3 -> duracionServicio | B6: ='M-BarberoServicio'!D2 -> Representa la cantidad de minutos que un barbero tarda en realizar un servicio, esta duracion el barbero debe de ser consiente de cuanto se demora en realizarlo | C6: No | D6: Entero | E6: Si | J6: 1 | L6: Minutos. | M6: El barbero debe ser consciente de cuánto se demora realmente en este servicio. | N6: No | O6: No | S6: No | T6: 0 | U6: No
A7: ='M-BarberoServicio'!E3 -> tiempoExtra | B7: ='M-BarberoServicio'!E2 -> Representa la cantidad de minutos que un barbero pone de tiempo extra en las citas de su agenda, cada barbero usa este tiempo porque hay ocaciones que la cita se puede demorar más de lo previsto. Este tiempo les ayuda a evitar que se les retrase la agenda | C7: No | D7: Entero | E7: No | J7: 0 | L7: Minutos. | N7: No | O7: No | S7: No | T7: 0 | U7: No
A9: Nombre combinación única | B9: Descripción | C9: Atributos involucrados
A10: ='M-BarberoServicio'!F3 -> Combinación única | B10: ='M-BarberoServicio'!F2 -> Combinación única que indica que un mismo barbero no puede aparecer dos veces ofreciendo el mismo servicio | C10: =A4 -> barbero
C11: =A5 -> servicio

Sheet M-BarberoServicio
A1: <<<< Ir al modulo de dominio | B1: <<<< Ir a objetos de dominio
A2: Representa un identificador que hará unico cada objeto de dominio de este tipo, no se puede repetir | B2: Representa el nombre y apellidos del barbero | C2: Representa el nombre del servicio de la barberia | D2: Representa la cantidad de minutos que un barbero tarda en realizar un servicio, esta duracion el barbero debe de ser consiente de cuanto se demora en realizarlo | E2: Representa la cantidad de minutos que un barbero pone de tiempo extra en las citas de su agenda, cada barbero usa este tiempo porque hay ocaciones que la cita se puede demorar más de lo previsto. Este tiempo les ayuda a evitar que se les retrase la agenda | F2: Combinación única que indica que un mismo barbero no puede aparecer dos veces ofreciendo el mismo servicio
A3: id | B3: barbero | C3: servicio | D3: duracionServicio | E3: tiempoExtra | F3: Combinación única
A4: 1 | B4: =_xlfn.CONCAT('M-Barbero'!B4," ",'M-Barbero'!D4) -> Juan García | C4: ='M-Servicio'!C4 -> Motilada | D4: 45 | E4: 15 | F4: =_xlfn.CONCAT(B4,"-",C4) -> Juan García-Motilada
A5: 2 | B5: =_xlfn.CONCAT('M-Barbero'!B5," ",'M-Barbero'!D5) -> Juan Ortiz | C5: ='M-Servicio'!C5 -> Corte de barba | D5: 10 | E5: 5 | F5: =_xlfn.CONCAT(B5,"-",C5) -> Juan Ortiz-Corte de barba
A6: 3 | B6: =_xlfn.CONCAT('M-Barbero'!B6," ",'M-Barbero'!D6) -> Carlos Arbeladez | C6: ='M-Servicio'!C6 -> Perfilada de barba | D6: 15 | E6: 5 | F6: =_xlfn.CONCAT(B6,"-",C6) -> Carlos Arbeladez-Perfilada de barba
A7: 4 | B7: =_xlfn.CONCAT('M-Barbero'!B7," ",'M-Barbero'!D7) -> Andres Ramirez | C7: ='M-Servicio'!C7 -> Arreglo completo de barba con toalla caliente | D7: 40 | E7: 10 | F7: =_xlfn.CONCAT(B7,"-",C7) -> Andres Ramirez-Arreglo completo de barba con toalla caliente
A8: 5 | B8: =_xlfn.CONCAT('M-Barbero'!B5," ",'M-Barbero'!D5) -> Juan Ortiz | C8: ='M-Servicio'!C4 -> Motilada | D8: 40 | E8: 10 | F8: =_xlfn.CONCAT(B8,"-",C8) -> Juan Ortiz-Motilada
A9: 6 | B9: =_xlfn.CONCAT('M-Barbero'!B6," ",'M-Barbero'!D6) -> Carlos Arbeladez | C9: ='M-Servicio'!C5 -> Corte de barba | D9: 15 | E9: 5 | F9: =_xlfn.CONCAT(B9,"-",C9) -> Carlos Arbeladez-Corte de barba
A10: 7 | B10: =_xlfn.CONCAT('M-Barbero'!B4," ",'M-Barbero'!D4) -> Juan García | C10: ='M-Servicio'!C6 -> Perfilada de barba | D10: 20 | E10: 5 | F10: =_xlfn.CONCAT(B10,"-",C10) -> Juan García-Perfilada de barba
A11: 8 | B11: =_xlfn.CONCAT('M-Barbero'!B7," ",'M-Barbero'!D7) -> Andres Ramirez | C11: ='M-Servicio'!C4 -> Motilada | D11: 50 | E11: 15 | F11: =_xlfn.CONCAT(B11,"-",C11) -> Andres Ramirez-Motilada
A12: 9 | B12: =_xlfn.CONCAT('M-Barbero'!B8," ",'M-Barbero'!D8) -> Juan Zambrano | C12: ='M-Servicio'!C5 -> Corte de barba | D12: 12 | E12: 5 | F12: =_xlfn.CONCAT(B12,"-",C12) -> Juan Zambrano-Corte de barba
B18: Corresponde a la descripcion de los atributos
B19: Corresponde al identificador unico del objeto de dominio
B20: Corresponde a los datos de referencia de otros objetos de dominio
B21: Corresponde a los datos de tipo entero
B22: Corresponde a la combinacion única

Sheet C-HorarioBarbero
A1: <<<< Ir al modulo de dominio | B1: <<<< Ir a objetos de dominio
A2: Nombre atributo | B2: Descripción atributo | C2: Identificador del objeto de dominio | D2: Tipo de dato | E2: Obligatorio | F2: Longitud mínima (si aplica) | G2: Longitud máxima (si aplica) | H2: Precisión (si aplica) | I2: Rendondeo (si aplica) | J2: Rango inicial (si aplica) | K2: Rango final (si aplica) | L2: Formato (si aplica) | M2: Reglas especiales (si aplica) | N2: Dato calculado | O2: Aplica ajuste del dato (si aplica) | P2: Carácter de ajuste (si aplica) | Q2: Quitar espacios en blanco al inicio (si aplica) | R2: Quitar espacios en blanco al fin (si aplica) | S2: Dato sensible (si aplica) | T2: Valor por defecto (si aplica) | U2: Auto generado
A3: ='M-HorarioBarbero'!A3 -> id | B3: ='M-HorarioBarbero'!A2 -> Representa un identificador que hará unico cada objeto de dominio de este tipo, no se puede repetir | C3: Si | D3: Identificador único universal | E3: Si | N3: No | O3: No | Q3: No | R3: No | S3: No | U3: Si
A4: ='M-HorarioBarbero'!B3 -> barbero | B4: ='M-HorarioBarbero'!B2 -> Referencia a que barbero va a ser dueño de esta agenda | C4: No | D4: Barbero | E4: Si | M4: Aplican las reglas del objeto referenciado. | N4: No | O4: No | Q4: No | R4: No | S4: No | U4: No
A5: agenda | B5: ='M-HorarioBarbero'!C2 -> Hace referencia a la agenda del barbero en la que queda guardado este horario de trabajo | C5: No | D5: Agenda | E5: Si | N5: No | U5: No
A6: ='M-HorarioBarbero'!D3 -> diaDeLaSemana | B6: ='M-HorarioBarbero'!D2 -> Representa el día de la semana en que aplica este horario que para la agenda del barbero, es necesario porque un barbero puede trabajar unos días sí y otros no. Su valor por defecto es el vacío y no es permitido, el barbero solo podra seleccionar los días de la semana que la barberia tiene en su horario | C6: No | D6: Alfanumérico | E6: Si | F6: 5 | G6: 9 | M6: Solo puede tomar uno de los días que la barbería tenga habilitados en HorarioBarberia. | N6: No | O6: No | Q6: No | R6: No | S6: No | U6: No
A7: ='M-HorarioBarbero'!E3 -> horaInicio | B7: ='M-HorarioBarbero'!E2 -> Representa la hora en la que el barbero empieza a estar disponible ese dia. Su valor por defecto es 00:00 y es permitido. La hora debe de estar dentro del horario barberia | C7: No | D7: Hora | E7: No | L7: hh:mm | M7: Debe estar dentro del horario de la barbería para ese día. | N7: No | O7: No | S7: No | T7: 00:00 | U7: No
A8: ='M-HorarioBarbero'!F3 -> horaFinal | B8: ='M-HorarioBarbero'!F2 -> Representa la hora en la que el barbero deja de estar disponible ese día, junto con horaInicio, es lo que la aplicación usa para saber si hay campo para agendar una cita nueva. Su valor por defecto es 00:00 y no es permitido. Esta hora debe de ser mayor a horaInicio y también debe de estar dentro de horario barberia | C8: No | D8: Hora | E8: Si | L8: hh:mm | M8: Debe ser mayor a horaInicio y debe estar dentro del horario de la barbería para ese día. | N8: No | O8: No | S8: No | T8: 0 | U8: No
A9: ='M-HorarioBarbero'!G3 -> fechaCreacion | B9: ='M-HorarioBarbero'!G2 -> Representa la fecha en el que el barbero creo esta agenda. Es un dato calculado que toma la fecha de hoy cuando el barbero crea la agenda | C9: No | D9: Fecha | E9: Si | L9: dd/mm/aaaa | M9: El sistema toma la fecha de hoy en el momento en que el barbero crea la agenda. | N9: Si | O9: No | S9: No | U9: No
A10: ='M-HorarioBarbero'!H3 -> fechaDesactivacion | B10: ='M-HorarioBarbero'!H2 -> Representa la fecha en el que el barbero decidio que ya no va a trabaja más en este horario. Es un dato calculo que toma la fecha de hoy cuando el barbero dice que ya no es vigente | C10: No | D10: Fecha | E10: No | L10: dd/mm/aaaa | M10: Mientras el registro esté vigente usa el valor centinela 01/01/1000; al desactivarse, el sistema toma la fecha de hoy y ya no se puede volver a modificar. | N10: Si | O10: No | S10: No | T10: 01/01/1000 | U10: No
A11: ='M-HorarioBarbero'!I3 -> vigente | B11: ='M-HorarioBarbero'!I2 -> Representa si este horario lo sigue o no usando el barbero. Una vez que el barbero cambie este estado a no vigente, no se puede volver a cambiar | C11: No | D11: Lógico | E11: No | M11: Una vez cambiado a no, el estado no se puede volver a modificar. | N11: No | O11: No | S11: No | T11: Si | U11: No
A13: Nombre combinación única | B13: Descripción | C13: Atributos involucrados
A14: ='M-HorarioBarbero'!M3 -> Combinación única | B14: ='M-HorarioBarbero'!M2 -> Combinación única que indica que un barbero no puede tener más de una agenda, cada barbero organiza todo su tiempo en un único lugar | C14: =A4 -> barbero
C15: =A6 -> diaDeLaSemana
C16: =A7 -> horaInicio
C17: =A8 -> horaFinal
C18: =A9 -> fechaCreacion
C19: =A10 -> fechaDesactivacion

Sheet M-HorarioBarbero
A1: <<<< Ir al modulo de dominio | B1: <<<< Ir a objetos de dominio
A2: Representa un identificador que hará unico cada objeto de dominio de este tipo, no se puede repetir | B2: Referencia a que barbero va a ser dueño de esta agenda | C2: Hace referencia a la agenda del barbero en la que queda guardado este horario de trabajo | D2: Representa el día de la semana en que aplica este horario que para la agenda del barbero, es necesario porque un barbero puede trabajar unos días sí y otros no. Su valor por defecto es el vacío y no es permitido, el barbero solo podra seleccionar los días de la semana que la barberia tiene en su horario | E2: Representa la hora en la que el barbero empieza a estar disponible ese dia. Su valor por defecto es 00:00 y es permitido. La hora debe de estar dentro del horario barberia | F2: Representa la hora en la que el barbero deja de estar disponible ese día, junto con horaInicio, es lo que la aplicación usa para saber si hay campo para agendar una cita nueva. Su valor por defecto es 00:00 y no es permitido. Esta hora debe de ser mayor a horaInicio y también debe de estar dentro de horario barberia | G2: Representa la fecha en el que el barbero creo esta agenda. Es un dato calculado que toma la fecha de hoy cuando el barbero crea la agenda | H2: Representa la fecha en el que el barbero decidio que ya no va a trabaja más en este horario. Es un dato calculo que toma la fecha de hoy cuando el barbero dice que ya no es vigente | I2: Representa si este horario lo sigue o no usando el barbero. Una vez que el barbero cambie este estado a no vigente, no se puede volver a cambiar | J2: Representa la hora en el que el barbero definió su hora de inicio para el descanso | K2: Representa la hora en que se acaba el descanso para el barbero | L2: Representa si el barbero tiene o no descanso en su horario de trabajo | M2: Combinación única que indica que un barbero no puede tener más de una agenda, cada barbero organiza todo su tiempo en un único lugar
A3: id | B3: barbero | C3: agenda | D3: diaDeLaSemana | E3: horaInicio | F3: horaFinal | G3: fechaCreacion | H3: fechaDesactivacion | I3: vigente | J3: inicioDescanso | K3: finDescanso | L3: tieneDescanso | M3: Combinación única
A4: 1 | B4: ='M-Barbero'!K4 -> Juan-Fernando-García-Lopez-+57-3245627890 | C4: ='M-Agenda'!C4 -> Agenda de Juan García | D4: Lunes | E4: 0.41666667 | F4: 0.66666667 | G4: 45780 | H4: 1/01/1000 | I4: si | J4: 0 | K4: 0 | L4: No | M4: =_xlfn.CONCAT(B4,"-",D4,"-",TEXT(E4,"hh:mm"),"-",TEXT(F4,"hh:mm"),"-",TEXT(G4,"dd/mm/yyyy"),"-",TEXT(H4,"dd/mm/yyyy")) -> Juan-Fernando-García-Lopez-+57-3245627890-Lunes-10:00-16:00-03/05/2025-1/01/1000
A5: 2 | B5: ='M-Barbero'!K5 -> Juan-David-Ortiz-Sanchez-+57-3124518923 | C5: ='M-Agenda'!C5 -> Agenda de Juan Ortiz | D5: Martes | E5: 0.375 | F5: 0.625 | G5: 45718 | H5: 1/01/1000 | I5: si | J5: 0.54166667 | K5: 0.58333333 | L5: Si | M5: =_xlfn.CONCAT(B5,"-",D5,"-",TEXT(E5,"hh:mm"),"-",TEXT(F5,"hh:mm"),"-",TEXT(G5,"dd/mm/yyyy"),"-",TEXT(H5,"dd/mm/yyyy")) -> Juan-David-Ortiz-Sanchez-+57-3124518923-Martes-09:00-15:00-02/03/2025-1/01/1000
A6: 3 | B6: ='M-Barbero'!K6 -> Carlos--Arbeladez--+57-3214533321 | C6: ='M-Agenda'!C6 -> Agenda de Carlos Arbeladez | D6: Jueves | E6: 0.54166667 | F6: 0.79166667 | G6: 44917 | H6: 1/01/1000 | I6: si | J6: 0.58333333 | K6: 0.60416667 | L6: Si | M6: =_xlfn.CONCAT(B6,"-",D6,"-",TEXT(E6,"hh:mm"),"-",TEXT(F6,"hh:mm"),"-",TEXT(G6,"dd/mm/yyyy"),"-",TEXT(H6,"dd/mm/yyyy")) -> Carlos--Arbeladez--+57-3214533321-Jueves-13:00-19:00-22/12/2022-1/01/1000
A7: 4 | B7: ='M-Barbero'!K7 -> Andres--Ramirez-Patiño-+91-9876543210 | C7: ='M-Agenda'!C7 -> Agenda de Andres Ramirez | D7: Sábado | E7: 0.33333333 | F7: 0.58333333 | G7: 45915 | H7: 46023 | I7: no | J7: 0.5 | K7: 0.5625 | L7: No | M7: =_xlfn.CONCAT(B7,"-",D7,"-",TEXT(E7,"hh:mm"),"-",TEXT(F7,"hh:mm"),"-",TEXT(G7,"dd/mm/yyyy"),"-",TEXT(H7,"dd/mm/yyyy")) -> Andres--Ramirez-Patiño-+91-9876543210-Sábado-08:00-14:00-15/09/2025-01/01/2026
A8: 5 | B8: ='M-Barbero'!K7 -> Andres--Ramirez-Patiño-+91-9876543210 | C8: ='M-Agenda'!C7 -> Agenda de Andres Ramirez | D8: Festivo | E8: 0.5 | F8: 0.625 | G8: 46054 | H8: 46083 | I8: no | J8: 0 | K8: 0 | L8: No | M8: =_xlfn.CONCAT(B8,"-",D8,"-",TEXT(E8,"hh:mm"),"-",TEXT(F8,"hh:mm"),"-",TEXT(G8,"dd/mm/yyyy"),"-",TEXT(H8,"dd/mm/yyyy")) -> Andres--Ramirez-Patiño-+91-9876543210-Festivo-12:00-15:00-01/02/2026-02/03/2026
B14: Corresponde a la descripcion de los atributos
B15: Corresponde al identificador unico del objeto de dominio
B16: Corresponde a referencias de objetos de dominio
B17: Corresponde a los datos de tipo alfanumerico
B18: Corresponde a los datos de tipo hora
B19: Corresponde a la combinacion única

Sheet C-Bloqueo
A1: <<<< Ir al modulo de dominio | B1: <<<< Ir a objetos de dominio
A2: Nombre atributo | B2: Descripción atributo | C2: Identificador del objeto de dominio | D2: Tipo de dato | E2: Obligatorio | F2: Longitud mínima (si aplica) | G2: Longitud máxima (si aplica) | H2: Precisión (si aplica) | I2: Rendondeo (si aplica) | J2: Rango inicial (si aplica) | K2: Rango final (si aplica) | L2: Formato (si aplica) | M2: Reglas especiales (si aplica) | N2: Dato calculado | O2: Aplica ajuste del dato (si aplica) | P2: Carácter de ajuste (si aplica) | Q2: Quitar espacios en blanco al inicio (si aplica) | R2: Quitar espacios en blanco al fin (si aplica) | S2: Dato sensible (si aplica) | T2: Valor por defecto (si aplica) | U2: Auto generado
A3: ='M-Bloqueo'!A3 -> id | B3: ='M-Bloqueo'!A2 -> Representa un identificador que hará unico cada objeto de dominio de este tipo, no se puede repetir | C3: Si | D3: Identificador único universal | E3: Si | N3: No | O3: No | Q3: No | R3: No | S3: No | U3: Si
A4: ='M-Bloqueo'!B3 -> agenda | B4: ='M-Bloqueo'!B2 -> Hace referencia a la agenda (y por lo tanto al barbero) a la que pertenece este bloqueo, permite saber en cual agenda se va agregar el bloqueo | C4: No | D4: Agenda | E4: Si | M4: Aplican las reglas del objeto referenciado. | N4: No | O4: No | S4: No | U4: No
A5: ='M-Bloqueo'!C3 -> fechaHoraInicio | B5: ='M-Bloqueo'!C2 -> Representa la fecha y la hora en el que va a empezar el bloqueo para la agenda del barbero. Su valor por defecto es 01/01/1000 00:00 y no es permitido. No se puden seleccionar fechas antes del momento de hoy, solo fechas futuras | C5: No | D5: Fecha Hora | E5: Si | L5: dd/mm/aaaa hh:mm | M5: No se pueden seleccionar fechas anteriores al momento actual, solo fechas futuras. | N5: No | O5: No | S5: No | U5: No
A6: ='M-Bloqueo'!D3 -> fechaHoraFinal | B6: ='M-Bloqueo'!D2 -> Representa la fecha y la hora en el que va a terminar el bloqueo para la agenda del barbero. Su valor por defecto es 01/01/1000 00:00 y no es permitido, la fecha debe de ser mayor a la fecha de inicio | C6: No | D6: Fecha Hora | E6: Si | L6: dd/mm/aaaa hh:mm | M6: Debe ser mayor a fechaHoraInicio. | N6: No | O6: No | S6: No | U6: No
A7: ='M-Bloqueo'!E3 -> nombre | B7: ='M-Bloqueo'!E2 -> Representa como el barbero va a llamar este bloqueo para su agenda. Su valor por defecto es el vacio y no es permitido | C7: No | D7: Alfanumérico | E7: Si | F7: 3 | G7: 100 | N7: No | O7: No | Q7: Si | R7: Si | S7: No | U7: No
A8: ='M-Bloqueo'!F3 -> duracion | B8: ='M-Bloqueo'!F2 -> Representa la cantidad de minutos dura el bloqueo de la agenda. Es un dato calculado a partir de la fechaHoraInicio y fechaHoraFinal | C8: No | D8: Entero | E8: Si | J8: 1 | L8: Minutos. | M8: Se calcula como fechaHoraFinal menos fechaHoraInicio. | N8: Si | O8: No | Q8: No | U8: No
A10: Nombre combinación única | B10: Descripción | C10: Atributos involucrados
A11: ='M-Bloqueo'!G3 -> Combinación única | B11: ='M-Bloqueo'!G2 -> Combinación única que indica que una misma agenda no puede tener dos bloqueos en una misma fecha, horaInicio y horaFinal | C11: =A4 -> agenda
C12: =A5 -> fechaHoraInicio
C13: =A6 -> fechaHoraFinal

Sheet M-Bloqueo
A1: <<<< Ir al modulo de dominio | B1: <<<< Ir a objetos de dominio
A2: Representa un identificador que hará unico cada objeto de dominio de este tipo, no se puede repetir | B2: Hace referencia a la agenda (y por lo tanto al barbero) a la que pertenece este bloqueo, permite saber en cual agenda se va agregar el bloqueo | C2: Representa la fecha y la hora en el que va a empezar el bloqueo para la agenda del barbero. Su valor por defecto es 01/01/1000 00:00 y no es permitido. No se puden seleccionar fechas antes del momento de hoy, solo fechas futuras | D2: Representa la fecha y la hora en el que va a terminar el bloqueo para la agenda del barbero. Su valor por defecto es 01/01/1000 00:00 y no es permitido, la fecha debe de ser mayor a la fecha de inicio | E2: Representa como el barbero va a llamar este bloqueo para su agenda. Su valor por defecto es el vacio y no es permitido | F2: Representa la cantidad de minutos dura el bloqueo de la agenda. Es un dato calculado a partir de la fechaHoraInicio y fechaHoraFinal | G2: Combinación única que indica que una misma agenda no puede tener dos bloqueos en una misma fecha, horaInicio y horaFinal
A3: id | B3: agenda | C3: fechaHoraInicio | D3: fechaHoraFinal | E3: nombre | F3: duracion | G3: Combinación única
A4: 1 | B4: ='M-Agenda'!C4 -> Agenda de Juan García | C4: 46272.417 | D4: 46272.5 | E4: Cita medica | F4: 120 | G4: =_xlfn.CONCAT(B4,"-",TEXT(C4,"dd/mm/yyyy hh:mm"),"-",TEXT(D4,"dd/mm/yyyy hh:mm")) -> Agenda de Juan García-07/09/2026 10:00-07/09/2026 12:00
A5: 2 | B5: ='M-Agenda'!C5 -> Agenda de Juan Ortiz | C5: 46273.396 | D5: 46273.458 | E5: Vueltas que voy a hacer | F5: 90 | G5: =_xlfn.CONCAT(B5,"-",TEXT(C5,"dd/mm/yyyy hh:mm"),"-",TEXT(D5,"dd/mm/yyyy hh:mm")) -> Agenda de Juan Ortiz-08/09/2026 09:30-08/09/2026 11:00
A6: 3 | B6: ='M-Agenda'!C6 -> Agenda de Carlos Arbeladez | C6: 46275.542 | D6: 46275.583 | E6: Incoveniente | F6: 60 | G6: =_xlfn.CONCAT(B6,"-",TEXT(C6,"dd/mm/yyyy hh:mm"),"-",TEXT(D6,"dd/mm/yyyy hh:mm")) -> Agenda de Carlos Arbeladez-10/09/2026 13:00-10/09/2026 14:00
A7: 4 | B7: ='M-Agenda'!C5 -> Agenda de Juan Ortiz | C7: 46301.542 | D7: 46301.625 | E7: Compromiso | F7: 120 | G7: =_xlfn.CONCAT(B7,"-",TEXT(C7,"dd/mm/yyyy hh:mm"),"-",TEXT(D7,"dd/mm/yyyy hh:mm")) -> Agenda de Juan Ortiz-06/10/2026 13:00-06/10/2026 15:00
B13: Corresponde a la descripcion de los atributos
B14: Corresponde al identificador unico del objeto de dominio
B15: Corresponde a referencias de objetos de dominio
B16: Corresponde a los datos de tipo alfanumerico
B17: Corresponde a los datos de tipo fecha y hora
B18: Corresponde a los datos calculados por el sistema
B19: Corresponde a la combinacion única

Sheet C-Cita
A1: <<<< Ir al modulo de dominio | B1: <<<< Ir a objetos de dominio
A2: Nombre atributo | B2: Descripción atributo | C2: Identificador del objeto de dominio | D2: Tipo de dato | E2: Obligatorio | F2: Longitud mínima (si aplica) | G2: Longitud máxima (si aplica) | H2: Precisión (si aplica) | I2: Rendondeo (si aplica) | J2: Rango inicial (si aplica) | K2: Rango final (si aplica) | L2: Formato (si aplica) | M2: Reglas especiales (si aplica) | N2: Dato calculado | O2: Aplica ajuste del dato (si aplica) | P2: Carácter de ajuste (si aplica) | Q2: Quitar espacios en blanco al inicio (si aplica) | R2: Quitar espacios en blanco al fin (si aplica) | S2: Dato sensible (si aplica) | T2: Valor por defecto (si aplica) | U2: Auto generado
A3: ='M-Cita'!A3 -> id | B3: ='M-Cita'!A2 -> Representa un identificador que hará unico cada objeto de dominio de este tipo, no se puede repetir | C3: Si | D3: Identificador único universal | E3: Si | N3: No | O3: No | Q3: No | R3: No | S3: No | U3: Si
A4: ='M-Cita'!B3 -> cliente | B4: ='M-Cita'!B2 -> Representa el nombre completo del cliente que va a estar en la cita, para que luego el barbero se acuerde a quien tiene que atender | C4: No | D4: Cliente | E4: Si | M4: Aplican las reglas del objeto referenciado. | N4: No | O4: No | S4: No | U4: No
A5: ='M-Cita'!C3 -> agenda | B5: ='M-Cita'!C2 -> Hace referencia a en la agenda de que barbero quedó registrada esta cita, es lo que permite validar que no se cruce con otra cita del mismo barbero | C5: No | D5: Agenda | E5: Si | M5: Aplican las reglas del objeto referenciado. | N5: No | O5: No | S5: No | U5: No
