Workbook

Sheet Modelo de Dominio
A1: Ir a objetos de dominio >>>>

Sheet Objetos de Dominio
A1: <<<< Ir al modulo de dominio
A2: Nombre | B2: Descripcion | C2: Linea de vida | D2: Muestreo | E2: Caracterización | F2: Event Storming | G2: Politicas
A3: Barberia | B3: Representa la cadena o marca comercial de barbería, dueña de una o varias sedes. | C3: 1 | D3: Ir al muestreo | E3: Ir a la caracterización | F3: Ir al Event Storming | G3: Ir a las políticas
A4: DiaSemana | B4: Representa cada uno de los días de la semana, incluyendo festivo, que se usa como catálogo para definir los horarios de la barbería y de cada barbero. | C4: 1 | D4: Ir al muestreo | E4: Ir a la caracterización | F4: Ir al Event Storming | G4: Ir a las políticas
A5: Departamento | B5: Representa cada uno de los departamentos del país en los que se encuentran las ciudades donde la barbería puede tener sedes. | C5: 1 | D5: Ir al muestreo | E5: Ir a la caracterización | F5: Ir al Event Storming | G5: Ir a las políticas
A6: Estado | B6: Representa en qué situación puntual se encuentra una cita: agendada, finalizada, cancelada por alguna de las partes, con tardanza del cliente o del barbero, o con inasistencia del cliente. | C6: 1 | D6: Ir al muestreo | E6: Ir a la caracterización | F6: Ir al Event Storming | G6: Ir a las políticas
A7: PrefijoCelular | B7: Representa el catálogo de prefijos telefónicos de país que el administrador habilita, y que son los únicos que barberos y clientes pueden usar en su número de celular. | C7: 1 | D7: Ir al muestreo | E7: Ir a la caracterización | F7: Ir al Event Storming | G7: Ir a las políticas
A8: TipoMulta | B8: Representa los tipos de multa que puede recibir un cliente: por tardanza o por inasistencia. | C8: 1 | D8: Ir al muestreo | E8: Ir a la caracterización | F8: Ir al Event Storming | G8: Ir a las políticas
A9: TipoRegistroHora | B9: Representa el catálogo de los distintos momentos en que se puede registrar una hora real durante una cita: llegada del cliente, barbero preparado, inicio y fin de la atención. | C9: 1 | D9: Ir al muestreo | E9: Ir a la caracterización | F9: Ir al Event Storming | G9: Ir a las políticas
A10: Cliente | B10: Representa a la persona que solicita citas en la barbería. | C10: 2 | D10: Ir al muestreo | E10: Ir a la caracterización | F10: Ir al Event Storming | G10: Ir a las políticas
A11: Ciudad | B11: Representa cada una de las ciudades, pertenecientes a un departamento, en las que puede estar ubicada una sede de la barbería. | C11: 2 | D11: Ir al muestreo | E11: Ir a la caracterización | F11: Ir al Event Storming | G11: Ir a las políticas
A12: Sede | B12: Representa cada una de las sucursales físicas de una barbería, ubicada en una ciudad puntual, donde se ofrecen los servicios y trabajan los barberos. | C12: 3 | D12: Ir al muestreo | E12: Ir a la caracterización | F12: Ir al Event Storming | G12: Ir a las políticas
A13: Barbero | B13: Representa a un trabajador de la barbería que atiende clientes según los servicios que sabe realizar, organiza su propio horario y tiene su agenda personal para atender todas las citas que valla teniendo. | C13: 4 | D13: Ir al muestreo | E13: Ir a la caracterización | F13: Ir al Event Storming | G13: Ir a las políticas
A14: HorarioBarberia | B14: Representa, día por día, a qué hora abre y cierra el negocio; es el límite dentro del cual debe caber el horario de cualquier barbero. | C14: 4 | D14: Ir al muestreo | E14: Ir a la caracterización | F14: Ir al Event Storming | G14: Ir a las políticas
... A23: RegistroHoraCita | B23: Representa cada hora real registrada durante una cita puntual, según el tipo de momento al que corresponde (llegada del cliente, barbero preparado, inicio o fin de la atención). | C23: 8 | D23: Ir al muestreo | E23: Ir a la caracterización | F23: Ir al Event Storming | G23: Ir a las políticas

Sheet C-Barberia
A1: <<<< Ir al modulo de dominio | B1: <<<< Ir a objetos de dominio
A2: Nombre atributo | B2: Descripción atributo | C2: Identificador del objeto de dominio | D2: Tipo de dato | E2: Obligatorio | F2: Longitud mínima (si aplica) | G2: Longitud máxima (si aplica) | H2: Precisión (si aplica) | I2: Rendondeo (si aplica) | J2: Rango inicial (si aplica) | K2: Rango final (si aplica) | L2: Formato (si aplica) | M2: Reglas especiales (si aplica) | N2: Dato calculado | O2: Aplica ajuste del dato (si aplica) | P2: Carácter de ajuste (si aplica) | Q2: Quitar espacios en blanco al inicio (si aplica) | R2: Quitar espacios en blanco al fin (si aplica) | S2: Dato sensible (si aplica) | T2: Valor por defecto (si aplica) | U2: Auto generado | V2: =A12 -> registrarBarberia | W2: =A14 -> consultarDatosBarberia | X2: =A15 -> consultarNombreBarberia | Y2: =A16 -> cambiarNombreBarberia | AA2: =A18 -> darDeBajaBarberia
A3: ='M-Barberia'!A3 -> id | B3: ='M-Barberia'!A2 -> Representa un identificador que hará unico cada objeto de dominio de este tipo, no se puede repetir | C3: Si | D3: Identificador único universal | E3: Si | F3: No aplica | G3: No aplica | H3: No aplica | I3: No aplica | J3: No aplica | K3: No aplica | L3: No aplica | M3: No aplica | N3: No | O3: No aplica | P3: No aplica | Q3: No aplica | R3: No aplica | S3: No | T3: UUID vacio | U3: Si | V3: No requerido | W3: No mostrar | X3: No mostrar | Y3: Requerido | Z3: No modificable | AA3: Requerido
A4: ='M-Barberia'!B3 -> nombre | B4: ='M-Barberia'!B2 -> Representa el nombre comercial de la cadena de barbería, dueña de una o varias sedes | C4: No | D4: Alfanumérico | E4: Si | F4: 2 | G4: 50 | H4: No aplica | I4: No aplica | J4: No aplica | K4: No aplica | L4: No aplica | M4: Se aceptan todos los caracterez | N4: No | O4: No aplica | P4: No aplica | Q4: Si | R4: Si | S4: No | T4: Vacio | U4: No | V4: Requerido | W4: Mostrar | X4: Mostrar | Y4: Requerido | Z4: Modificable | AA4: No requerido
A5: ='M-Barberia'!C3 -> nit | B5: ='M-Barberia'!C2 -> Representa el número de identificación tributaria (NIT) que identifica legalmente a la barbería como empresa | C5: No | D5: Alfanumérico | E5: Si | F5: 10 | G5: 12 | H5: No aplica | I5: No aplica | J5: No aplica | K5: No aplica | L5: El usuario debe ingresar entre 8 y 10 dígitos, seguido de un guion (-), seguido de 1 dígito | M5: Solo se aceptan numeros del 0 al 9 y el '-' | N5: No | O5: No aplica | P5: No aplica | Q5: Si | R5: Si | S5: No | T5: Vacio | U5: No | V5: Requerido | W5: Mostrar | X5: No mostrar | Y5: No requerido | Z5: No modificable | AA5: No requerido
A7: Nombre combinación única | B7: Descripción | C7: Atributos involucrados
A8: ='M-Barberia'!D3 -> Combinación única | B8: ='M-Barberia'!D2 -> Combinación única que indica que no puede existir más de una barbería con el mismo NIT | C8: =A5 -> nit
A10: Responsabilidad | C10: Descripción | G10: Entradas | J10: Salida | O10: Políticas (Reglas de Negocio) | Q10: Excepción
G11: Parámetro | H11: Tipo de dato | I11: Descripción | J11: Tipo de Dato | K11: Descripción | O11: Política | P11: Descripción | Q11: Detalle | R11: ¿Qué hago?
A12: registrarBarberia | C12: Comando que permite registrar una nueva barbería con su nombre y nit | G12: datos{nombre, nit} | H12: Barberia | I12: Contiene la información requerida para registrar la barbería | J12: Barberia | K12: Contiene la información de la barbería registrada | O12: ='P-Barberia'!A6 -> P-BRA-0001 | P12: ='P-Barberia'!B6 -> Asegurar que los datos requeridos de la barbería (nombre, nit) sean válidos en tipo de dato, longitud, obligatoriedad, formato y rango | Q12: Generar una excepción indicándole al administrador que los datos no cumplen | R12: Detener operación
O13: ='P-Barberia'!A7 -> P-BRA-0002 | P13: ='P-Barberia'!B7 -> Asegurar que no exista otra barbería registrada con el mismo nit | Q13: Generar una excepción indicándole al administrador que ya existe una barbería con ese nit | R13: Detener operación
A14: consultarDatosBarberia | C14: Permite al administrador consultar el nombre y el nit de la barbería | G14: id | H14: UUID | I14: Corresponde al identificador de la barbería que se va a consultar | J14: Barberia | K14: Contiene el nombre y el nit de la barbería | O14: ='P-Barberia'!A8 -> P-BRA-0003 | P14: ='P-Barberia'!B8 -> Asegurar que exista la barbería con el id enviado | Q14: Informar con un mensaje que no existe una barbería con el identificador enviado y por lo tanto no se puede realizar la operación | R14: Detener operación
A15: consultarNombreBarberia | C15: Permite al barbero y al cliente consultar el nombre de la barbería | G15: id | H15: UUID | I15: Corresponde al identificador de la barbería que se va a consultar | J15: Alfanumérico | K15: Contiene el nombre de la barbería | O15: ='P-Barberia'!A8 -> P-BRA-0003 | P15: ='P-Barberia'!B8 -> Asegurar que exista la barbería con el id enviado | Q15: Informar con un mensaje que no existe una barbería con el identificador enviado y por lo tanto no se puede realizar la operación | R15: Detener operación
A16: cambiarNombreBarberia | C16: Permite al administrador cambiar el nombre comercial de la barbería | G16: id | H16: UUID | I16: Corresponde al identificador de la barbería | J16: Barberia | K16: Contiene la barbería con su nombre actualizado | O16: ='P-Barberia'!A8 -> P-BRA-0003 | P16: ='P-Barberia'!B8 -> Asegurar que exista la barbería con el id enviado | Q16: Informar con un mensaje que no existe una barbería con el identificador enviado y por lo tanto no se puede realizar la operación | R16: Detener operación
G17: datos{nombre} | H17: Barberia | I17: Contiene el nuevo nombre de la barbería | O17: ='P-Barberia'!A6 -> P-BRA-0001 | P17: ='P-Barberia'!B6 -> Asegurar que los datos requeridos de la barbería (nombre, nit) sean válidos en tipo de dato, longitud, obligatoriedad, formato y rango | Q17: Generar una excepción indicándole al administrador cuáles datos de la barbería no cumplen con las reglas definidas | R17: Detener operación
A18: darDeBajaBarberia | C18: Permite al administrador eliminar la barbería del sistema cuando ya no tiene sedes registradas | G18: id | H18: UUID | I18: Corresponde al identificador de la barbería que se va a dar de baja | J18: No retorna ningún valor. En caso de error genera una excepción. | O18: ='P-Barberia'!A8 -> P-BRA-0003 | P18: ='P-Barberia'!B8 -> Asegurar que exista la barbería con el id enviado | Q18: Informar con un mensaje que no existe una barbería con el identificador enviado y por lo tanto no se puede realizar la operación | R18: Detener operación

Sheet P-Barberia
A1: << Ir al modelo de dominio | B1: << Ir al listado de objetos de dominio | C1: << Ir a la caracterización del objeto de dominio | D1: Ir al muestreo de datos del objeto de dominio >> | E1: Ir al event storming del objeto de dominio >>
A2: Objeto de Dominio: | B2: ='Objetos de Dominio'!A3 -> Barberia
A3: Descripción: | B3: ='Objetos de Dominio'!B3 -> Representa la cadena o marca comercial de barbería, dueña de una o varias sedes.
A4: Numero politica | B4: Descripcion politica | D4: Objeto responsable | E4: Regla responsable
A6: P-BRA-0001 | B6: Asegurar que los datos requeridos de la barbería (nombre, nit) sean válidos en tipo de dato, longitud, obligatoriedad, formato y rango | D6: Barberia
A7: P-BRA-0002 | B7: Asegurar que no exista otra barbería registrada con el mismo nit | D7: Barberia
A8: P-BRA-0003 | B8: Asegurar que exista la barbería con el id enviado | D8: Barberia

Sheet E-Barberia
A1: << Ir al modelo de dominio | C1: << Ir al listado de objetos de dominio | F1: << Ir a la caracterización del objeto de dominio | J1: Ir al muestreo de datos del objeto de dominio >>
A2: Objeto de Dominio: | B2: ='Objetos de Dominio'!A3 -> Barberia
A3: Descripción: | B3: ='Objetos de Dominio'!B3 -> Representa la cadena o marca comercial de barbería, dueña de una o varias sedes.
A4: Actor | B4: Action/Command | D4: Entity/Aggregate/Object domain | E4: Read Model | G4: Business Rule/Policy | I4: External System | J4: Domain Event | K4: Hotspot/questions/Risk
A5: Actor | B5: Acción | C5: Descripción | D5: Objeto de dominio | E5: Información externa | G5: Políticas | I5: Sistema Externo | J5: Evento | K5: Aspectos por solucionar
E6: Información | F6: Descripción | G6: Número | H6: Descripción
A7: Administrador | B7: Registrar barberia | C7: Comando que permite al administrador registrar una nueva barbería con su nombre y nit | D7: =$B$2 -> Barberia | G7: ='P-Barberia'!A6 -> P-BRA-0001 | H7: ='P-Barberia'!B6 -> Asegurar que los datos requeridos de la barbería (nombre, nit) sean válidos en tipo de dato, longitud, obligatoriedad, formato y rango | J7: Barbería registrada
G8: ='P-Barberia'!A7 -> P-BRA-0002 | H8: ='P-Barberia'!B7 -> Asegurar que no exista otra barbería registrada con el mismo nit
A9: Administrador | B9: Ver nombre y nit de la barberia | C9: Permite al administrador consultar el nombre y el nit de la barbería | D9: =$B$2 -> Barberia | J9: Nombre y nit de barbería consultados
A10: Barbero | B10: Ver nombre de la barberia | C10: Permite al barbero consultar el nombre de la barbería | D10: =$B$2 -> Barberia | J10: Nombre de barbería consultado
A11: Cliente | B11: Ver nombre de la barberia | C11: Permite al cliente consultar el nombre de la barbería | D11: =$B$2 -> Barberia | J11: Nombre de barbería consultado
A12: Administrador | B12: Cambiar nombre de la barberia | C12: Permite al administrador cambiar el nombre comercial de la barbería | D12: =$B$2 -> Barberia | G12: ='P-Barberia'!A8 -> P-BRA-0003 | H12: ='P-Barberia'!B8 -> Asegurar que exista la barbería con el id enviado | J12: Nombre de barbería cambiado
G13: ='P-Barberia'!A6 -> P-BRA-0001 | H13: ='P-Barberia'!B6 -> Asegurar que los datos requeridos de la barbería (nombre, nit) sean válidos en tipo de dato, longitud, obligatoriedad, formato y rango
A14: Administrador | B14: Dar de baja la barberia | C14: Permite al administrador eliminar la barbería del sistema, como si nunca hubiera existido, cuando ya no tiene sedes registradas | D14: =$B$2 -> Barberia | J14: Barbería eliminada

Sheet M-Barberia
A1: <<<< Ir al modulo de dominio | B1: <<<< Ir a objetos de dominio
A2: Representa un identificador que hará unico cada objeto de dominio de este tipo, no se puede repetir | B2: Representa el nombre comercial de la cadena de barbería, dueña de una o varias sedes | C2: Representa el número de identificación tributaria (NIT) que identifica legalmente a la barbería como empresa | D2: Combinación única que indica que no puede existir más de una barbería con el mismo NIT
A3: id | B3: nombre | C3: nit | D3: Combinación única
A4: 1 | B4: BarberClub | C4: 900123456-7 | D4: =C4 -> 900123456-7
A5: 2 | B5: Corte y Estilo | C5: 900654321-9 | D5: =C5 -> 900654321-9
B11: Corresponde a la descripcion de los atributos
B12: Corresponde al identificador unico del objeto de dominio
B13: Corresponde a los datos que ingresa el usuario
B14: Corresponde a la combinacion única

Sheet C-DiaSemana
A1: <<<< Ir al modulo de dominio | B1: <<<< Ir a objetos de dominio
A2: Nombre atributo | B2: Descripción atributo | C2: Identificador del objeto de dominio | D2: Tipo de dato | E2: Obligatorio | F2: Longitud mínima (si aplica) | G2: Longitud máxima (si aplica) | H2: Precisión (si aplica) | I2: Rendondeo (si aplica) | J2: Rango inicial (si aplica) | K2: Rango final (si aplica) | L2: Formato (si aplica) | M2: Reglas especiales (si aplica) | N2: Dato calculado | O2: Aplica ajuste del dato (si aplica) | P2: Carácter de ajuste (si aplica) | Q2: Quitar espacios en blanco al inicio (si aplica) | R2: Quitar espacios en blanco al fin (si aplica) | S2: Dato sensible (si aplica) | T2: Valor por defecto (si aplica) | U2: Auto generado | V2: =A11 -> VerDiasDeLaSemana
A3: ='M-DiaSemana'!A3 -> id | B3: ='M-DiaSemana'!A2 -> Representa un identificador que hará unico cada objeto de dominio de este tipo, no se puede repetir | C3: Si | D3: Identificador único universal | E3: Si | F3: No aplica | G3: No aplica | H3: No aplica | I3: No aplica | J3: No aplica | K3: No aplica | L3: No aplica | M3: No aplica | N3: No | O3: No aplica | P3: No aplica | Q3: No aplica | R3: No aplica | S3: No | T3: UUID vacio | U3: Si | V3: No mostrar
A4: ='M-DiaSemana'!B3 -> nombre | B4: ='M-DiaSemana'!B2 -> Representa como se llama el dia de la semana, para los horarios | C4: No | D4: Alfanumérico | E4: Si | F4: 5 | G4: 9 | H4: No aplica | I4: No aplica | J4: No aplica | K4: No aplica | L4: No aplica | M4: Solo pueden ser los dias de la semana como Lunes, Martes, Miércoles, Jueves, Viernes, Sábado, Domingo y Festivo | N4: No | O4: No aplica | P4: No aplica | Q4: Si | R4: Si | S4: No | T4: Vacio | U4: No | V4: Mostrar
A6: Nombre combinación única | B6: Descripción | C6: Atributos involucrados
A7: ='M-DiaSemana'!C3 -> Combinación única | B7: ='M-DiaSemana'!C2 -> Combinacion única que indica que no puede existir más un dia de la semana con el mismo nombre | C7: nombre
A9: Responsabilidad | C9: Descripción | G9: Entradas | J9: Salida | O9: Políticas (Reglas de Negocio) | Q9: Excepción
G10: Parámetro | H10: Tipo de dato | I10: Descripción | J10: Tipo de Dato | K10: Descripción | O10: Política | P10: Descripción | Q10: Detalle | R10: ¿Qué hago?
A11: VerDiasDeLaSemana | C11: Permite consultar el catálogo de días de la semana, incluyendo festivo, para definir los horarios | J11: Lista<DiaSemana> | K11: Contiene todos los días de la semana

Sheet P-DiaSemana
A1: << Ir al modelo de dominio | B1: << Ir al listado de objetos de dominio | C1: << Ir a la caracterización del objeto de dominio | D1: Ir al muestreo de datos del objeto de dominio >> | E1: Ir al event storming del objeto de dominio >>
A2: Objeto de Dominio: | B2: ='Objetos de Dominio'!A4 -> DiaSemana
A3: Descripción: | B3: ='Objetos de Dominio'!B4 -> Representa cada uno de los días de la semana, incluyendo festivo, que se usa como catálogo para definir los horarios de la barbería y de cada barbero.
A4: Numero politica | B4: Descripcion politica | D4: Objeto responsable | E4: Regla responsable
B6: No aplica: es un catálogo de solo lectura, sin comandos que impliquen políticas de negocio propias

Sheet E-DiaSemana
A1: << Ir al modelo de dominio | C1: << Ir al listado de objetos de dominio | F1: << Ir a la caracterización del objeto de dominio | J1: Ir al muestreo de datos del objeto de dominio >>
A2: Objeto de Dominio: | B2: ='Objetos de Dominio'!A4 -> DiaSemana
A3: Descripción: | B3: ='Objetos de Dominio'!B4 -> Representa cada uno de los días de la semana, incluyendo festivo, que se usa como catálogo para definir los horarios de la barbería y de cada barbero.
A4: Actor | B4: Action/Command | D4: Entity/Aggregate/Object domain | E4: Read Model | G4: Business Rule/Policy | I4: External System | J4: Domain Event | K4: Hotspot/questions/Risk
A5: Actor | B5: Acción | C5: Descripción | D5: Objeto de dominio | E5: Información externa | G5: Políticas | I5: Sistema Externo | J5: Evento | K5: Aspectos por solucionar
E6: Información | F6: Descripción | G6: Número | H6: Descripción
A7: Administrador | B7: Ver los días de las semanas | C7: Permite consultar el catálogo de días de la semana, incluyendo festivo, disponibles para definir horarios | D7: =$B$2 -> DiaSemana | J7: Días de la semana consultados
A8: Barbero | B8: Ver los días de las semanas | C8: Permite consultar el catálogo de días de la semana, incluyendo festivo, disponibles para definir horarios | D8: =$B$2 -> DiaSemana | J8: Días de la semana consultados

Sheet M-DiaSemana
A1: <<<< Ir al modulo de dominio | B1: <<<< Ir a objetos de dominio
A2: Representa un identificador que hará unico cada objeto de dominio de este tipo, no se puede repetir | B2: Representa como se llama el dia de la semana, para los horarios | C2: Combinacion única que indica que no puede existir más un dia de la semana con el mismo nombre
A3: id | B3: nombre | C3: Combinación única
A4: 1 | B4: Lunes | C4: =B4 -> Lunes
A5: 2 | B5: Martes | C5: =B5 -> Martes
A6: 3 | B6: Miércoles | C6: =B6 -> Miércoles
A7: 4 | B7: Jueves | C7: =B7 -> Jueves
A8: 5 | B8: Viernes | C8: =B8 -> Viernes
A9: 6 | B9: Sábado | C9: =B9 -> Sábado
A10: 7 | B10: Domingo | C10: =B10 -> Domingo
A11: 8 | B11: Festivo | C11: =B11 -> Festivo
B17: Corresponde a la descripcion de los atributos
B18: Corresponde al identificador unico del objeto de dominio
B19: Corresponde a los datos que ingresa el usuario
B20: Corresponde a la combinacion única

Sheet C-Departamento
A1: <<<< Ir al modulo de dominio | B1: <<<< Ir a objetos de dominio
A2: Nombre atributo | B2: Descripción atributo | C2: Identificador del objeto de dominio | D2: Tipo de dato | E2: Obligatorio | F2: Longitud mínima (si aplica) | G2: Longitud máxima (si aplica) | H2: Precisión (si aplica) | I2: Rendondeo (si aplica) | J2: Rango inicial (si aplica) | K2: Rango final (si aplica) | L2: Formato (si aplica) | M2: Reglas especiales (si aplica) | N2: Dato calculado | O2: Aplica ajuste del dato (si aplica) | P2: Carácter de ajuste (si aplica) | Q2: Quitar espacios en blanco al inicio (si aplica) | R2: Quitar espacios en blanco al fin (si aplica) | S2: Dato sensible (si aplica) | T2: Valor por defecto (si aplica) | U2: Auto generado | V2: =A11 -> consultarDepartamentos
A3: ='M-Departamento'!A3 -> id | B3: ='M-Departamento'!A2 -> Representa un identificador que hará unico cada objeto de dominio de este tipo, no se puede repetir | C3: Si | D3: Identificador único universal | E3: Si | F3: No aplica | G3: No aplica | H3: No aplica | I3: No aplica | J3: No aplica | K3: No aplica | L3: No aplica | M3: No aplica | N3: No | O3: No aplica | P3: No aplica | Q3: No aplica | R3: No aplica | S3: No | T3: UUID vacio | U3: Si | V3: No mostrar
A4: ='M-Departamento'!B3 -> nombre | B4: ='M-Departamento'!B2 -> Representa el nombre del departamento en el que están ubicadas las ciudades donde la barbería puede tener sedes | C4: No | D4: Alfanumérico | E4: Si | F4: 4 | G4: 60 | H4: No aplica | I4: No aplica | J4: No aplica | K4: No aplica | L4: No aplica | M4: Permite caracterez de la 'a' a la 'z' minusculas y mayusculas, con espacios en blanco y esas letras pero con tilde | N4: No | O4: No aplica | P4: No aplica | Q4: Si | R4: Si | S4: No | T4: Vacio | U4: No | V4: Mostrar
A6: Nombre combinación única | B6: Descripción | C6: Atributos involucrados
A7: ='M-Departamento'!C3 -> Combinación única | B7: ='M-Departamento'!C2 -> Combinación única que indica que no puede existir más de un departamento con el mismo nombre | C7: =A4 -> nombre
A9: Responsabilidad | C9: Descripción | G9: Entradas | J9: Salida | O9: Políticas (Reglas de Negocio) | Q9: Excepción
G10: Parámetro | H10: Tipo de dato | I10: Descripción | J10: Tipo de Dato | K10: Descripción | O10: Política | P10: Descripción | Q10: Detalle | R10: ¿Qué hago?
A11: consultarDepartamentos | C11: Permite consultar el catálogo de departamentos disponibles | J11: Lista<Departamento> | K11: Contiene todos los departamentos registrados

Sheet P-Departamento
A1: << Ir al modelo de dominio | B1: << Ir al listado de objetos de dominio | C1: << Ir a la caracterización del objeto de dominio | D1: Ir al muestreo de datos del objeto de dominio >> | E1: Ir al event storming del objeto de dominio >>
A2: Objeto de Dominio: | B2: ='Objetos de Dominio'!A5 -> Departamento
A3: Descripción: | B3: ='Objetos de Dominio'!B5 -> Representa cada uno de los departamentos del país en los que se encuentran las ciudades donde la barbería puede tener sedes.
A4: Numero politica | B4: Descripcion politica | D4: Objeto responsable | E4: Regla responsable
B6: No aplica: es un catálogo de solo lectura, sin comandos que impliquen políticas de negocio propias

Sheet E-Departamento
A1: << Ir al modelo de dominio | C1: << Ir al listado de objetos de dominio | F1: << Ir a la caracterización del objeto de dominio | J1: Ir al muestreo de datos del objeto de dominio >>
A2: Objeto de Dominio: | B2: ='Objetos de Dominio'!A5 -> Departamento
A3: Descripción: | B3: ='Objetos de Dominio'!B5 -> Representa cada uno de los departamentos del país en los que se encuentran las ciudades donde la barbería puede tener sedes.
A4: Actor | B4: Action/Command | D4: Entity/Aggregate/Object domain | E4: Read Model | G4: Business Rule/Policy | I4: External System | J4: Domain Event | K4: Hotspot/questions/Risk
A5: Actor | B5: Acción | C5: Descripción | D5: Objeto de dominio | E5: Información externa | G5: Políticas | I5: Sistema Externo | J5: Evento | K5: Aspectos por solucionar
E6: Información | F6: Descripción | G6: Número | H6: Descripción
A7: Administrador | B7: Ver los departamentos | C7: Permite consultar el catálogo de departamentos en los que se pueden ubicar las ciudades de las sedes | D7: =$B$2 -> Departamento | J7: Departamentos consultados

Sheet M-Departamento
A1: <<<< Ir al modulo de dominio | B1: <<<< Ir a objetos de dominio
A2: Representa un identificador que hará unico cada objeto de dominio de este tipo, no se puede repetir | B2: Representa el nombre del departamento en el que están ubicadas las ciudades donde la barbería puede tener sedes | C2: Combinación única que indica que no puede existir más de un departamento con el mismo nombre
A3: id | B3: nombre | C3: Combinación única
A4: 1 | B4: Antioquia | C4: =B4 -> Antioquia
A5: 2 | B5: Cundinamarca | C5: =B5 -> Cundinamarca
A6: 3 | B6: Valle del Cauca | C6: =B6 -> Valle del Cauca
A7: 4 | B7: Atlántico | C7: =B7 -> Atlántico
A8: 5 | B8: Santander | C8: =B8 -> Santander
B14: Corresponde a la descripcion de los atributos
B15: Corresponde al identificador unico del objeto de dominio
B16: Corresponde a los datos de libre ingreso
B17: Corresponde a la combinacion única

Sheet C-Estado
A1: <<<< Ir al modulo de dominio | B1: <<<< Ir a objetos de dominio
A2: Nombre atributo | B2: Descripción atributo | C2: Identificador del objeto de dominio | D2: Tipo de dato | E2: Obligatorio | F2: Longitud mínima (si aplica) | G2: Longitud máxima (si aplica) | H2: Precisión (si aplica) | I2: Rendondeo (si aplica) | J2: Rango inicial (si aplica) | K2: Rango final (si aplica) | L2: Formato (si aplica) | M2: Reglas especiales (si aplica) | N2: Dato calculado | O2: Aplica ajuste del dato (si aplica) | P2: Carácter de ajuste (si aplica) | Q2: Quitar espacios en blanco al inicio (si aplica) | R2: Quitar espacios en blanco al fin (si aplica) | S2: Dato sensible (si aplica) | T2: Valor por defecto (si aplica) | U2: Auto generado | V2: =A12 -> consultarTodosLosEstados | W2: =A13 -> editarDescripcion | X2: 'C-Estado'!A13 | Y2: =A15 -> consultarDescripcion
A3: ='M-Estado'!A3 -> id | B3: ='M-Estado'!A2 -> Representa un identificador que hará unico cada objeto de dominio de este tipo, no se puede repetir | C3: Si | D3: Identificador único universal | E3: Si | F3: No aplica | G3: No aplica | H3: No aplica | I3: No aplica | J3: No aplica | K3: No aplica | L3: No aplica | M3: No aplica | N3: No | O3: No aplica | P3: No aplica | Q3: No aplica | R3: No aplica | S3: No aplica | T3: UUID vacio | U3: Si | V3: No mostrar | W3: Requerido | X3: No modificable | Y3: No mostrar
A4: ='M-Estado'!B3 -> nombre | B4: ='M-Estado'!B2 -> Representa como se llama el estado en el que se encuentra una cita puntual | C4: No | D4: Alfanumérico | E4: Si | F4: 4 | G4: 50 | H4: No aplica | I4: No aplica | J4: No aplica | K4: No aplica | L4: No aplica | M4: Solo se aceptan caracteres de letras de la 'a' a la 'z' y espacios en blanco | N4: No | O4: No aplica | P4: No aplica | Q4: Si | R4: Si | S4: No | T4: Vacio | U4: No | V4: Mostrar | W4: No requerido | X4: No modificable | Y4: No mostrar
A5: ='M-Estado'!C3 -> descripcion | B5: ='M-Estado'!C2 -> Representa el significado de que representa cada estado para la cita | C5: No | D5: Alfanumérico | E5: Si | F5: 10 | G5: 300 | H5: No aplica | I5: No aplica | J5: No aplica | K5: No aplica | L5: No aplica | M5: Solo se aceptan caracteres de letras de la 'a' a la 'z', caracteres con tilde y espacios en blanco | N5: No | O5: No aplica | P5: No aplica | Q5: Si | R5: Si | S5: No | T5: Vacio | U5: No | V5: No mostrar | W5: Requerido | X5: Modificable | Y5: Mostrar
A7: Nombre combinación única | B7: Descripción | C7: Atributos involucrados
A8: ='M-Estado'!D3 -> Combinación única | B8: ='M-Estado'!D2 -> Combinacion única que indica que no puede existir más un dia de la semana con el mismo nombre | C8: nombre
A10: Responsabilidad | C10: Descripción | G10: Entradas | J10: Salida | O10: Políticas (Reglas de Negocio) | Q10: Excepción
G11: Parámetro | H11: Tipo de dato | I11: Descripción | J11: Tipo de Dato | K11: Descripción | O11: Política | P11: Descripción | Q11: Detalle | R11: ¿Qué hago?
A12: consultarTodosLosEstados | C12: Permite consultar los estados posibles que puede tener una cita | J12: Lista<Estado> | K12: Contiene todos los estados que cumplen con el filtro enviado
A13: editarDescripcion | C13: Permite ajustar el texto descriptivo de un estado ya creado, sin cambiar su significado en el flujo de la cita | G13: id | H13: UUID | I13: Corresponde al identificador del estado que se va a editar | K13: La descripcion del estado se editó | O13: ='P-Estado'!A7 -> P-EST-0002 | P13: ='P-Estado'!B7 -> Asegurar que exista el estado con el id enviado | Q13: Informar con un mensaje que no existe un estado con el identificador enviado y por lo tanto no es posible modificar la descripción | R13: Detener ejecución de la operación
G14: datos{descripcion} | H14: Estado | I14: Contiene la nueva descripción del estado | O14: ='P-Estado'!A6 -> P-EST-0001 | P14: ='P-Estado'!B6 -> Asegurar que los datos requeridos (descripción) sean válidos en tipo de dato, longitud, formato y rango | Q14: Generar una excepción indicándole al usuario cuáles datos de la descripción del estado no cumplen con las reglas definidas | R14: Detener operación
A15: consultarDescripcion | C15: Permite consultar la descripcion de un estado en especifico | G15: datos{nombre} | H15: Estado | I15: Contiene el nombre del estado | J15: Alfanumérico | K15: Contiene la información del estado consultado por su identificador | O15: ='P-Estado'!A7 -> P-EST-0002 | P15: ='P-Estado'!B7 -> Asegurar que exista el estado con el id enviado | Q15: Informar con un mensaje que no existe un Estado con el identificador enviado y por lo tanto no es posible modificar la descripción | R15: Detener ejecución de la operación

Sheet P-Estado
A1: << Ir al modelo de dominio | B1: << Ir al listado de objetos de dominio | C1: << Ir a la caracterización del objeto de dominio | D1: Ir al muestreo de datos del objeto de dominio >> | E1: Ir al event storming del objeto de dominio >>
A2: Objeto de Dominio: | B2: ='Objetos de Dominio'!A6 -> Estado
A3: Descripción: | B3: ='Objetos de Dominio'!B6 -> Representa en qué situación puntual se encuentra una cita: agendada, finalizada, cancelada por alguna de las partes, con tardanza del cliente o del barbero, o con inasistencia del cliente.
A4: Numero politica | B4: Descripcion politica | D4: Objeto responsable | E4: Regla responsable
A6: P-EST-0001 | B6: Asegurar que los datos requeridos (descripción) sean válidos en tipo de dato, longitud, formato y rango | D6: Estado
A7: P-EST-0002 | B7: Asegurar que exista el estado con el id enviado | D7: Estado

Sheet E-Estado
A1: << Ir al modelo de dominio | C1: << Ir al listado de objetos de dominio | F1: << Ir a la caracterización del objeto de dominio | J1: Ir al muestreo de datos del objeto de dominio >>
A2: Objeto de Dominio: | B2: ='Objetos de Dominio'!A6 -> Estado
A3: Descripción: | B3: ='Objetos de Dominio'!B6 -> Representa en qué situación puntual se encuentra una cita: agendada, finalizada, cancelada por alguna de las partes, con tardanza del cliente o del barbero, o con inasistencia del cliente.
A4: Actor | B4: Action/Command | D4: Entity/Aggregate/Object domain | E4: Read Model | G4: Business Rule/Policy | I4: External System | J4: Domain Event | K4: Hotspot/questions/Risk
A5: Actor | B5: Acción | C5: Descripción | D5: Objeto de dominio | E5: Información externa | G5: Políticas | I5: Sistema Externo | J5: Evento | K5: Aspectos por solucionar
E6: Información | F6: Descripción | G6: Número | H6: Descripción
A7: Administrador | B7: Ver estados de las citas | C7: Permite consultar los estados posibles que puede tener una cita | D7: =$B$2 -> Estado | J7: Estados consultados
A8: Barbero | B8: Ver estados de las citas | C8: Permite consultar los estados posibles que puede tener una cita | D8: =$B$2 -> Estado | J8: Estados consultados
A9: Cliente | B9: Ver estados de las citas | C9: Permite consultar los estados posibles que puede tener una cita | D9: =$B$2 -> Estado | J9: Estados consultados
A10: Administrador | B10: Editar descripción del estado | C10: Permite ajustar el texto descriptivo de un estado ya creado, sin cambiar su significado en el flujo de la cita | D10: =$B$2 -> Estado | G10: ='P-Estado'!A6 -> P-EST-0001 | H10: ='P-Estado'!B6 -> Asegurar que los datos requeridos (descripción) sean válidos en tipo de dato, longitud, formato y rango | J10: Descripción de estado actualizada
A11: Administrador | B11: Ver descripcion de un estado | C11: Permite consultar la descripcion de un estado en especifico | D11: =$B$2 -> Estado | J11: Descripción del estado consultada
A12: Barbero | B12: Ver descripcion de un estado | C12: Permite consultar la descripcion de un estado en especifico | D12: =$B$2 -> Estado | J12: Descripción del estado consultada
A13: Cliente | B13: Ver descripcion de un estado | C13: Permite consultar la descripcion de un estado en especifico | D13: =$B$2 -> Estado | J13: Descripción del estado consultada

Sheet M-Estado
A1: <<<< Ir al modulo de dominio | B1: <<<< Ir a objetos de dominio
A2: Representa un identificador que hará unico cada objeto de dominio de este tipo, no se puede repetir | B2: Representa como se llama el estado en el que se encuentra una cita puntual | C2: Representa el significado de que representa cada estado para la cita | D2: Combinacion única que indica que no puede existir más un dia de la semana con el mismo nombre
A3: id | B3: nombre | C3: descripcion | D3: Combinación única
A4: 1 | B4: Agendada | C4: La cita quedó registrada en la agenda del barbero y está a la espera de la fecha y hora acordadas. | D4: =B4 -> Agendada
A5: 2 | B5: Finalizada | C5: El barbero atendió al cliente y el servicio contratado se prestó por completo, sin tener ninguna sanción. | D5: =B5 -> Finalizada
A6: 3 | B6: Cancelada por el cliente | C6: El cliente decidió no asistir y anuló la cita antes de la fecha y hora programada. | D6: =B6 -> Cancelada por el cliente
A7: 4 | B7: Cancelada por el barbero | C7: El barbero anuló la cita antes de la fecha y hora programada, por ejemplo por una eventualidad. | D7: =B7 -> Cancelada por el barbero
A8: 5 | B8: El cliente se demoro | C8: El cliente llegó después de la hora acordada superando el tiempoEspera definido en la cita, lo que genera una multa de tipo Tardanza. | D8: =B8 -> El cliente se demoro
A9: 6 | B9: El barbero se demoro | C9: El barbero se demoró más de lo previsto en una cita anterior y empezó a atender al cliente superando el tiempoEspera definido en la cita, lo que le da un descuento al cliente. | D9: =B9 -> El barbero se demoro
A10: 7 | B10: Inasistencia del cliente | C10: El cliente nunca llegó a la cita: se alcanzó la hora estimada de finalización sin registrar su llegada, lo que genera una multa por el valor total de los servicios pedidos. | D10: =B10 -> Inasistencia del cliente
A11: 8 | B11: Cancelación | C11: La cita se anuló automáticamente porque la barbería cambió sus políticas de horario: al desactivarse el horario de la barbería se desactivaron los horarios de barbero y las agendas que dependían de él, y las citas que quedaron por fuera se cancelaron. | D11: =B11 -> Cancelación
B17: Corresponde a la descripcion de los atributos
B18: Corresponde al identificador unico del objeto de dominio
B19: Corresponde a los datos del objeto de dominio
B20: Corresponde a la combinacion única

Sheet C-PrefijoCelular
A1: <<<< Ir al modulo de dominio | B1: <<<< Ir a objetos de dominio
A2: Nombre atributo | B2: Descripción atributo | C2: Identificador del objeto de dominio | D2: Tipo de dato | E2: Obligatorio | F2: Longitud mínima (si aplica) | G2: Longitud máxima (si aplica) | H2: Precisión (si aplica) | I2: Rendondeo (si aplica) | J2: Rango inicial (si aplica) | K2: Rango final (si aplica) | L2: Formato (si aplica) | M2: Reglas especiales (si aplica) | N2: Dato calculado | O2: Aplica ajuste del dato (si aplica) | P2: Carácter de ajuste (si aplica) | Q2: Quitar espacios en blanco al inicio (si aplica) | R2: Quitar espacios en blanco al fin (si aplica) | S2: Dato sensible (si aplica) | T2: Valor por defecto (si aplica) | U2: Auto generado | V2: =A11 -> consultarPrefijosCelular
A3: ='M-PrefijoCelular'!A3 -> id | B3: ='M-PrefijoCelular'!A2 -> Representa un identificador que hará unico cada objeto de dominio de este tipo, no se puede repetir | C3: Si | D3: Identificador único universal | E3: Si | F3: No aplica | G3: No aplica | H3: No aplica | I3: No aplica | J3: No aplica | K3: No aplica | L3: No aplica | M3: No aplica | N3: No | O3: No | P3: No aplica | Q3: No | R3: No | S3: No | T3: No aplica | U3: Si | V3: No mostrar
A4: ='M-PrefijoCelular'!B3 -> prefijo | B4: ='M-PrefijoCelular'!B2 -> Representa el prefijo telefónico del país que el administrador habilita para que la barbería pueda atender números de ese país | C4: No | D4: Alfanumérico | E4: Si | F4: 2 | G4: 6 | H4: No aplica | I4: No aplica | J4: No aplica | K4: No aplica | L4: Simbolo + seguido de un número. Por ejemplo +57. Tambien el anterior puede ser seguido de un - y un numero. Por ejemplo +1-809 | M4: Solo se aceptan caracteres numericos del 0 al 9 y el carácter '+' y '-' | N4: No | O4: No | P4: No aplica | Q4: Si | R4: Si | S4: No | T4: +0 | U4: No | V4: Mostrar
A6: Nombre combinación única | B6: Descripción | C6: Atributos involucrados
A7: ='M-PrefijoCelular'!C3 -> Combinación única | B7: ='M-PrefijoCelular'!C2 -> Combinacion única que indica que no puede existir más un mismo prefijo | C7: prefijo
A9: Responsabilidad | C9: Descripción | G9: Entradas | J9: Salida | O9: Políticas (Reglas de Negocio) | Q9: Excepción
G10: Parámetro | H10: Tipo de dato | I10: Descripción | J10: Tipo de Dato | K10: Descripción | O10: Política | P10: Descripción | Q10: Detalle | R10: ¿Qué hago?
A11: consultarPrefijosCelular | C11: Permite al administrador consultar el catálogo de prefijos telefónicos de país que tiene habilitados | J11: Lista<PrefijoCelular> | K11: Contiene todos los prefijos de celular registrados

Sheet P-PrefijoCelular
A1: << Ir al modelo de dominio | B1: << Ir al listado de objetos de dominio | C1: << Ir a la caracterización del objeto de dominio | D1: Ir al muestreo de datos del objeto de dominio >> | E1: Ir al event storming del objeto de dominio >>
A2: Objeto de Dominio: | B2: ='Objetos de Dominio'!A7 -> PrefijoCelular
A3: Descripción: | B3: ='Objetos de Dominio'!B7 -> Representa el catálogo de prefijos telefónicos de país que el administrador habilita, y que son los únicos que barberos y clientes pueden usar en su número de celular.
A4: Numero politica | B4: Descripcion politica | D4: Objeto responsable | E4: Regla responsable
B6: No aplica: es un catálogo de solo lectura, sin comandos que impliquen políticas de negocio propias

Sheet E-PrefijoCelular
A1: << Ir al modelo de dominio | C1: << Ir al listado de objetos de dominio | F1: << Ir a la caracterización del objeto de dominio | J1: Ir al muestreo de datos del objeto de dominio >>
A2: Objeto de Dominio: | B2: ='Objetos de Dominio'!A7 -> PrefijoCelular
A3: Descripción: | B3: ='Objetos de Dominio'!B7 -> Representa el catálogo de prefijos telefónicos de país que el administrador habilita, y que son los únicos que barberos y clientes pueden usar en su número de celular.
A4: Actor | B4: Action/Command | D4: Entity/Aggregate/Object domain | E4: Read Model | G4: Business Rule/Policy | I4: External System | J4: Domain Event | K4: Hotspot/questions/Risk
A5: Actor | B5: Acción | C5: Descripción | D5: Objeto de dominio | E5: Información externa | G5: Políticas | I5: Sistema Externo | J5: Evento | K5: Aspectos por solucionar
E6: Información | F6: Descripción | G6: Número | H6: Descripción
A7: Administrador | B7: Ver prefijos de celular | C7: Permite al administrador consultar el catálogo de prefijos telefónicos de país que tiene habilitados | D7: =$B$2 -> PrefijoCelular | J7: Prefijos de celular consultados
A8: Barbero | B8: Ver prefijos de celular | C8: Permite consultar el catálogo de prefijos telefónicos de país disponibles | D8: =$B$2 -> PrefijoCelular | J8: Prefijos de celular consultados
A9: Cliente | B9: Ver prefijos de celular | C9: Permite consultar el catálogo de prefijos telefónicos de país disponibles | D9: =$B$2 -> PrefijoCelular | J9: Prefijos de celular consultados

Sheet M-PrefijoCelular
A1: <<<< Ir al modulo de dominio | B1: <<<< Ir a objetos de dominio
A2: Representa un identificador que hará unico cada objeto de dominio de este tipo, no se puede repetir | B2: Representa el prefijo telefónico del país que el administrador habilita para que la barbería pueda atender números de ese país | C2: Combinacion única que indica que no puede existir más un mismo prefijo
A3: id | B3: prefijo | C3: Combinación única
A4: 1 | B4: +57 | C4: =B4 -> +57
A5: 2 | B5: +91 | C5: =B5 -> +91
A6: 3 | B6: +593 | C6: =B6 -> +593
A7: 4 | B7: +58 | C7: =B7 -> +58
B13: Corresponde a la descripcion de los atributos
B14: Corresponde al identificador unico del objeto de dominio
B15: Corresponde a los datos que ingresa el usuario
B16: Corresponde a la combinacion única

Sheet C-TipoMulta
A1: <<<< Ir al modulo de dominio | B1: <<<< Ir a objetos de dominio
A2: Nombre atributo | B2: Descripción atributo | C2: Identificador del objeto de dominio | D2: Tipo de dato | E2: Obligatorio | F2: Longitud mínima (si aplica) | G2: Longitud máxima (si aplica) | H2: Precisión (si aplica) | I2: Rendondeo (si aplica) | J2: Rango inicial (si aplica) | K2: Rango final (si aplica) | L2: Formato (si aplica) | M2: Reglas especiales (si aplica) | N2: Dato calculado | O2: Aplica ajuste del dato (si aplica) | P2: Carácter de ajuste (si aplica) | Q2: Quitar espacios en blanco al inicio (si aplica) | R2: Quitar espacios en blanco al fin (si aplica) | S2: Dato sensible (si aplica) | T2: Valor por defecto (si aplica) | U2: Auto generado | V2: =A12 -> consultarTodosLosTiposMulta
A3: ='M-TipoMulta'!A3 -> id | B3: ='M-TipoMulta'!A2 -> Representa un identificador que hará unico cada objeto de dominio de este tipo, no se puede repetir | C3: Si | D3: Identificador único universal | E3: Si | F3: No aplica | G3: No aplica | H3: No aplica | I3: No aplica | J3: No aplica | K3: No aplica | L3: No aplica | M3: No aplica | N3: No | O3: No | P3: No aplica | Q3: No | R3: No | S3: No | T3: UUID vacio | U3: Si | V3: No mostrar
A4: ='M-TipoMulta'!B3 -> nombre | B4: ='M-TipoMulta'!B2 -> Representa el nombre del tipo de multa | C4: No | D4: Alfanumérico | E4: Si | F4: 4 | G4: 50 | H4: No aplica | I4: No aplica | J4: No aplica | K4: No aplica | L4: No aplica | M4: No aplica | N4: No | O4: No | P4: No aplica | Q4: Si | R4: Si | S4: No | T4: Vacio | U4: No | V4: Mostrar
A5: ='M-TipoMulta'!C3 -> descripcion | B5: ='M-TipoMulta'!C2 -> Representa que hace cada tipo de multa | C5: No | D5: Alfanumérico | E5: Si | F5: 10 | G5: 300 | H5: No aplica | I5: No aplica | J5: No aplica | K5: No aplica | L5: No aplica | M5: No aplica | N5: No | O5: No | P5: No aplica | Q5: Si | R5: Si | S5: No | T5: Vacio | U5: No | V5: Mostrar
A7: Nombre combinación única | B7: Descripción | C7: Atributos involucrados
A8: ='M-TipoMulta'!D3 -> Combinación única | B8: ='M-TipoMulta'!D2 -> Combinación única indica que no puede existir más de un tipo de multa con el mismo nombre | C8: nombre
A10: Responsabilidad | C10: Descripción | G10: Entradas | J10: Salida | O10: Políticas (Reglas de Negocio) | Q10: Excepción
G11: Parámetro | H11: Tipo de dato | I11: Descripción | J11: Tipo de Dato | K11: Descripción | O11: Política | P11: Descripción | Q11: Detalle | R11: ¿Qué hago?
A12: consultarTodosLosTiposMulta | C12: Permite consultar los tipos de multa que puede recibir un cliente | J12: Lista<TipoMulta> | K12: Contiene todos los tipos de multa que hay

Sheet P-TipoMulta
A1: << Ir al modelo de dominio | B1: << Ir al listado de objetos de dominio | C1: << Ir a la caracterización del objeto de dominio | D1: Ir al muestreo de datos del objeto de dominio >> | E1: Ir al event storming del objeto de dominio >>
A2: Objeto de Dominio: | B2: ='Objetos de Dominio'!A8 -> TipoMulta
A3: Descripción: | B3: ='Objetos de Dominio'!B8 -> Representa los tipos de multa que puede recibir un cliente: por tardanza o por inasistencia.
A4: Numero politica | B4: Descripcion politica | D4: Objeto responsable | E4: Regla responsable
B6: No aplica: es un catálogo de solo lectura, sin comandos que impliquen políticas de negocio propias

Sheet E-TipoMulta
A1: << Ir al modelo de dominio | C1: << Ir al listado de objetos de dominio | F1: << Ir a la caracterización del objeto de dominio | J1: Ir al muestreo de datos del objeto de dominio >>
A2: Objeto de Dominio: | B2: ='Objetos de Dominio'!A8 -> TipoMulta
A3: Descripción: | B3: ='Objetos de Dominio'!B8 -> Representa los tipos de multa que puede recibir un cliente: por tardanza o por inasistencia.
A4: Actor | B4: Action/Command | D4: Entity/Aggregate/Object domain | E4: Read Model | G4: Business Rule/Policy | I4: External System | J4: Domain Event | K4: Hotspot/questions/Risk
A5: Actor | B5: Acción | C5: Descripción | D5: Objeto de dominio | E5: Información externa | G5: Políticas | I5: Sistema Externo | J5: Evento | K5: Aspectos por solucionar
E6: Información | F6: Descripción | G6: Número | H6: Descripción
A7: Administrador | B7: Ver tipos de multa | C7: Permite consultar los tipos de multa que puede recibir un cliente | D7: =$B$2 -> TipoMulta | J7: Tipos de multa consultados
A8: Barbero | B8: Ver tipos de multa | C8: Permite consultar los tipos de multa que puede recibir un cliente | D8: =$B$2 -> TipoMulta | J8: Tipos de multa consultados
A9: Cliente | B9: Ver tipos de multa | C9: Permite consultar los tipos de multa que puede recibir un cliente | D9: =$B$2 -> TipoMulta | J9: Tipos de multa consultados

Sheet M-TipoMulta
A1: <<<< Ir al modulo de dominio | B1: <<<< Ir a objetos de dominio
A2: Representa un identificador que hará unico cada objeto de dominio de este tipo, no se puede repetir | B2: Representa el nombre del tipo de multa | C2: Representa que hace cada tipo de multa | D2: Combinación única indica que no puede existir más de un tipo de multa con el mismo nombre
A3: id | B3: nombre | C3: descripcion | D3: Combinación única
A4: 1 | B4: Tardanza | C4: El cliente llegó a la cita después de la hora acordada, superando los minutos de tiempoEspera definidos en la cita. | D4: =B4 -> Tardanza
A5: 2 | B5: Inasistencia | C5: El cliente no se presentó a la cita agendada: se llegó a la hora estimada de finalización sin que hubiera registrado su llegada. | D5: =B5 -> Inasistencia
B11: Corresponde a la descripcion de los atributos
B12: Corresponde al identificador unico del objeto de dominio
B13: Corresponde a los datos del objeto de dominio
B14: Corresponde a la combinacion única

Sheet C-TipoRegistroHora
A1: <<<< Ir al modulo de dominio | B1: <<<< Ir a objetos de dominio
A2: Nombre atributo | B2: Descripción atributo | C2: Identificador del objeto de dominio | D2: Tipo de dato | E2: Obligatorio | F2: Longitud mínima (si aplica) | G2: Longitud máxima (si aplica) | H2: Precisión (si aplica) | I2: Rendondeo (si aplica) | J2: Rango inicial (si aplica) | K2: Rango final (si aplica) | L2: Formato (si aplica) | M2: Reglas especiales (si aplica) | N2: Dato calculado | O2: Aplica ajuste del dato (si aplica) | P2: Carácter de ajuste (si aplica) | Q2: Quitar espacios en blanco al inicio (si aplica) | R2: Quitar espacios en blanco al fin (si aplica) | S2: Dato sensible (si aplica) | T2: Valor por defecto (si aplica) | U2: Auto generado | V2: =A11 -> consultarTiposRegistroHora
A3: ='M-TipoRegistroHora'!A3 -> id | B3: ='M-TipoRegistroHora'!A2 -> Representa un identificador que hará unico cada objeto de dominio de este tipo, no se puede repetir | C3: Si | D3: Identificador único universal | E3: Si | F3: No aplica | G3: No aplica | H3: No aplica | I3: No aplica | J3: No aplica | K3: No aplica | L3: No aplica | M3: No aplica | N3: No | O3: No aplica | P3: No aplica | Q3: No aplica | R3: No aplica | S3: No | T3: UUID vacio | U3: Si | V3: No mostrar
A4: ='M-TipoRegistroHora'!B3 -> nombre | B4: ='M-TipoRegistroHora'!B2 -> Representa el nombre del tipo de hora real que se puede registrar durante una cita | C4: No | D4: Alfanumérico | E4: Si | F4: 15 | G4: 20 | H4: No aplica | I4: No aplica | J4: No aplica | K4: No aplica | L4: No aplica | M4: Permite los caracteres de la 'a' a la 'z', incluidas mayusculas, espacios en blanco y todas las letras con tilde | N4: No | O4: No aplica | P4: No aplica | Q4: Si | R4: Si | S4: No | T4: Vacio | U4: No | V4: Mostrar
A6: Nombre combinación única | B6: Descripción | C6: Atributos involucrados
A7: ='M-TipoRegistroHora'!C3 -> Combinación única | B7: ='M-TipoRegistroHora'!C2 -> Combinación única que indica que no puede existir más de un tipo de registro de hora con el mismo nombre | C7: =A4 -> nombre
A9: Responsabilidad | C9: Descripción | G9: Entradas | J9: Salida | O9: Políticas (Reglas de Negocio) | Q9: Excepción
G10: Parámetro | H10: Tipo de dato | I10: Descripción | J10: Tipo de Dato | K10: Descripción | O10: Política | P10: Descripción | Q10: Detalle | R10: ¿Qué hago?
A11: consultarTiposRegistroHora | C11: Permite consultar el catálogo de tipos de registro de hora de una cita | J11: Lista<TipoRegistroHora> | K11: Contiene todos los tipos de registro de hora

Sheet P-TipoRegistroHora
A1: << Ir al modelo de dominio | B1: << Ir al listado de objetos de dominio | C1: << Ir a la caracterización del objeto de dominio | D1: Ir al muestreo de datos del objeto de dominio >> | E1: Ir al event storming del objeto de dominio >>
A2: Objeto de Dominio: | B2: ='Objetos de Dominio'!A9 -> TipoRegistroHora
A3: Descripción: | B3: ='Objetos de Dominio'!B9 -> Representa el catálogo de los distintos momentos en que se puede registrar una hora real durante una cita: llegada del cliente, barbero preparado, inicio y fin de la atención.
A4: Numero politica | B4: Descripcion politica | D4: Objeto responsable | E4: Regla responsable
B6: No aplica: es un catálogo de solo lectura, sin comandos que impliquen políticas de negocio propias

Sheet E-TipoRegistroHora
A1: << Ir al modelo de dominio | C1: << Ir al listado de objetos de dominio | F1: << Ir a la caracterización del objeto de dominio | J1: Ir al muestreo de datos del objeto de dominio >>
A2: Objeto de Dominio: | B2: ='Objetos de Dominio'!A9 -> TipoRegistroHora
A3: Descripción: | B3: ='Objetos de Dominio'!B9 -> Representa el catálogo de los distintos momentos en que se puede registrar una hora real durante una cita: llegada del cliente, barbero preparado, inicio y fin de la atención.
A4: Actor | B4: Action/Command | D4: Entity/Aggregate/Object domain | E4: Read Model | G4: Business Rule/Policy | I4: External System | J4: Domain Event | K4: Hotspot/questions/Risk
A5: Actor | B5: Acción | C5: Descripción | D5: Objeto de dominio | E5: Información externa | G5: Políticas | I5: Sistema Externo | J5: Evento | K5: Aspectos por solucionar
E6: Información | F6: Descripción | G6: Número | H6: Descripción
A7: Sistema | B7: Ver tipos de registro de hora para la cita | C7: Permite consultar el catálogo de tipos de registro de hora de una cita (llegada del cliente, barbero preparado, inicio y fin de la atención) | D7: =$B$2 -> TipoRegistroHora | J7: Tipos de registro de hora consultados
A8: Barbero | B8: Ver tipos de registro de hora para la cita | C8: Permite consultar el catálogo de tipos de registro de hora de una cita (llegada del cliente, barbero preparado, inicio y fin de la atención) | D8: =$B$2 -> TipoRegistroHora | J8: Tipos de registro de hora consultados

Sheet M-TipoRegistroHora
A1: <<<< Ir al modulo de dominio | B1: <<<< Ir a objetos de dominio
A2: Representa un identificador que hará unico cada objeto de dominio de este tipo, no se puede repetir | B2: Representa el nombre del tipo de hora real que se puede registrar durante una cita | C2: Combinación única que indica que no puede existir más de un tipo de registro de hora con el mismo nombre
A3: id | B3: nombre | C3: Combinación única
A4: 1 | B4: Llegada del cliente | C4: =B4 -> Llegada del cliente
A5: 2 | B5: Barbero preparado | C5: =B5 -> Barbero preparado
A6: 3 | B6: Inicio de atención | C6: =B6 -> Inicio de atención
A7: 4 | B7: Fin de atención | C7: =B7 -> Fin de atención
B13: Corresponde a la descripcion de los atributos
B14: Corresponde al identificador unico del objeto de dominio
B15: Corresponde a los datos del objeto de dominio
B16: Corresponde a la combinacion única

Sheet C-Cliente
A1: <<<< Ir al modulo de dominio | B1: <<<< Ir a objetos de dominio
A2: Nombre atributo | B2: Descripción atributo | C2: Identificador del objeto de dominio | D2: Tipo de dato | E2: Obligatorio | F2: Longitud mínima (si aplica) | G2: Longitud máxima (si aplica) | H2: Precisión (si aplica) | I2: Rendondeo (si aplica) | J2: Rango inicial (si aplica) | K2: Rango final (si aplica) | L2: Formato (si aplica) | M2: Reglas especiales (si aplica) | N2: Dato calculado | O2: Aplica ajuste del dato (si aplica) | P2: Carácter de ajuste (si aplica) | Q2: Quitar espacios en blanco al inicio (si aplica) | R2: Quitar espacios en blanco al fin (si aplica) | S2: Dato sensible (si aplica) | T2: Valor por defecto (si aplica) | U2: Auto generado | V2: =A21 -> registrarCliente | W2: =A23 -> editarContactoCliente | Y2: =A26 -> consultarDatosCliente | Z2: =A27 -> consultarEstadoVetoCliente | AA2: =A28 -> consultarCantidadMultasSinPagar | AB2: =A29 -> vetarCliente | AD2: =A31 -> quitarVetoCliente
A3: ='M-Cliente'!A3 -> id | B3: ='M-Cliente'!A2 -> Representa un identificador que hará unico cada objeto de dominio de este tipo, no se puede repetir | C3: Si | D3: Identificador único universal | E3: Si | F3: No aplica | G3: No aplica | H3: No aplica | I3: No aplica | J3: No aplica | K3: No aplica | L3: No aplica | M3: No aplica | N3: Si | O3: No | P3: No aplica | Q3: No aplica | R3: No aplica | S3: No | T3: UUID vacio | U3: Si | V3: No requerido | W3: Requerido | X3: No modificable | Y3: No mostrar | Z3: No mostrar | AA3: No mostrar | AB3: Requerido | AC3: No modificable | AD3: Requerido | AE3: No modificable
A4: ='M-Cliente'!B3 -> primerNombre | B4: ='M-Cliente'!B2 -> Representa el primer nombre de la persona, que va a estar llendo a la barberia para las citas | C4: No | D4: Alfanumérico | E4: Si | F4: 3 | G4: 50 | H4: No aplica | I4: No aplica | J4: No aplica | K4: No aplica | L4: No aplica | M4: Solo se aceptan caracteres de letras de la 'a' a la 'z', caracteres con tilde y numeros del 0 al 9 | N4: No | O4: No | P4: No | Q4: Si | R4: Si | S4: No | T4: Vacio | U4: No | V4: Requerido | W4: No requerido | X4: No modificable | Y4: Mostrar | Z4: No mostrar | AA4: No mostrar | AB4: No requerido | AC4: No modificable | AD4: No requerido | AE4: No modificable
A5: ='M-Cliente'!C3 -> segundoNombre | B5: ='M-Cliente'!C2 -> Representa el segundo nombre de la persona, que va a estar llendo a la barberia para las citas | C5: No | D5: Alfanumérico | E5: No | F5: 0 | G5: 50 | H5: No aplica | I5: No aplica | J5: No aplica | K5: No aplica | L5: No aplica | M5: Solo se aceptan caracteres de letras de la 'a' a la 'z', caracteres con tilde y numeros del 0 al 9 | N5: No | O5: No | P5: No | Q5: Si | R5: Si | S5: No | T5: Vacio | U5: No | V5: No requerido | W5: No requerido | X5: No modificable | Y5: Mostrar | Z5: No mostrar | AA5: No mostrar | AB5: No requerido | AC5: No modificable | AD5: No requerido | AE5: No modificable
A6: ='M-Cliente'!D3 -> primerApellido | B6: ='M-Cliente'!D2 -> Representa el primer apellido de la persona, que va a estar llendo a la barberia para las citas | C6: No | D6: Alfanumérico | E6: Si | F6: 3 | G6: 50 | H6: No aplica | I6: No aplica | J6: No aplica | K6: No aplica | L6: No aplica | M6: Solo se aceptan caracteres de letras de la 'a' a la 'z', caracteres con tilde y numeros del 0 al 9 | N6: No | O6: No | P6: No | Q6: Si | R6: Si | S6: No | T6: Vacio | U6: No | V6: Requerido | W6: No requerido | X6: No modificable | Y6: Mostrar | Z6: No mostrar | AA6: No mostrar | AB6: No requerido | AC6: No modificable | AD6: No requerido | AE6: No modificable
A7: ='M-Cliente'!E3 -> segundoApellido | B7: ='M-Cliente'!E2 -> Representa el segundo apellido de la persona, que va a estar llendo a la barberia para las citas | C7: No | D7: Alfanumérico | E7: No | F7: 0 | G7: 50 | H7: No aplica | I7: No aplica | J7: No aplica | K7: No aplica | L7: No aplica | M7: Solo se aceptan caracteres de letras de la 'a' a la 'z', caracteres con tilde y numeros del 0 al 9 | N7: No | O7: No | P7: No | Q7: Si | R7: Si | S7: No | T7: Vacio | U7: No | V7: No requerido | W7: No requerido | X7: No modificable | Y7: Mostrar | Z7: No mostrar | AA7: No mostrar | AB7: No requerido | AC7: No modificable | AD7: No requerido | AE7: No modificable
A8: ='M-Cliente'!F3 -> prefijoCelular | B8: ='M-Cliente'!F2 -> Representa cual es el prefijo del numero de celular del cliente | C8: No | D8: PrefijoCelular | E8: Si | F8: No aplica | G8: No aplica | H8: No aplica | I8: No aplica | J8: No aplica | K8: No aplica | L8: No aplica | M8: Aplican las reglas del objeto referenciado | N8: No | O8: No aplica | P8: No aplica | Q8: No aplica | R8: No aplica | S8: No | T8: UUID vacio | U8: No | V8: Requerido | W8: Requerido | X8: Modificable | Y8: Mostrar | Z8: No mostrar | AA8: No mostrar | AB8: No requerido | AC8: No modificable | AD8: No requerido | AE8: No modificable
A9: ='M-Cliente'!G3 -> celular | B9: ='M-Cliente'!G2 -> Representa el numero de celular del cliente, es el dato que el barbero necesita en caso de que tenga que contactarse con el | C9: No | D9: Alfanumérico | E9: Si | F9: 6 | G9: 15 | H9: No aplica | I9: No aplica | J9: No aplica | K9: No aplica | L9: No aplica | M9: Solo se aceptan caracteres de numeros del '0' al '9' | N9: No | O9: No aplica | P9: No aplica | Q9: Si | R9: Si | S9: Si | T9: 0 | U9: No | V9: Requerido | W9: Requerido | X9: Modificable | Y9: Mostrar | Z9: No mostrar | AA9: No mostrar | AB9: No requerido | AC9: No modificable | AD9: No requerido | AE9: No modificable
A10: ='M-Cliente'!H3 -> elNumeroCelularEsCorrecto | B10: ='M-Cliente'!H2 -> Representa si el numero que ingreso el cliente es correcto o no | C10: No | D10: Lógico | E10: Si | F10: No aplica | G10: No aplica | H10: No aplica | I10: No aplica | J10: No aplica | K10: No aplica | L10: No aplica | M10: No aplica | N10: No | O10: No aplica | P10: No aplica | Q10: No aplica | R10: No aplica | S10: No | T10: No | U10: No | V10: No requerido | W10: No requerido | X10: Modificable | Y10: Mostrar | Z10: No mostrar | AA10: No mostrar | AB10: No requerido | AC10: No modificable | AD10: No requerido | AE10: No modificable
A11: ='M-Cliente'!I3 -> estaVetado | B11: ='M-Cliente'!I2 -> Representa si el cliente esta en estado de veto o no, cuando el cliente esta vetado el sistema no va a permitir agendar citas con este cliente con ningun barbero | C11: No | D11: Lógico | E11: Si | F11: No aplica | G11: No aplica | H11: No aplica | I11: No aplica | J11: No aplica | K11: No aplica | L11: No aplica | M11: Se calcula a partir de multasSinPagar: basta con una multa sin pagar para que el cliente quede vetado y no pueda agendar; deja de estarlo en el momento en que la paga | N11: Si | O11: No | P11: No aplica | Q11: No aplica | R11: No aplica | S11: No | T11: No | U11: No | V11: No requerido | W11: No requerido | X11: No modificable | Y11: Mostrar | Z11: Mostrar | AA11: No mostrar | AB11: No requerido | AC11: Modificable | AD11: No requerido | AE11: Modificable
A13: Nombre combinación única | B13: Descripción | C13: Atributos involucrados
