Workbook

Sheet Modelo de Dominio
A1: Ir a objetos de dominio >>>>

Sheet Objetos de Dominio
A1: <<<< Ir al modulo de dominio
A2: Nombre | B2: Descripcion | C2: Linea de vida | D2: Muestreo | E2: Caracterización | F2: Event Storming | G2: Politicas
A3: DiaSemana | B3: Representa cada uno de los días de la semana, incluyendo festivo, que se usa como catálogo para definir los horarios de la barbería y de cada barbero. | C3: 1 | D3: Ir al muestreo | E3: Ir a la caracterización | F3: Ir al Event Storming | G3: Ir a las políticas
A4: Estado | B4: Representa en qué situación puntual se encuentra una cita: agendada, finalizada, cancelada por alguna de las partes, con tardanza del cliente o del barbero, o con inasistencia del cliente. | C4: 1 | D4: Ir al muestreo | E4: Ir a la caracterización | F4: Ir al Event Storming | G4: Ir a las políticas
A5: Servicio | B5: Representa cada tipo de corte o arreglo que ofrece la barbería, definido por el dueño, para que luego cada barbero decida cuáles sabe hacer. | C5: 1 | D5: Ir al muestreo | E5: Ir a la caracterización | F5: Ir al Event Storming | G5: Ir a las políticas
A6: PrefijoCelular | B6: Representa el catálogo de prefijos telefónicos de país que el dueño habilita, y que son los únicos que barberos y clientes pueden usar en su número de celular. | C6: 1 | D6: Ir al muestreo | E6: Ir a la caracterización | F6: Ir al Event Storming | G6: Ir a las políticas
A7: TipoMulta | B7: Representa los tipos de multa que puede recibir un cliente: por tardanza o por inasistencia. | C7: 1 | D7: Ir al muestreo | E7: Ir a la caracterización | F7: Ir al Event Storming | G7: Ir a las políticas
A8: Barbero | B8: Representa a un trabajador de la barbería que atiende clientes según los servicios que sabe realizar, organiza su propio horario y tiene su agenda personal para atender todas las citas que valla teniendo. | C8: 2 | D8: Ir al muestreo | E8: Ir a la caracterización | F8: Ir al Event Storming | G8: Ir a las políticas
A9: Cliente | B9: Representa a la persona que solicita citas en la barbería. | C9: 2 | D9: Ir al muestreo | E9: Ir a la caracterización | F9: Ir al Event Storming | G9: Ir a las políticas
A10: HorarioBarberia | B10: Representa, día por día, a qué hora abre y cierra el negocio; es el límite dentro del cual debe caber el horario de cualquier barbero. | C10: 2 | D10: Ir al muestreo | E10: Ir a la caracterización | F10: Ir al Event Storming | G10: Ir a las políticas
A11: Bloqueo | B11: Representa los momentos en que el barbero no esta disponible para atender sus citas, el barbero establece la hora y la fecha en que empieza y termina ese estado de no disponible. | C11: 3 | D11: Ir al muestreo | E11: Ir a la caracterización | F11: Ir al Event Storming | G11: Ir a las políticas
A12: BarberoServicio | B12: Representa qué servicios sabe hacer cada barbero, cuánto se demora en realizarlos y cuánto tiempo extra usa de colchón, ya que no todos los barberos ofrecen los mismos servicios que están en la barbería. | C12: 3 | D12: Ir al muestreo | E12: Ir a la caracterización | F12: Ir al Event Storming | G12: Ir a las políticas
A13: HorarioBarbero | B13: Representa el día de la semana en que trabaja un barbero, junto con la hora en la que empieza y termina su jornada de trabajo. | C13: 3 | D13: Ir al muestreo | E13: Ir a la caracterización | F13: Ir al Event Storming | G13: Ir a las políticas
A14: Agenda | B14: Representa una fecha puntual en donde el barbero ve todas las citas que debe de atender ese día. | C14: 4 | D14: Ir al muestreo | E14: Ir a la caracterización | F14: Ir al Event Storming | G14: Ir a las políticas
... A17: Multa | B17: Representa la sanción económica que se le impone a un cliente por incumplir una cita, ya sea por llegar tarde fuera de tolerancia o por no presentarse, calculada a partir de la cita específica que la originó. | C17: 6 | D17: Ir al muestreo | E17: Ir a la caracterización | F17: Ir al Event Storming | G17: Ir a las políticas

Sheet C-DiaSemana
A1: <<<< Ir al modulo de dominio | B1: <<<< Ir a objetos de dominio
A2: Nombre atributo | B2: Descripción atributo | C2: Identificador del objeto de dominio | D2: Tipo de dato | E2: Obligatorio | F2: Longitud mínima (si aplica) | G2: Longitud máxima (si aplica) | H2: Precisión (si aplica) | I2: Rendondeo (si aplica) | J2: Rango inicial (si aplica) | K2: Rango final (si aplica) | L2: Formato (si aplica) | M2: Reglas especiales (si aplica) | N2: Dato calculado | O2: Aplica ajuste del dato (si aplica) | P2: Carácter de ajuste (si aplica) | Q2: Quitar espacios en blanco al inicio (si aplica) | R2: Quitar espacios en blanco al fin (si aplica) | S2: Dato sensible (si aplica) | T2: Valor por defecto (si aplica) | U2: Auto generado | V2: =A11 -> VerDiasDeLaSemana
A3: ='M-DiaSemana'!A3 -> id | B3: ='M-DiaSemana'!A2 -> Representa un identificador que hará unico cada objeto de dominio de este tipo, no se puede repetir | C3: Si | D3: Identificador único universal | E3: Si | F3: No aplica | G3: No aplica | H3: No aplica | I3: No aplica | J3: No aplica | K3: No aplica | L3: No aplica | M3: No aplica | N3: No | O3: No aplica | P3: No aplica | Q3: No aplica | R3: No aplica | S3: No | T3: UUID vacio | U3: Si | V3: No mostrar
A4: ='M-DiaSemana'!B3 -> nombre | B4: ='M-DiaSemana'!B2 -> Representa como se llama el dia de la semana, para los horarios | C4: No | D4: Alfanumérico | E4: Si | F4: 5 | G4: 9 | H4: No aplica | I4: No aplica | J4: No aplica | K4: No aplica | L4: No aplica | M4: Solo pueden ser los dias de la semana como Lunes, Martes, Miércoles, Jueves, Viernes, Sábado, Domingo y Festivo | N4: No | O4: No aplica | P4: No aplica | Q4: Si | R4: Si | S4: No | T4: Vacio | U4: No | V4: Mostrar
A6: Nombre combinación única | B6: Descripción | C6: Atributos involucrados
A7: ='M-DiaSemana'!C3 -> Combinación única | B7: ='M-DiaSemana'!C2 -> Combinacion única que indica que no puede existir más un dia de la semana con el mismo nombre | C7: nombre
A9: Responsabilidad | C9: Descripción | G9: Entradas | J9: Salida | O9: Políticas (Reglas de Negocio) | Q9: Excepción
G10: Parámetro | H10: Tipo de dato | I10: Descripción | J10: Tipo de Dato | K10: Descripción | O10: Política | P10: Descripción | Q10: Detalle | R10: ¿Qué hago?
A11: VerDiasDeLaSemana | C11: Permite consultar el catálogo de días de la semana, incluyendo festivo, para definir los horarios | J11: Lista<DiaSemana> | K11: Contiene todos los días de la semana

Sheet P-DiaSemana
A1: << Ir al modelo de dominio | B1: << Ir al listado de objetos de dominio | C1: << Ir a la caracterización del objeto de dominio | D1: Ir al muestreo de datos del objeto de dominio >> | E1: Ir al event storming del objeto de dominio >>
A2: Objeto de Dominio: | B2: ='Objetos de Dominio'!A3 -> DiaSemana
A3: Descripción: | B3: ='Objetos de Dominio'!B3 -> Representa cada uno de los días de la semana, incluyendo festivo, que se usa como catálogo para definir los horarios de la barbería y de cada barbero.
A4: Numero politica | B4: Descripcion politica | D4: Objeto responsable | E4: Regla responsable
B6: No aplica: es un catálogo de solo lectura, sin comandos que impliquen políticas de negocio propias

Sheet E-DiaSemana
A1: << Ir al modelo de dominio | C1: << Ir al listado de objetos de dominio | F1: << Ir a la caracterización del objeto de dominio | J1: Ir al muestreo de datos del objeto de dominio >>
A2: Objeto de Dominio: | B2: ='Objetos de Dominio'!A3 -> DiaSemana
A3: Descripción: | B3: ='Objetos de Dominio'!B3 -> Representa cada uno de los días de la semana, incluyendo festivo, que se usa como catálogo para definir los horarios de la barbería y de cada barbero.
A4: Actor | B4: Action/Command | D4: Entity/Aggregate/Object domain | E4: Read Model | G4: Business Rule/Policy | I4: External System | J4: Domain Event | K4: Hotspot/questions/Risk
A5: Actor | B5: Acción | C5: Descripción | D5: Objeto de dominio | E5: Información externa | G5: Políticas | I5: Sistema Externo | J5: Evento | K5: Aspectos por solucionar
E6: Información | F6: Descripción | G6: Número | H6: Descripción
A7: Dueño | B7: Ver los días de las semanas | C7: Permite consultar el catálogo de días de la semana, incluyendo festivo, disponibles para definir horarios | D7: =$B$2 -> DiaSemana | J7: Días de la semana consultados
A8: Barbero | B8: Ver los días de las semanas | C8: Permite consultar el catálogo de días de la semana, incluyendo festivo, disponibles para definir horarios | D8: =$B$2 -> DiaSemana | J8: Días de la semana consultados

Sheet M-DiaSemana
A1: <<<< Ir al modulo de dominio | B1: <<<< Ir a objetos de dominio
A2: Representa un identificador que hará unico cada objeto de dominio de este tipo, no se puede repetir | B2: Representa como se llama el dia de la semana, para los horarios | C2: Combinacion única que indica que no puede existir más un dia de la semana con el mismo nombre
A3: id | B3: nombre | C3: Combinación única
A4: 1 | B4: Lunes | C4: =B4 -> Lunes
A5: 2 | B5: Martes | C5: =B5 -> Martes
A6: 3 | B6: Miércoles | C6: =B6 -> Miércoles
A7: 4 | B7: Jueves | C7: =B7 -> Jueves
A8: 5 | B8: Viernes | C8: =B8 -> Viernes
A9: 6 | B9: Sábado | C9: =B9 -> Sábado
A10: 7 | B10: Domingo | C10: =B10 -> Domingo
A11: 8 | B11: Festivo | C11: =B11 -> Festivo
B17: Corresponde a la descripcion de los atributos
B18: Corresponde al identificador unico del objeto de dominio
B19: Corresponde a los datos que ingresa el usuario
B20: Corresponde a la combinacion única

Sheet C-Estado
A1: <<<< Ir al modulo de dominio | B1: <<<< Ir a objetos de dominio
A2: Nombre atributo | B2: Descripción atributo | C2: Identificador del objeto de dominio | D2: Tipo de dato | E2: Obligatorio | F2: Longitud mínima (si aplica) | G2: Longitud máxima (si aplica) | H2: Precisión (si aplica) | I2: Rendondeo (si aplica) | J2: Rango inicial (si aplica) | K2: Rango final (si aplica) | L2: Formato (si aplica) | M2: Reglas especiales (si aplica) | N2: Dato calculado | O2: Aplica ajuste del dato (si aplica) | P2: Carácter de ajuste (si aplica) | Q2: Quitar espacios en blanco al inicio (si aplica) | R2: Quitar espacios en blanco al fin (si aplica) | S2: Dato sensible (si aplica) | T2: Valor por defecto (si aplica) | U2: Auto generado | V2: =A12 -> consultarTodosLosEstados | W2: =A13 -> editarDescripcion | X2: 'C-Estado'!A13 | Y2: =A15 -> consultarDescripcion
A3: ='M-Estado'!A3 -> id | B3: ='M-Estado'!A2 -> Representa un identificador que hará unico cada objeto de dominio de este tipo, no se puede repetir | C3: Si | D3: Identificador único universal | E3: Si | F3: No aplica | G3: No aplica | H3: No aplica | I3: No aplica | J3: No aplica | K3: No aplica | L3: No aplica | M3: No aplica | N3: No | O3: No aplica | P3: No aplica | Q3: No aplica | R3: No aplica | S3: No aplica | T3: UUID vacio | U3: Si | V3: No mostrar | W3: Requerido | X3: No modificable | Y3: No mostrar
A4: ='M-Estado'!B3 -> nombre | B4: ='M-Estado'!B2 -> Representa como se llama el estado en el que se encuentra una cita puntual | C4: No | D4: Alfanumérico | E4: Si | F4: 4 | G4: 50 | H4: No aplica | I4: No aplica | J4: No aplica | K4: No aplica | L4: No aplica | M4: Solo se aceptan caracteres de letras de la 'a' a la 'z' y espacios en blanco | N4: No | O4: No aplica | P4: No aplica | Q4: Si | R4: Si | S4: No | T4: Vacio | U4: No | V4: Mostrar | W4: No requerido | X4: No modificable | Y4: No mostrar
A5: ='M-Estado'!C3 -> descripcion | B5: ='M-Estado'!C2 -> Representa el significado de que representa cada estado para la cita | C5: No | D5: Alfanumérico | E5: Si | F5: 10 | G5: 300 | H5: No aplica | I5: No aplica | J5: No aplica | K5: No aplica | L5: No aplica | M5: Solo se aceptan caracteres de letras de la 'a' a la 'z', caracteres con tilde y espacios en blanco | N5: No | O5: No aplica | P5: No aplica | Q5: Si | R5: Si | S5: No | T5: Vacio | U5: No | V5: No mostrar | W5: Requerido | X5: Modificable | Y5: Mostrar
A7: Nombre combinación única | B7: Descripción | C7: Atributos involucrados
A8: ='M-Estado'!D3 -> Combinación única | B8: ='M-Estado'!D2 -> Combinacion única que indica que no puede existir más un dia de la semana con el mismo nombre | C8: nombre
A10: Responsabilidad | C10: Descripción | G10: Entradas | J10: Salida | O10: Políticas (Reglas de Negocio) | Q10: Excepción
G11: Parámetro | H11: Tipo de dato | I11: Descripción | J11: Tipo de Dato | K11: Descripción | O11: Política | P11: Descripción | Q11: Detalle | R11: ¿Qué hago?
A12: consultarTodosLosEstados | C12: Permite consultar los estados posibles que puede tener una cita | J12: Lista<Estado> | K12: Contiene todos los estados que cumplen con el filtro enviado
A13: editarDescripcion | C13: Permite ajustar el texto descriptivo de un estado ya creado, sin cambiar su significado en el flujo de la cita | G13: id | H13: UUID | I13: Corresponde al identificador del estado que se va a editar | K13: La descripcion del estado se editó | O13: ='P-Estado'!A7 -> P-EST-0002 | P13: ='P-Estado'!B7 -> Asegurar que exista el estado con el id enviado | Q13: Informar con un mensaje que no existe un estado con el identificador enviado y por lo tanto no es posible modificar la descripción | R13: Detener ejecución de la operación
G14: datos{descripcion} | H14: Estado | I14: Contiene la nueva descripción del estado | O14: ='P-Estado'!A6 -> P-EST-0001 | P14: ='P-Estado'!B6 -> Asegurar que los datos requeridos (descripción) sean válidos en tipo de dato, longitud, formato y rango | Q14: Generar una excepción indicándole al usuario cuáles datos de la descripción del estado no cumplen con las reglas definidas | R14: Detener operación
A15: consultarDescripcion | C15: Permite consultar la descripcion de un estado en especifico | G15: datos{nombre} | H15: Estado | I15: Contiene el nombre del estado | J15: Alfanumérico | K15: Contiene la información del estado consultado por su identificador | O15: ='P-Estado'!A7 -> P-EST-0002 | P15: ='P-Estado'!B7 -> Asegurar que exista el estado con el id enviado | Q15: Informar con un mensaje que no existe un Estado con el identificador enviado y por lo tanto no es posible modificar la descripción | R15: Detener ejecución de la operación

Sheet P-Estado
A1: << Ir al modelo de dominio | B1: << Ir al listado de objetos de dominio | C1: << Ir a la caracterización del objeto de dominio | D1: Ir al muestreo de datos del objeto de dominio >> | E1: Ir al event storming del objeto de dominio >>
A2: Objeto de Dominio: | B2: ='Objetos de Dominio'!A4 -> Estado
A3: Descripción: | B3: ='Objetos de Dominio'!B4 -> Representa en qué situación puntual se encuentra una cita: agendada, finalizada, cancelada por alguna de las partes, con tardanza del cliente o del barbero, o con inasistencia del cliente.
A4: Numero politica | B4: Descripcion politica | D4: Objeto responsable | E4: Regla responsable
A6: P-EST-0001 | B6: Asegurar que los datos requeridos (descripción) sean válidos en tipo de dato, longitud, formato y rango | D6: Estado
A7: P-EST-0002 | B7: Asegurar que exista el estado con el id enviado | D7: Estado

Sheet E-Estado
A1: << Ir al modelo de dominio | C1: << Ir al listado de objetos de dominio | F1: << Ir a la caracterización del objeto de dominio | J1: Ir al muestreo de datos del objeto de dominio >>
A2: Objeto de Dominio: | B2: ='Objetos de Dominio'!A4 -> Estado
A3: Descripción: | B3: ='Objetos de Dominio'!B4 -> Representa en qué situación puntual se encuentra una cita: agendada, finalizada, cancelada por alguna de las partes, con tardanza del cliente o del barbero, o con inasistencia del cliente.
A4: Actor | B4: Action/Command | D4: Entity/Aggregate/Object domain | E4: Read Model | G4: Business Rule/Policy | I4: External System | J4: Domain Event | K4: Hotspot/questions/Risk
A5: Actor | B5: Acción | C5: Descripción | D5: Objeto de dominio | E5: Información externa | G5: Políticas | I5: Sistema Externo | J5: Evento | K5: Aspectos por solucionar
E6: Información | F6: Descripción | G6: Número | H6: Descripción
A7: Dueño | B7: Ver estados de las citas | C7: Permite consultar los estados posibles que puede tener una cita | D7: =$B$2 -> Estado | J7: Estados consultados
A8: Barbero | B8: Ver estados de las citas | C8: Permite consultar los estados posibles que puede tener una cita | D8: =$B$2 -> Estado | J8: Estados consultados
A9: Cliente | B9: Ver estados de las citas | C9: Permite consultar los estados posibles que puede tener una cita | D9: =$B$2 -> Estado | J9: Estados consultados
A10: Dueño | B10: Editar descripción del estado | C10: Permite ajustar el texto descriptivo de un estado ya creado, sin cambiar su significado en el flujo de la cita | D10: =$B$2 -> Estado | G10: ='P-Estado'!A6 -> P-EST-0001 | H10: ='P-Estado'!B6 -> Asegurar que los datos requeridos (descripción) sean válidos en tipo de dato, longitud, formato y rango | J10: Descripción de estado actualizada
A11: Dueño | B11: Ver descripcion de un estado | C11: Permite consultar la descripcion de un estado en especifico | D11: =$B$2 -> Estado | J11: Descripción del estado consultada
A12: Barbero | B12: Ver descripcion de un estado | C12: Permite consultar la descripcion de un estado en especifico | D12: =$B$2 -> Estado | J12: Descripción del estado consultada
A13: Cliente | B13: Ver descripcion de un estado | C13: Permite consultar la descripcion de un estado en especifico | D13: =$B$2 -> Estado | J13: Descripción del estado consultada

Sheet M-Estado
A1: <<<< Ir al modulo de dominio | B1: <<<< Ir a objetos de dominio
A2: Representa un identificador que hará unico cada objeto de dominio de este tipo, no se puede repetir | B2: Representa como se llama el estado en el que se encuentra una cita puntual | C2: Representa el significado de que representa cada estado para la cita | D2: Combinacion única que indica que no puede existir más un dia de la semana con el mismo nombre
A3: id | B3: nombre | C3: descripcion | D3: Combinación única
A4: 1 | B4: Agendada | C4: La cita quedó registrada en la agenda del barbero y está a la espera de la fecha y hora acordadas. | D4: =B4 -> Agendada
A5: 2 | B5: Finalizada | C5: El barbero atendió al cliente y el servicio contratado se prestó por completo, sin tener ninguna sanción. | D5: =B5 -> Finalizada
A6: 3 | B6: Cancelada por el cliente | C6: El cliente decidió no asistir y anuló la cita antes de la fecha y hora programada. | D6: =B6 -> Cancelada por el cliente
A7: 4 | B7: Cancelada por el barbero | C7: El barbero anuló la cita antes de la fecha y hora programada, por ejemplo por una eventualidad. | D7: =B7 -> Cancelada por el barbero
A8: 5 | B8: El cliente se demoro | C8: El cliente llegó después de la hora acordada superando el tiempoEspera definido en la cita, lo que genera una multa de tipo Tardanza. | D8: =B8 -> El cliente se demoro
A9: 6 | B9: El barbero se demoro | C9: El barbero se demoró más de lo previsto en una cita anterior y empezó a atender al cliente superando el tiempoEspera definido en la cita, lo que le da un descuento al cliente. | D9: =B9 -> El barbero se demoro
A10: 7 | B10: Inasistencia del cliente | C10: El cliente nunca llegó a la cita: se alcanzó la hora estimada de finalización sin registrar su llegada, lo que genera una multa por el valor total de los servicios pedidos. | D10: =B10 -> Inasistencia del cliente
A11: 8 | B11: Cancelación | C11: La cita se anuló automáticamente porque la barbería cambió sus políticas de horario: al desactivarse el horario de la barbería se desactivaron los horarios de barbero y las agendas que dependían de él, y las citas que quedaron por fuera se cancelaron. | D11: =B11 -> Cancelación
B17: Corresponde a la descripcion de los atributos
B18: Corresponde al identificador unico del objeto de dominio
B19: Corresponde a los datos que ingresa el usuario
B20: Corresponde a la combinacion única

Sheet C-Servicio
A1: <<<< Ir al modulo de dominio | B1: <<<< Ir a objetos de dominio
A2: Nombre atributo | B2: Descripción atributo | C2: Identificador del objeto de dominio | D2: Tipo de dato | E2: Obligatorio | F2: Longitud mínima (si aplica) | G2: Longitud máxima (si aplica) | H2: Precisión (si aplica) | I2: Rendondeo (si aplica) | J2: Rango inicial (si aplica) | K2: Rango final (si aplica) | L2: Formato (si aplica) | M2: Reglas especiales (si aplica) | N2: Dato calculado | O2: Aplica ajuste del dato (si aplica) | P2: Carácter de ajuste (si aplica) | Q2: Quitar espacios en blanco al inicio (si aplica) | R2: Quitar espacios en blanco al fin (si aplica) | S2: Dato sensible (si aplica) | T2: Valor por defecto (si aplica) | U2: Auto generado | V2: =A14 -> ofrecerServicioNuevo | W2: =A16 -> editarServicio | Y2: =A19 -> consultarServiciosDisponibles | Z2: =A20 -> retirarServicio
A3: ='M-Servicio'!A3 -> id | B3: ='M-Servicio'!A2 -> Representa un identificador que hará unico cada objeto de dominio de este tipo, no se puede repetir | C3: Si | D3: Identificador único universal | E3: Si | F3: No aplica | G3: No aplica | H3: No aplica | I3: No aplica | J3: No aplica | K3: No aplica | L3: No aplica | M3: No aplica | N3: No | O3: No aplica | P3: No aplica | Q3: No aplica | R3: No aplica | S3: No | T3: UUID vacio | U3: Si | V3: No requerido | W3: Requerido | X3: No modificable | Y3: No mostrar | Z3: Requerido
A4: ='M-Servicio'!B3 -> nombre | B4: ='M-Servicio'!B2 -> Representa el nombre del servicio que va estar en la barberia, para que el barbero elija los servicios que el sabe hacer | C4: No | D4: Alfanumérico | E4: Si | F4: 3 | G4: 50 | H4: No aplica | I4: No aplica | J4: No aplica | K4: No aplica | L4: No aplica | M4: Solo se aceptan caracteres de letras de la 'a' a la 'z' y caracteres con tilde | N4: No | O4: No aplica | P4: No aplica | Q4: Si | R4: Si | S4: No | T4: Vacio | U4: No | V4: Requerido | W4: Requerido | X4: Modificable | Y4: Mostrar | Z4: No requerido
A5: ='M-Servicio'!C3 -> descripcion | B5: ='M-Servicio'!C2 -> Representa una descripcion de que va a hacer cada servicio en la barberia, para que el barbero sepa que hace el servicio | C5: No | D5: Alfanumérico | E5: No | F5: 0 | G5: 200 | H5: No aplica | I5: No aplica | J5: No aplica | K5: No aplica | L5: No aplica | M5: Solo se aceptan caracteres de letras de la 'a' a la 'z', caracteres con tilde y espacios en blanco | N5: No | O5: No aplica | P5: No aplica | Q5: Si | R5: Si | S5: No | T5: Vacio | U5: No | V5: Requerido | W5: Requerido | X5: Modificable | Y5: Mostrar | Z5: No requerido
A6: ='M-Servicio'!D3 -> precio | B6: ='M-Servicio'!D2 -> Representa cuanto va a valer el servicio en pesos colombianos | C6: No | D6: Entero | E6: Si | F6: No aplica | G6: No aplica | H6: No aplica | I6: No aplica | J6: 0 | K6: 2000000 | L6: No aplica | M6: No aplica | N6: No | O6: No aplica | P6: No aplica | Q6: No aplica | R6: No aplica | S6: No | T6: 0 | U6: No | V6: Requerido | W6: Requerido | X6: Modificable | Y6: Mostrar | Z6: No requerido
A7: ='M-Servicio'!E3 -> disponible | B7: ='M-Servicio'!E2 -> Representa si el servicio sigue o no disponible en la barberia | C7: No | D7: Lógico | E7: Si | F7: No aplica | G7: No aplica | H7: No aplica | I7: No aplica | J7: No aplica | K7: No aplica | L7: No aplica | M7: No aplica | N7: No | O7: No aplica | P7: No aplica | Q7: No aplica | R7: No aplica | S7: No | T7: Si | U7: Si | V7: No requerido | W7: No requerido | X7: No modificable | Y7: No mostrar | Z7: No requerido
A9: Nombre combinación única | B9: Descripción | C9: Atributos involucrados
A10: ='M-Servicio'!F3 -> Combinacion única | B10: ='M-Servicio'!F2 -> Combinacion única que indica que no puede existir más de un servicio con el mismo nombre | C10: =A4 -> nombre
A12: Responsabilidad | C12: Descripción | G12: Entradas | J12: Salida | O12: Políticas (Reglas de Negocio) | Q12: Excepción
G13: Parámetro | H13: Tipo de dato | I13: Descripción | J13: Tipo de Dato | K13: Descripción | O13: Política | P13: Descripción | Q13: Detalle | R13: ¿Qué hago?
A14: ofrecerServicioNuevo | C14: Comando que permite registrar un nuevo tipo de servicio que la barbería pondrá a disposición de los barberos | G14: datos{nombre, descripcion, precio} | H14: Servicio | I14: Contiene la información requerida para registrar un nuevo servicio de la barbería | J14: Servicio | K14: Contiene la información del servicio registrado | O14: ='P-Servicio'!A6 -> P-SER-0001 | P14: ='P-Servicio'!B6 -> Asegurar que los datos requeridos del servicio (nombre, descripción, precio) sean válidos en tipo de dato, longitud, obligatoriedad, formato y rango | Q14: Generar una excepción indicándole al usuario cuáles datos del servicio no cumplen con las reglas definidas | R14: Detener operación
O15: ='P-Servicio'!A7 -> P-SER-0002 | P15: ='P-Servicio'!B7 -> Asegurar que no exista otro servicio registrado con el mismo nombre en la barbería | Q15: Generar una excepción indicándole al usuario que ya existe un servicio registrado con ese mismo nombre en la barbería | R15: Detener operación
A16: editarServicio | C16: Permite modificar todos los atibutos de un servicio, que son el nombre, la descripción y el precio | G16: id | H16: UUID | I16: Corresponde al identificador del servicio que se va a editar | J16: Servicio | K16: Contiene la información del servicio con sus datos actualizados | O16: ='P-Servicio'!A9 -> P-SER-0004 | P16: ='P-Servicio'!B9 -> Asegurar que exista el servicio con el id enviado | Q16: Informar con un mensaje que no existe un servicio con el identificador enviado y por lo tanto no es posible modificar el servicio | R16: Detener ejecución de la operación
G17: datos{nombre, descripcion, precio} | H17: Servicio | I17: Contiene los datos con los que se va a modificar el servicio | O17: ='P-Servicio'!A6 -> P-SER-0001 | P17: ='P-Servicio'!B6 -> Asegurar que los datos requeridos del servicio (nombre, descripción, precio) sean válidos en tipo de dato, longitud, obligatoriedad, formato y rango | Q17: Generar una excepción indicándole al usuario cuáles datos del servicio no cumplen con las reglas definidas | R17: Detener operación
O18: ='P-Servicio'!A7 -> P-SER-0002 | P18: ='P-Servicio'!B7 -> Asegurar que no exista otro servicio registrado con el mismo nombre en la barbería | Q18: Generar una excepción indicándole al usuario que ya existe un servicio registrado con ese mismo nombre en la barbería | R18: Detener operación
A19: consultarServiciosDisponibles | C19: Permite consultar el catálogo de servicios que ofrece la barbería | J19: Lista<Servicio> | K19: Contiene todos los servicios disponibles en la barberia
A20: retirarServicio | C20: Permite dar de baja un servicio para que deje de ofrecerse a nuevos clientes | G20: id | H20: UUID | I20: Corresponde al identificador del servicio que se va a retirar | K20: No retorna ningún valor. En caso de error genera una excepción. | O20: ='P-Servicio'!A8 -> P-SER-0003 | P20: ='P-Servicio'!B8 -> Asegurar que el servicio a retirar no esté siendo ofrecido actualmente por ningún barbero vigente | Q20: Generar una excepción indicándole al usuario que el servicio no se puede retirar porque todavía lo ofrece al menos un barbero vigente | R20: Detener operación
O21: ='P-Servicio'!A9 -> P-SER-0004 | P21: ='P-Servicio'!B9 -> Asegurar que exista el servicio con el id enviado | Q21: Informar con un mensaje que no existe un servicio con el identificador enviado y por lo tanto no es posible desactivar el servicio | R21: Detener operación

Sheet P-Servicio
A1: << Ir al modelo de dominio | B1: << Ir al listado de objetos de dominio | C1: << Ir a la caracterización del objeto de dominio | D1: Ir al muestreo de datos del objeto de dominio >> | E1: Ir al event storming del objeto de dominio >>
A2: Objeto de Dominio: | B2: ='Objetos de Dominio'!A5 -> Servicio
A3: Descripción: | B3: ='Objetos de Dominio'!B5 -> Representa cada tipo de corte o arreglo que ofrece la barbería, definido por el dueño, para que luego cada barbero decida cuáles sabe hacer.
A4: Numero politica | B4: Descripcion politica | D4: Objeto responsable | E4: Regla responsable
A6: P-SER-0001 | B6: Asegurar que los datos requeridos del servicio (nombre, descripción, precio) sean válidos en tipo de dato, longitud, obligatoriedad, formato y rango | D6: Servicio
A7: P-SER-0002 | B7: Asegurar que no exista otro servicio registrado con el mismo nombre en la barbería | D7: Servicio
A8: P-SER-0003 | B8: Asegurar que el servicio a retirar no esté siendo ofrecido actualmente por ningún barbero vigente | D8: BarberoServicio
A9: P-SER-0004 | B9: Asegurar que exista el servicio con el id enviado | D9: Servicio

Sheet E-Servicio
A1: << Ir al modelo de dominio | C1: << Ir al listado de objetos de dominio | F1: << Ir a la caracterización del objeto de dominio | J1: Ir al muestreo de datos del objeto de dominio >>
A2: Objeto de Dominio: | B2: ='Objetos de Dominio'!A5 -> Servicio
A3: Descripción: | B3: ='Objetos de Dominio'!B5 -> Representa cada tipo de corte o arreglo que ofrece la barbería, definido por el dueño, para que luego cada barbero decida cuáles sabe hacer.
A4: Actor | B4: Action/Command | D4: Entity/Aggregate/Object domain | E4: Read Model | G4: Business Rule/Policy | I4: External System | J4: Domain Event | K4: Hotspot/questions/Risk
A5: Actor | B5: Acción | C5: Descripción | D5: Objeto de dominio | E5: Información externa | G5: Políticas | I5: Sistema Externo | J5: Evento | K5: Aspectos por solucionar
E6: Información | F6: Descripción | G6: Número | H6: Descripción
A7: Dueño | B7: Ofrecer un servicio nuevo a la barbería | C7: Comando que permite registrar un nuevo tipo de servicio que la barbería pondrá a disposición de los barberos | D7: =$B$2 -> Servicio | G7: ='P-Servicio'!A6 -> P-SER-0001 | H7: aquí | J7: Servicio ofrecido
G8: ='P-Servicio'!A7 -> P-SER-0002 | H8: aquí
A9: Dueño | B9: Editar un servicio | C9: Permite modificar todos los atibutos de un servicio, que son el nombre, la descripción y el precio | D9: =$B$2 -> Servicio | G9: ='P-Servicio'!A6 -> P-SER-0001 | H9: aquí | J9: Nombre, descripción, precio del servicio actualizados
G10: ='P-Servicio'!A7 -> P-SER-0002 | H10: aquí
A11: Dueño | B11: Ver servicios disponibles de la barbería | C11: Permite consultar el catálogo de servicios que ofrece la barbería | D11: =$B$2 -> Servicio | J11: Servicios consultados
A12: Barbero | B12: Ver servicios disponibles de la barbería | C12: Permite consultar el catálogo de servicios que ofrece la barbería | D12: =$B$2 -> Servicio | J12: Servicios consultados
A13: Cliente | B13: Ver servicios disponibles de la barbería | C13: Permite consultar el catálogo de servicios que ofrece la barbería | D13: =$B$2 -> Servicio | J13: Servicios consultados
A14: Dueño | B14: Retirar un servicio de la barbería | C14: Permite dar de baja un servicio para que deje de ofrecerse a nuevos clientes | D14: =$B$2 -> Servicio | G14: ='P-Servicio'!A8 -> P-SER-0003 | H14: aquí | J14: Servicio retirado

Sheet M-Servicio
A1: <<<< Ir al modulo de dominio | B1: <<<< Ir a objetos de dominio
A2: Representa un identificador que hará unico cada objeto de dominio de este tipo, no se puede repetir | B2: Representa el nombre del servicio que va estar en la barberia, para que el barbero elija los servicios que el sabe hacer | C2: Representa una descripcion de que va a hacer cada servicio en la barberia, para que el barbero sepa que hace el servicio | D2: Representa cuanto va a valer el servicio en pesos colombianos | E2: Representa si el servicio sigue o no disponible en la barberia | F2: Combinacion única que indica que no puede existir más de un servicio con el mismo nombre
A3: id | B3: nombre | C3: descripcion | D3: precio | E3: disponible | F3: Combinacion única
A4: 1 | B4: Motilada | C4: Corte de cabello completo con máquina y tijera, incluye lavado y secado | D4: 22000 | E4: si | F4: =B4 -> Motilada
A5: 2 | B5: Corte de barba | C5: Recorte de la barba con máquina para dejarla pareja y a la medida que pide el cliente | D5: 12000 | E5: si | F5: =B5 -> Corte de barba
A6: 3 | B6: Perfilada de barba | C6: Delineado de los bordes de la barba y el bigote con navaja, sin recortar el largo | D6: 15000 | E6: si | F6: =B6 -> Perfilada de barba
A7: 4 | B7: Arreglo completo de barba con toalla caliente | C7: Recorte, perfilado con navaja, toalla caliente, exfoliación y aceite para la barba | D7: 35000 | E7: si | F7: =B7 -> Arreglo completo de barba con toalla caliente
B13: Corresponde a la descripcion de los atributos
B14: Corresponde al identificador unico del objeto de dominio
B15: Corresponde a los datos que ingresa el usuario
B16: Corresponde a los datos auto generados por el sistema
B17: Corresponde a la combinacion única

Sheet C-PrefijoCelular
A1: <<<< Ir al modulo de dominio | B1: <<<< Ir a objetos de dominio
A2: Nombre atributo | B2: Descripción atributo | C2: Identificador del objeto de dominio | D2: Tipo de dato | E2: Obligatorio | F2: Longitud mínima (si aplica) | G2: Longitud máxima (si aplica) | H2: Precisión (si aplica) | I2: Rendondeo (si aplica) | J2: Rango inicial (si aplica) | K2: Rango final (si aplica) | L2: Formato (si aplica) | M2: Reglas especiales (si aplica) | N2: Dato calculado | O2: Aplica ajuste del dato (si aplica) | P2: Carácter de ajuste (si aplica) | Q2: Quitar espacios en blanco al inicio (si aplica) | R2: Quitar espacios en blanco al fin (si aplica) | S2: Dato sensible (si aplica) | T2: Valor por defecto (si aplica) | U2: Auto generado | V2: =A11 -> registrarPrefijoCelular | W2: =A13 -> modificarPrefijoCelular | Y2: =A16 -> retirarPrefijoCelular | Z2: =A18 -> consultarPrefijosCelular
A3: ='M-PrefijoCelular'!A3 -> id | B3: ='M-PrefijoCelular'!A2 -> Representa un identificador que hará unico cada objeto de dominio de este tipo, no se puede repetir | C3: Si | D3: Identificador único universal | E3: Si | F3: No aplica | G3: No aplica | H3: No aplica | I3: No aplica | J3: No aplica | K3: No aplica | L3: No aplica | M3: No aplica | N3: No | O3: No | P3: No aplica | Q3: No | R3: No | S3: No | T3: No aplica | U3: Si | V3: No requerido | W3: Requerido | X3: No modificable | Y3: Requerido | Z3: No mostrar
A4: ='M-PrefijoCelular'!B3 -> prefijo | B4: ='M-PrefijoCelular'!B2 -> Representa el prefijo telefónico del país que el dueño habilita para que la barbería pueda atender números de ese país | C4: No | D4: Alfanumérico | E4: Si | F4: 2 | G4: 6 | H4: No aplica | I4: No aplica | J4: No aplica | K4: No aplica | L4: Simbolo + seguido de un número. Por ejemplo +57. Tambien el anterior puede ser seguido de un - y un numero. Por ejemplo +1-809 | M4: Solo se aceptan caracteres numericos del 0 al 9 y el carácter '+' y '-' | N4: No | O4: No | P4: No aplica | Q4: Si | R4: Si | S4: No | T4: +0 | U4: No | V4: Requerido | W4: Requerido | X4: Modificable | Y4: No requerido | Z4: Mostrar
A6: Nombre combinación única | B6: Descripción | C6: Atributos involucrados
A7: ='M-PrefijoCelular'!C3 -> Combinación única | B7: ='M-PrefijoCelular'!C2 -> Combinacion única que indica que no puede existir más un mismo prefijo | C7: prefijo
A9: Responsabilidad | C9: Descripción | G9: Entradas | J9: Salida | O9: Políticas (Reglas de Negocio) | Q9: Excepción
G10: Parámetro | H10: Tipo de dato | I10: Descripción | J10: Tipo de Dato | K10: Descripción | O10: Política | P10: Descripción | Q10: Detalle | R10: ¿Qué hago?
A11: registrarPrefijoCelular | C11: Comando que permite al dueño habilitar el prefijo de un país cuyos números va a atender la barbería | G11: datos{prefijo} | H11: PrefijoCelular | I11: Contiene la información requerida para habilitar un nuevo prefijo de país | J11: PrefijoCelular | K11: Contiene la información del prefijo de celular registrado | O11: ='P-PrefijoCelular'!A6 -> P-PRE-0001 | P11: ='P-PrefijoCelular'!B6 -> Asegurar que los datos requeridos (prefijo) sean válidos en tipo de dato, longitud, obligatoriedad, formato y regla especial | Q11: Generar una excepción indicándole al usuario que el prejo de celualr que envio no es válido | R11: Detener operación
O12: ='P-PrefijoCelular'!A7 -> P-PRE-0002 | P12: ='P-PrefijoCelular'!B7 -> Asegurar que no exista otro prefijo de celular registrado con el mismo valor | Q12: Generar una excepción indicándole al usuario que ya existe un prefijo de celular registrado con ese mismo valor | R12: Detener operación
A13: modificarPrefijoCelular | C13: Permite al dueño corregir el valor de un prefijo que ya había habilitado | G13: id | H13: UUID | I13: Corresponde al identificador del prefijo que se va a modificar | J13: PrefijoCelular | K13: Contiene la información del prefijo de celular modificado | O13: ='P-PrefijoCelular'!A9 -> P-PRE-0004 | P13: ='P-PrefijoCelular'!B9 -> Asegurar que exista el prefijo de celular con el id enviado | Q13: Informar con un mensaje que no existe un prefijo de celular con el identificador enviado y por lo tanto no es posible modificar el prefijo | R13: Detener operación
G14: datos{prefijo} | H14: PrefijoCelular | I14: Contiene el valor con el que se va a modificar el prefijo | O14: ='P-PrefijoCelular'!A6 -> P-PRE-0001 | P14: ='P-PrefijoCelular'!B6 -> Asegurar que los datos requeridos (prefijo) sean válidos en tipo de dato, longitud, obligatoriedad, formato y regla especial | Q14: Generar una excepción indicándole al usuario cuáles datos del prefijo no cumplen con las reglas definidas | R14: Detener operación
O15: ='P-PrefijoCelular'!A7 -> P-PRE-0002 | P15: ='P-PrefijoCelular'!B7 -> Asegurar que no exista otro prefijo de celular registrado con el mismo valor | Q15: Generar una excepción indicándole al usuario que ya existe un prefijo de celular registrado con ese mismo valor | R15: Detener operación
A16: retirarPrefijoCelular | C16: Permite al dueño quitar un prefijo para que la barbería deje de atender números de ese país | G16: id | H16: UUID | I16: Corresponde al identificador del prefijo que se va a retirar | K16: No retorna ningún valor. En caso de error genera una excepción. | O16: ='P-PrefijoCelular'!A8 -> P-PRE-0003 | P16: ='P-PrefijoCelular'!B8 -> Asegurar que el prefijo que se va a retirar no esté siendo usado por ningún barbero ni por ningún cliente | Q16: Generar una excepción indicándole al usuario que el prefijo no se puede retirar porque todavía lo usa algún barbero o algún cliente | R16: Detener operación
O17: ='P-PrefijoCelular'!A9 -> P-PRE-0004 | P17: ='P-PrefijoCelular'!B9 -> Asegurar que exista el prefijo de celular con el id enviado | Q17: Informar con un mensaje que no existe un prefijo de celular con el identificador enviado y por lo tanto no es posible dar de baja el prefijo | R17: Detener operación
A18: consultarPrefijosCelular | C18: Permite al dueño consultar el catálogo de prefijos telefónicos de país que tiene habilitados | J18: Lista<PrefijoCelular> | K18: Contiene todos los prefijos de celular registrados

Sheet P-PrefijoCelular
A1: << Ir al modelo de dominio | B1: << Ir al listado de objetos de dominio | C1: << Ir a la caracterización del objeto de dominio | D1: Ir al muestreo de datos del objeto de dominio >> | E1: Ir al event storming del objeto de dominio >>
A2: Objeto de Dominio: | B2: ='Objetos de Dominio'!A6 -> PrefijoCelular
A3: Descripción: | B3: ='Objetos de Dominio'!B6 -> Representa el catálogo de prefijos telefónicos de país que el dueño habilita, y que son los únicos que barberos y clientes pueden usar en su número de celular.
A4: Numero politica | B4: Descripcion politica | D4: Objeto responsable | E4: Regla responsable
A6: P-PRE-0001 | B6: Asegurar que los datos requeridos (prefijo) sean válidos en tipo de dato, longitud, obligatoriedad, formato y regla especial | D6: PrefijoCelular
A7: P-PRE-0002 | B7: Asegurar que no exista otro prefijo de celular registrado con el mismo valor | D7: PrefijoCelular
A8: P-PRE-0003 | B8: Asegurar que el prefijo que se va a retirar no esté siendo usado por ningún barbero ni por ningún cliente | D8: PrefijoCelular
A9: P-PRE-0004 | B9: Asegurar que exista el prefijo de celular con el id enviado | D9: PrefijoCelular

Sheet E-PrefijoCelular
A1: << Ir al modelo de dominio | C1: << Ir al listado de objetos de dominio | F1: << Ir a la caracterización del objeto de dominio | J1: Ir al muestreo de datos del objeto de dominio >>
A2: Objeto de Dominio: | B2: ='Objetos de Dominio'!A6 -> PrefijoCelular
A3: Descripción: | B3: ='Objetos de Dominio'!B6 -> Representa el catálogo de prefijos telefónicos de país que el dueño habilita, y que son los únicos que barberos y clientes pueden usar en su número de celular.
A4: Actor | B4: Action/Command | D4: Entity/Aggregate/Object domain | E4: Read Model | G4: Business Rule/Policy | I4: External System | J4: Domain Event | K4: Hotspot/questions/Risk
A5: Actor | B5: Acción | C5: Descripción | D5: Objeto de dominio | E5: Información externa | G5: Políticas | I5: Sistema Externo | J5: Evento | K5: Aspectos por solucionar
E6: Información | F6: Descripción | G6: Número | H6: Descripción
A7: Dueño | B7: Registrar un prefijo de celular | C7: Comando que permite al dueño habilitar el prefijo de un país cuyos números va a atender la barbería | D7: =$B$2 -> PrefijoCelular | G7: ='P-PrefijoCelular'!A6 -> P-PRE-0001 | H7: ='P-PrefijoCelular'!B6 -> Asegurar que los datos requeridos (prefijo) sean válidos en tipo de dato, longitud, obligatoriedad, formato y regla especial | J7: Prefijo de celular registrado
G8: ='P-PrefijoCelular'!A7 -> P-PRE-0002 | H8: ='P-PrefijoCelular'!B7 -> Asegurar que no exista otro prefijo de celular registrado con el mismo valor
A9: Dueño | B9: Modificar un prefijo de celular registrado | C9: Permite al dueño corregir el valor de un prefijo que ya había habilitado | D9: =$B$2 -> PrefijoCelular | G9: ='P-PrefijoCelular'!A6 -> P-PRE-0001 | H9: ='P-PrefijoCelular'!B6 -> Asegurar que los datos requeridos (prefijo) sean válidos en tipo de dato, longitud, obligatoriedad, formato y regla especial | J9: Prefijo de celular modificado
G10: ='P-PrefijoCelular'!A7 -> P-PRE-0002 | H10: ='P-PrefijoCelular'!B7 -> Asegurar que no exista otro prefijo de celular registrado con el mismo valor
A11: Dueño | B11: Retirar un prefijo de celular | C11: Permite al dueño quitar un prefijo para que la barbería deje de atender números de ese país | D11: =$B$2 -> PrefijoCelular | G11: ='P-PrefijoCelular'!A8 -> P-PRE-0003 | H11: ='P-PrefijoCelular'!B8 -> Asegurar que el prefijo que se va a retirar no esté siendo usado por ningún barbero ni por ningún cliente | J11: Prefijo de celular retirado
A12: Dueño | B12: Ver prefijos de celular | C12: Permite al dueño consultar el catálogo de prefijos telefónicos de país que tiene habilitados | D12: =$B$2 -> PrefijoCelular | J12: Prefijos de celular consultados
A13: Barbero | B13: Ver prefijos de celular | C13: Permite consultar el catálogo de prefijos telefónicos de país disponibles | D13: =$B$2 -> PrefijoCelular | J13: Prefijos de celular consultados
A14: Cliente | B14: Ver prefijos de celular | C14: Permite consultar el catálogo de prefijos telefónicos de país disponibles | D14: =$B$2 -> PrefijoCelular | J14: Prefijos de celular consultados

Sheet M-PrefijoCelular
A1: <<<< Ir al modulo de dominio | B1: <<<< Ir a objetos de dominio
A2: Representa un identificador que hará unico cada objeto de dominio de este tipo, no se puede repetir | B2: Representa el prefijo telefónico del país que el dueño habilita para que la barbería pueda atender números de ese país | C2: Combinacion única que indica que no puede existir más un mismo prefijo
A3: id | B3: prefijo | C3: Combinación única
A4: 1 | B4: +57 | C4: =B4 -> +57
A5: 2 | B5: +91 | C5: =B5 -> +91
A6: 3 | B6: +593 | C6: =B6 -> +593
A7: 4 | B7: +58 | C7: =B7 -> +58
B13: Corresponde a la descripcion de los atributos
B14: Corresponde al identificador unico del objeto de dominio
B15: Corresponde a los datos que ingresa el usuario
B16: Corresponde a la combinacion única

Sheet C-TipoMulta
A1: <<<< Ir al modulo de dominio | B1: <<<< Ir a objetos de dominio
A2: Nombre atributo | B2: Descripción atributo | C2: Identificador del objeto de dominio | D2: Tipo de dato | E2: Obligatorio | F2: Longitud mínima (si aplica) | G2: Longitud máxima (si aplica) | H2: Precisión (si aplica) | I2: Rendondeo (si aplica) | J2: Rango inicial (si aplica) | K2: Rango final (si aplica) | L2: Formato (si aplica) | M2: Reglas especiales (si aplica) | N2: Dato calculado | O2: Aplica ajuste del dato (si aplica) | P2: Carácter de ajuste (si aplica) | Q2: Quitar espacios en blanco al inicio (si aplica) | R2: Quitar espacios en blanco al fin (si aplica) | S2: Dato sensible (si aplica) | T2: Valor por defecto (si aplica) | U2: Auto generado | V2: =A12 -> consultarTodosLosTiposMulta
A3: ='M-TipoMulta'!A3 -> id | B3: ='M-TipoMulta'!A2 -> Representa un identificador que hará unico cada objeto de dominio de este tipo, no se puede repetir | C3: Si | D3: Identificador único universal | E3: Si | F3: No aplica | G3: No aplica | H3: No aplica | I3: No aplica | J3: No aplica | K3: No aplica | L3: No aplica | M3: No aplica | N3: No | O3: No | P3: No aplica | Q3: No | R3: No | S3: No | T3: UUID vacio | U3: Si | V3: No mostrar
A4: ='M-TipoMulta'!B3 -> nombre | B4: ='M-TipoMulta'!B2 -> Representa el nombre del tipo de multa | C4: No | D4: Alfanumérico | E4: Si | F4: 4 | G4: 50 | H4: No aplica | I4: No aplica | J4: No aplica | K4: No aplica | L4: No aplica | M4: No aplica | N4: No | O4: No | P4: No aplica | Q4: Si | R4: Si | S4: No | T4: Vacio | U4: No | V4: Mostrar
A5: ='M-TipoMulta'!C3 -> descripcion | B5: ='M-TipoMulta'!C2 -> Representa que hace cada tipo de multa | C5: No | D5: Alfanumérico | E5: Si | F5: 10 | G5: 300 | H5: No aplica | I5: No aplica | J5: No aplica | K5: No aplica | L5: No aplica | M5: No aplica | N5: No | O5: No | P5: No aplica | Q5: Si | R5: Si | S5: No | T5: Vacio | U5: No | V5: Mostrar
A7: Nombre combinación única | B7: Descripción | C7: Atributos involucrados
A8: ='M-TipoMulta'!D3 -> Combinación única | B8: ='M-TipoMulta'!D2 -> Combinación única indica que no puede existir más de un tipo de multa con el mismo nombre | C8: nombre
A10: Responsabilidad | C10: Descripción | G10: Entradas | J10: Salida | O10: Políticas (Reglas de Negocio) | Q10: Excepción
G11: Parámetro | H11: Tipo de dato | I11: Descripción | J11: Tipo de Dato | K11: Descripción | O11: Política | P11: Descripción | Q11: Detalle | R11: ¿Qué hago?
A12: consultarTodosLosTiposMulta | C12: Permite consultar los tipos de multa que puede recibir un cliente | J12: Lista<TipoMulta> | K12: Contiene todos los tipos de multa que hay

Sheet P-TipoMulta
A1: << Ir al modelo de dominio | B1: << Ir al listado de objetos de dominio | C1: << Ir a la caracterización del objeto de dominio | D1: Ir al muestreo de datos del objeto de dominio >> | E1: Ir al event storming del objeto de dominio >>
A2: Objeto de Dominio: | B2: ='Objetos de Dominio'!A7 -> TipoMulta
A3: Descripción: | B3: ='Objetos de Dominio'!B7 -> Representa los tipos de multa que puede recibir un cliente: por tardanza o por inasistencia.
A4: Numero politica | B4: Descripcion politica | D4: Objeto responsable | E4: Regla responsable
B6: No aplica: es un catálogo de solo lectura, sin comandos que impliquen políticas de negocio propias

Sheet E-TipoMulta
A1: << Ir al modelo de dominio | C1: << Ir al listado de objetos de dominio | F1: << Ir a la caracterización del objeto de dominio | J1: Ir al muestreo de datos del objeto de dominio >>
A2: Objeto de Dominio: | B2: ='Objetos de Dominio'!A7 -> TipoMulta
A3: Descripción: | B3: ='Objetos de Dominio'!B7 -> Representa los tipos de multa que puede recibir un cliente: por tardanza o por inasistencia.
A4: Actor | B4: Action/Command | D4: Entity/Aggregate/Object domain | E4: Read Model | G4: Business Rule/Policy | I4: External System | J4: Domain Event | K4: Hotspot/questions/Risk
A5: Actor | B5: Acción | C5: Descripción | D5: Objeto de dominio | E5: Información externa | G5: Políticas | I5: Sistema Externo | J5: Evento | K5: Aspectos por solucionar
E6: Información | F6: Descripción | G6: Número | H6: Descripción
A7: Dueño | B7: Ver tipos de multa | C7: Permite consultar los tipos de multa que puede recibir un cliente | D7: =$B$2 -> TipoMulta | J7: Tipos de multa consultados
A8: Barbero | B8: Ver tipos de multa | C8: Permite consultar los tipos de multa que puede recibir un cliente | D8: =$B$2 -> TipoMulta | J8: Tipos de multa consultados
A9: Cliente | B9: Ver tipos de multa | C9: Permite consultar los tipos de multa que puede recibir un cliente | D9: =$B$2 -> TipoMulta | J9: Tipos de multa consultados

Sheet M-TipoMulta
A1: <<<< Ir al modulo de dominio | B1: <<<< Ir a objetos de dominio
A2: Representa un identificador que hará unico cada objeto de dominio de este tipo, no se puede repetir | B2: Representa el nombre del tipo de multa | C2: Representa que hace cada tipo de multa | D2: Combinación única indica que no puede existir más de un tipo de multa con el mismo nombre
A3: id | B3: nombre | C3: descripcion | D3: Combinación única
A4: 1 | B4: Tardanza | C4: El cliente llegó a la cita después de la hora acordada, superando los minutos de tiempoEspera definidos en la cita. | D4: =B4 -> Tardanza
A5: 2 | B5: Inasistencia | C5: El cliente no se presentó a la cita agendada: se llegó a la hora estimada de finalización sin que hubiera registrado su llegada. | D5: =B5 -> Inasistencia
B11: Corresponde a la descripcion de los atributos
B12: Corresponde al identificador unico del objeto de dominio
B13: Corresponde a los datos que ingresa el usuario
B14: Corresponde a la combinacion única

Sheet C-Barbero
A1: <<<< Ir al modulo de dominio | B1: <<<< Ir a objetos de dominio
A2: Nombre atributo | B2: Descripción atributo | C2: Identificador del objeto de dominio | D2: Tipo de dato | E2: Obligatorio | F2: Longitud mínima (si aplica) | G2: Longitud máxima (si aplica) | H2: Precisión (si aplica) | I2: Rendondeo (si aplica) | J2: Rango inicial (si aplica) | K2: Rango final (si aplica) | L2: Formato (si aplica) | M2: Reglas especiales (si aplica) | N2: Dato calculado | O2: Aplica ajuste del dato (si aplica) | P2: Carácter de ajuste (si aplica) | Q2: Quitar espacios en blanco al inicio (si aplica) | R2: Quitar espacios en blanco al fin (si aplica) | S2: Dato sensible (si aplica) | T2: Valor por defecto (si aplica) | U2: Auto generado | V2: =A21 -> registrarBarbero | W2: =A24 -> editarContactoBarbero | Y2: =A27 -> editarTiemposAnticipacionBarbero | AA2: =A29 -> consultarDatosBarbero | AB2: =A30 -> desactivarBarbero | AD2: =A32 -> consultarTiemposAnticipacionBarbero | AE2: =A33 -> reactivarBarbero
A3: ='M-Barbero'!A3 -> id | B3: ='M-Barbero'!A2 -> Representa un identificador que hará unico cada objeto de dominio de este tipo, no se puede repetir | C3: Si | D3: Identificador único universal | E3: Si | F3: No aplica | G3: No aplica | H3: No aplica | I3: No aplica | J3: No aplica | K3: No aplica | L3: No aplica | M3: No aplica | N3: No | O3: No aplica | P3: No aplica | Q3: No | R3: No | S3: No | T3: UUID vacio | U3: Si | V3: No requerido | W3: Requerido | X3: No modificable | Y3: Requerido | Z3: No modificable | AA3: No mostrar | AB3: Requerido | AC3: No modificable | AD3: No mostrar | AE3: Requerido | AF3: No modificable
A4: ='M-Barbero'!B3 -> primerNombre | B4: ='M-Barbero'!B2 -> Representa el primer nombre del barbero que trabaja en barbería | C4: No | D4: Alfanumérico | E4: Si | F4: 3 | G4: 100 | H4: No aplica | I4: No aplica | J4: No aplica | K4: No aplica | L4: No aplica | M4: Solo se aceptan caracteres de letras de la 'a' a la 'z', caracteres con tilde y numeros del 0 al 9 | N4: No | O4: No | P4: No | Q4: Si | R4: Si | S4: No | T4: vacío | U4: No | V4: Requerido | W4: No requerido | X4: No modificable | Y4: No requerido | Z4: No modificable | AA4: Mostrar | AB4: No requerido | AC4: No modificable | AD4: No mostrar | AE4: No requerido | AF4: No modificable
A5: ='M-Barbero'!C3 -> segundoNombre | B5: ='M-Barbero'!C2 -> Representa el segundo nombre del barbero que trabaja en barbería | C5: No | D5: Alfanumérico | E5: No | F5: 3 | G5: 100 | H5: No aplica | I5: No aplica | J5: No aplica | K5: No aplica | L5: No aplica | M5: Solo se aceptan caracteres de letras de la 'a' a la 'z', caracteres con tilde y numeros del 0 al 9 | N5: No | O5: No | P5: No | Q5: Si | R5: Si | S5: No | T5: vacío | U5: No | V5: No requerido | W5: No requerido | X5: No modificable | Y5: No requerido | Z5: No modificable | AA5: Mostrar | AB5: No requerido | AC5: No modificable | AD5: No mostrar | AE5: No requerido | AF5: No modificable
A6: ='M-Barbero'!D3 -> primerApellido | B6: ='M-Barbero'!D2 -> Representa el primer apellido del barbero que trabaja en la barbería | C6: No | D6: Alfanumérico | E6: Si | F6: 3 | G6: 100 | H6: No aplica | I6: No aplica | J6: No aplica | K6: No aplica | L6: No aplica | M6: Solo se aceptan caracteres de letras de la 'a' a la 'z', caracteres con tilde y numeros del 0 al 9 | N6: No | O6: No | P6: No | Q6: Si | R6: Si | S6: No | T6: vacío | U6: No | V6: Requerido | W6: No requerido | X6: No modificable | Y6: No requerido | Z6: No modificable | AA6: Mostrar | AB6: No requerido | AC6: No modificable | AD6: No mostrar | AE6: No requerido | AF6: No modificable
A7: ='M-Barbero'!E3 -> segundoApellido | B7: ='M-Barbero'!E2 -> Representa el segundo apellido del barbero que trabaja en la barbería | C7: No | D7: Alfanumérico | E7: No | F7: 3 | G7: 100 | H7: No aplica | I7: No aplica | J7: No aplica | K7: No aplica | L7: No aplica | M7: Solo se aceptan caracteres de letras de la 'a' a la 'z', caracteres con tilde y numeros del 0 al 9 | N7: No | O7: No | P7: No | Q7: Si | R7: Si | S7: No | T7: vacío | U7: No | V7: No requerido | W7: No requerido | X7: No modificable | Y7: No requerido | Z7: No modificable | AA7: Mostrar | AB7: No requerido | AC7: No modificable | AD7: No mostrar | AE7: No requerido | AF7: No modificable
A8: ='M-Barbero'!F3 -> prefijo | B8: ='M-Barbero'!F2 -> Representa cual es el prefijo del numero de celular del barbero | C8: No | D8: PrefijoCelular | E8: Si | F8: No aplica | G8: No aplica | H8: No aplica | I8: No aplica | J8: No aplica | K8: No aplica | L8: No aplica | M8: Aplican las reglas del objeto referenciado | N8: No | O8: No aplica | P8: No aplica | Q8: No aplica | R8: No aplica | S8: No | T8: UUID vacio | U8: No | V8: Requerido | W8: Requerido | X8: Modificable | Y8: No requerido | Z8: No modificable | AA8: Mostrar | AB8: No requerido | AC8: No modificable | AD8: No mostrar | AE8: No requerido | AF8: No modificable
A9: ='M-Barbero'!G3 -> celular | B9: ='M-Barbero'!G2 -> Representa el número de celular del barbero, es el dato que el cliente necesita en caso de que tenga que contactarse con el | C9: No | D9: Alfanumérico | E9: Si | F9: 6 | G9: 15 | H9: No aplica | I9: No aplica | J9: No aplica | K9: No aplica | L9: No aplica | M9: Solo se aceptan caracteres de numeros del '0' al '9' | N9: No | O9: No aplica | P9: No aplica | Q9: Si | R9: Si | S9: Si | T9: 0 | U9: No | V9: Requerido | W9: Requerido | X9: Modificable | Y9: No requerido | Z9: No modificable | AA9: Mostrar | AB9: No requerido | AC9: No modificable | AD9: No mostrar | AE9: No requerido | AF9: No modificable
A10: ='M-Barbero'!H3 -> elNumeroCelularEsCorrecto | B10: ='M-Barbero'!H2 -> Representa si el numero que ingreso el cliente es correcto o no | C10: No | D10: Lógico | E10: Si | F10: No aplica | G10: No aplica | H10: No aplica | I10: No aplica | J10: No aplica | K10: No aplica | L10: No aplica | M10: El barbero debe de poner un si en este atributo | N10: No | O10: No aplica | P10: No aplica | Q10: No aplica | R10: No aplica | S10: No | T10: No | U10: No | V10: Requerido | W10: No requerido | X10: No modificable | Y10: No requerido | Z10: No modificable | AA10: Mostrar | AB10: Requerido | AC10: Modificable | AD10: No mostrar | AE10: Requerido | AF10: Modificable
A11: ='M-Barbero'!I3 -> vigente | B11: ='M-Barbero'!I2 -> Representa si el barbero sigue o no trabajando en la barberia | C11: No | D11: Lógico | E11: No | F11: No aplica | G11: No aplica | H11: No aplica | I11: No aplica | J11: No aplica | K11: No aplica | L11: No aplica | M11: No aplica | N11: Si | O11: No aplica | P11: No aplica | Q11: No aplica | R11: No aplica | S11: No | T11: Si | U11: Si | V11: No requerido | W11: No requerido | X11: No modificable | Y11: No requerido | Z11: No modificable | AA11: Mostrar | AB11: No requerido | AC11: No modificable | AD11: No mostrar | AE11: No requerido | AF11: No modificable
A12: ='M-Barbero'!J3 -> anticipacionEnHorasParaAgendarCita | B12: ='M-Barbero'!J2 -> Representa la parte en horas del tiempo mínimo de anticipación con el que un cliente debe pedirle una cita a este barbero. Junto con anticipacionEnMinutosParaAgendarCita forma el tiempo total de anticipación que exige el barbero | C12: No | D12: Entero | E12: No | F12: No aplica | G12: No aplica | H12: No aplica | I12: No aplica | J12: 0 | K12: 720 | L12: Horas | M12: No aplica | N12: No | O12: No aplica | P12: No aplica | Q12: No aplica | R12: No aplica | S12: No | T12: 0 | U12: No | V12: No requerido | W12: No requerido | X12: No modificable | Y12: Requerido | Z12: Modificable | AA12: No mostrar | AB12: No requerido | AC12: No modificable | AD12: Mostrar | AE12: No requerido | AF12: No modificable
A13: ='M-Barbero'!K3 -> anticipacionEnMinutosParaAgendarCita | B13: ='M-Barbero'!K2 -> Representa la parte en minutos del tiempo mínimo de anticipación con el que un cliente debe pedirle una cita a este barbero. Junto con anticipacionEnHorasParaAgendarCita forma el tiempo total de anticipación que exige el barbero | C13: No | D13: Entero | E13: No | F13: No aplica | G13: No aplica | H13: No aplica | I13: No aplica | J13: 0 | K13: 59 | L13: Minutos | M13: No aplica | N13: No | O13: No aplica | P13: No aplica | Q13: No aplica | R13: No aplica | S13: No | T13: 0 | U13: No | V13: No requerido | W13: No requerido | X13: No modificable | Y13: Requerido | Z13: Modificable | AA13: No mostrar | AB13: No requerido | AC13: No modificable | AD13: Mostrar | AE13: No requerido | AF13: No modificable
A15: Nombre combinación única | B15: Descripción | C15: Atributos involucrados
A16: ='M-Barbero'!L3 -> Combinación única 1 | B16: ='M-Barbero'!L2 -> Combinacion única que indica que no puede existir más de un barbero con el mismo prefijo de celular y número de celular | C16: =A8 -> prefijo
C17: =A9 -> celular
A19: Responsabilidad | C19: Descripción | G19: Entradas | J19: Salida | O19: Políticas (Reglas de Negocio) | Q19: Excepción
G20: Parámetro | H20: Tipo de dato | I20: Descripción | J20: Tipo de Dato | K20: Descripción | O20: Política | P20: Descripción | Q20: Detalle | R20: ¿Qué hago?
A21: registrarBarbero | C21: Comando que permite el ingreso de un nuevo barbero a trabajar en la barbería | G21: datos{primerNombre, segundoNombre, primerApellido, segundoApellido, prefijoCelular, celular, elNumeroCelularEsCorrecto} | H21: Barbero | I21: Contiene la información requerida para registrar un nuevo barbero en la barbería | J21: Barbero | K21: Contiene la información del barbero registrado | O21: ='P-Barbero'!A6 -> P-BAR-0001 | P21: ='P-Barbero'!B6 -> Asegurar que los datos requeridos del barbero (nombre, apellido, prefijo de celular, celular, tiempos de anticipación) sean válidos en tipo de dato, longitud, obligatoriedad, formato y rango | Q21: Generar una excepción indicándole al barbero que los datos ingresados no son válidos | R21: Detener operación
O22: ='P-Barbero'!A7 -> P-BAR-0002 | P22: ='P-Barbero'!B7 -> Asegurar que el número de celular y prefijo de celular no esté siendo utilizado por otro barbero | Q22: Generar una excepción indicándole al usuario que ya existe otro barbero registrado con ese prefijo y número de celular | R22: Detener operación
O23: ='P-Barbero'!A11 -> P-BAR-0006 | P23: ='P-Barbero'!B11 -> Asegurar que el barbero halla puesto un si en el atributo elNumeroCelularEsCorrecto | Q23: Generar una excepción indicándole al barbero que ponga si en elNumeroCelularEsCorrecto | R23: Detener operación
